Workbook
Name IQ_CH: 110000
Name IQ_CQ: 5000
Name IQ_CY: 10000
Name IQ_DAILY: 500000
Name IQ_FH: 100000
Name IQ_FQ: 500
Name IQ_FY: 1000
Name IQ_LTM: 2000
Name IQ_MONTH: 15000
Name IQ_NTM: 6000
Name IQ_WEEK: 50000
Name IQ_YTD: 3000

Sheet __snloffice
A1: 允䅁䙁䅕䅁䭁䅁䅁兑卂䕁䅍睑䅁䅁䅁䅁捁䅁䅁督睂䙁䄸督潂䝁䅅杣求䡁䅍睘療䡁䅕䅤䅁䅁䅙䅁畁䅁䅁兓剂䙁䄸睑療䝁䄰兢療䝁䄴睘歂䝁䅫杤時䝁䅑党橂䝁䅷兙祂䝁䅕䅚䅁䅁䅅䅁䝁䅁䅁杒剂䅁䅁杁䅁䅁䅧䅁䝂䙁䅅䅍䅁䅁䅕䅁啁䅁䅁睍癁䑁䅍免癁䑁䅉䅍祁䑁䅅䅁䑁䅁䅁䅇䅁䝁䅫兣時䝁䅕杙あ䙁䄸党㑂䝁䅍䅢䅁䍁䅉䅁㑁䅁䅁睉䩂䕁䄴杖䉂䕁䅷兓䕂䍁䅁杒噂䕁䄴睑啂䕁䅫睔佂䍁䅁䅕䉂䙁䅉兑乂䕁䅕䅖䙂䙁䅉䅁䕁䅁䅁䅆䅁䑁䅙睌穁䑁䅁睌祁䑁䅁杍硁䅁䅁睂䅁䉁䅙䅁祁䑁䅁杍祁䍁䄰䅍ㅁ䍁䄰䅍穁䅁䅁兏䅁䉁䅑䅁穁䍁䄸睍硁䍁䄸杍睁䑁䅉䅎䅁䅁䅧䅁坁䅁䅁杍睁䑁䅉䅎瑁䑁䅁杍瑁䑁䅉免䅁䑁䅑䅁啁䅁䅁兏癁䑁䅍䅍癁䑁䅉䅍祁䑁䅅䅁䩁䅁䅁杆䅁䑁䅅杍癁䑁䅍免癁䑁䅉䅍祁䑁䅉䅁䱁䅁䅁杆䅁䑁䅉䅍祁䑁䅍兌硁䑁䅅兌睁䑁䅧䅁癁䅁䅁杆䅁䑁䅅杍癁䑁䅍免癁䑁䅉䅍祁䑁䅅䅁䭁䅁䅁䅆䅁䑁䅫睌穁䑁䅁睌祁䑁䅁杍祁䅁䅁充䅁䉁䅙䅁硁䑁䅉睌穁䑁䅅睌祁䑁䅁杍穁䅁䅁䅄䅁䉁䅙䅁硁䑁䅉睌穁䑁䅅睌祁䑁䅁杍ぁ䅁䅁兄䅁䅁䅯䅁䍂䙁䅧睕䵂䅁䅁杇䅁䉁䅷䅁䩂䙁䅅睘啂䝁䄸䅤桂䝁䅷睘歂䝁䅕杙あ䅁䅁睉䅁䉁䅙䅁硁䑁䅉睌穁䑁䅅睌祁䑁䅁杍ㅁ䅁䅁杄䅁䉁䅑䅁穁䍁䄸睍硁䍁䄸杍睁䑁䅉杍䅁䅁䄸䅁啁䅁䅁李癁䑁䅍䅍癁䑁䅉䅍祁䑁䅉䅁允䅁䅁杆䅁䑁䅉䅍祁䑁䅕兌睁䑁䅕兌睁䑁䅣䅁湁䅁䅁䅆䅁䑁䅙睌穁䑁䅁睌祁䑁䅁杍穁䅁䅁杅䅁䍁䅙䅁呂䕁䄴䅔時䝁䄴党あ䙁䄸兡畂䡁䅙党穂䡁䅑睘灂䝁䄴睙䅁䍁䅅䅁䭁䅁䅁睒䍂䕁䅑睑䅁䉁䅷䅁啁䅁䅁睍癁䑁䅍免癁䑁䅉䅍祁䑁䅍䅁呁䅁䅁杆䅁䑁䅉䅍祁䑁䅍兌睁䑁䅧兌睁䑁䅫䅁煁䅁䅁杋䅁䕁䅫兕時䙁䅑睔啂䕁䅅䅔時䕁䅑兓坂䙁䄸䅕䉂䕁䅫䅒時䕁䅍杒䅁䙁䅅䅁啁䅁䅁李癁䑁䅍䅍癁䑁䅉䅍祁䑁䅕䅁啁䅁䅁杆䅁䑁䅉䅍祁䑁䅅兌睁䑁䅕兌睁䑁䅑䅁㑁䅁䅁杆䅁䑁䅉䅍祁䑁䅉兌睁䑁䅧兌睁䑁䅉䅁㥁䅁䅁䅆䅁䑁䅫睌穁䑁䅁睌祁䑁䅁杍穁䅁䅁兆䅁䉁䅑䅁㉁䍁䄸睍睁䍁䄸杍睁䑁䅉䅎䅁䉁䅙䅁坁䅁䅁杍睁䑁䅉免瑁䑁䅁兎瑁䑁䅁兎䅁䍁䅑䅁坁䅁䅁杍睁䑁䅉杍瑁䑁䅁䅏瑁䑁䅁睍䅁䍁䅫䅁啁䅁䅁兏癁䑁䅍䅍癁䑁䅉䅍祁䑁䅑䅁塁䅁䅁䅆䅁䑁䅍睌穁䑁䅅睌祁䑁䅁杍ㅁ䅁䅁䅇䅁䉁䅑䅁㕁䍁䄸睍睁䍁䄸杍睁䑁䅉兎䅁䉁䅫䅁䝁䅁䅁杔䉂䅁䅁睇䅁䅁䅯䅁偂䕁䅉䅒䑂䅁䅁先䅁䅁䅯䅁啂䕁䅍䅕䑂䅁䅁杈䅁䅁䅯䅁啂䙁䅍䅔奂䅁䅁睈䅁䉁䅙䅁祁䑁䅁杍ぁ䍁䄰䅍㑁䍁䄰䅍㍁䅁䅁睋䅁䉁䅙䅁祁䑁䅁杍ぁ䍁䄰䅍ㅁ䍁䄰䅍硁䅁䅁睏䅁䅁䅉䅁䅁䍁䅁䅁坁䅁䅁杍睁䑁䅉睍瑁䑁䅁䅏瑁䑁䅁睍䅁䑁䄴䅁坁䅁䅁杍睁䑁䅉杍瑁䑁䅁兎瑁䑁䅁䅎䅁䍁䅕䅁坁䅁䅁杍睁䑁䅉兎瑁䑁䅁䅏瑁䑁䅁李䅁䍁䅷䅁坁䅁䅁杍睁䑁䅉䅎瑁䑁䅁兎瑁䑁䅁䅏䅁䍁䅙䅁坁䅁䅁杍睁䑁䅉免瑁䑁䅁䅏瑁䑁䅁䅎䅁䍁䅧䅁坁䅁䅁杍睁䑁䅉免瑁䑁䅅免瑁䑁䅁睍䅁䍁䄰䅁坁䅁䅁杍睁䑁䅉䅎瑁䑁䅅免瑁䑁䅁李䅁䑁䅁䅁坁䅁䅁杍睁䑁䅉杍瑁䑁䅅免瑁䑁䅁杍䅁䍁䄴䅁坁䅁䅁杍睁䑁䅉兎瑁䑁䅅免瑁䑁䅁兎䅁䑁䅅䅁坁䅁䅁杍睁䑁䅉杍瑁䑁䅁杍瑁䑁䅉睍䅁䑁䅉䅁坁䅁䅁杍睁䑁䅉睍瑁䑁䅁杍瑁䑁䅉杍䅁䑁䅍䅁坁䅁䅁杍睁䑁䅉兎瑁䑁䅁杍瑁䑁䅅兏䅁䑁䅕䅁坁䅁䅁杍睁䑁䅉李瑁䑁䅁杍瑁䑁䅅䅏䅁䑁䅙䅁坁䅁䅁杍睁䑁䅉睍瑁䑁䅁兎瑁䑁䅅䅍䅁䑁䅣䅁坁䅁䅁杍睁䑁䅉睍瑁䑁䅁兎瑁䑁䅁䅏䅁䑁䅯䅁坁䅁䅁杍睁䑁䅉免瑁䑁䅁䅏瑁䑁䅁睍䅁䑁䅷䅁坁䅁䅁杍睁䑁䅉免瑁䑁䅅免瑁䑁䅁杍䅁䑁䄸䅁坁䅁䅁杍睁䑁䅉杍瑁䑁䅅免瑁䑁䅁免䅁䕁䅁䅁坁䅁䅁杍睁䑁䅉睍瑁䑁䅅免瑁䑁䅁杍䅁䕁䅅䅁坁䅁䅁杍睁䑁䅉䅎瑁䑁䅅免瑁䑁䅁兎䅁䕁䅉䅁坁䅁䅁杍睁䑁䅉兎瑁䑁䅅免瑁䑁䅁䅎䅁䕁䅍䅁坁䅁䅁杍睁䑁䅉杍瑁䑁䅁杍瑁䑁䅅睎䅁䕁䅑䅁坁䅁䅁杍睁䑁䅉睍瑁䑁䅁杍瑁䑁䅅李䅁䕁䅕䅁坁䅁䅁杍睁䑁䅉䅎瑁䑁䅁杍瑁䑁䅅兎䅁䕁䅙䅁坁䅁䅁杍睁䑁䅉兎瑁䑁䅁杍瑁䑁䅅睍䅁䕁䅣䅁坁䅁䅁杍睁䑁䅉李瑁䑁䅁杍瑁䑁䅅杍䅁䕁䅧䅁坁䅁䅁杍睁䑁䅉䅎瑁䑁䅁睎瑁䑁䅍免䅁䕁䅫䅁坁䅁䅁杍睁䑁䅉兎瑁䑁䅁睎瑁䑁䅍䅍䅁䕁䅯䅁坁䅁䅁杍睁䑁䅉兎瑁䑁䅁䅎瑁䑁䅍䅍䅁䕁䅳䅁敁䅁䅁睕兂䙁䄸䅕卂䕁䅫睑䙂䙁䄸睑䵂䕁䄸睕䙂䅁䅁䅔䅁䉁䅉䅁汁䙁䅑睑乂䙁䅍兗睁䑁䅉䅁乂䅁䅁䅈䅁䙁䅍䅕時䙁䅉兑啂䕁䅕睘坂䕁䅅䅔噂䕁䅕䅁佂䅁䅁杅䅁䍁䅕䅖䑂䕁䄰睕婂䑁䅁睍䅁䕁䄸䅁䭁䅁䅁村䩂䙁䅯䅒䅁䙁䅁䅁䥁䅁䅁杒婂䑁䅁䅁卂䅁䅁䅅䅁䕁䅫兕時䕁䅉杖兂䙁䅍䅁呂䅁䅁杉䅁䙁䅍䅕時䕁䄴兑坂䙁䄸䅕䙂䙁䅉睘呂䕁䅧兑卂䕁䅕䅁啂䅁䅁か䅕䅁杷允䅁䅁䅑䅁䑁䅁䅷䅁䭁䕁䄸䅁䭁䕁䄴䅁䙁䅁䅁䅁䅃⭃䅚允䅁䅁䅅䅁䙁佁㙆䭆䠵刴䅆䍄䉁䅁䅁兂䅁䅁䅍䅄䅁䅁䅯先䅁䅁䅯允䅁䅁䅯兂䅁䅁䅕䅁䅁䍁扂欵䉁䅁䅁允䅁䅁䅕歲桦桥畓稱䴸䅉䅅䅁䙁䅁䅁睁䵁䅁䅁权慁䅁䅁权呂䅁䅁权䙁䅁䅁兂䅁䅁䅁䵉汌䅑䅅䅁䉁䅁䅁兂㙃兓䍷祋㙣䅑杷允䅁䅁䅕䅁䑁䅁䅷䅁䭁䉁䄰䅁䭁䙁䅍䅁䭁䅁䅕䅁䙁䅁䅁䅁杁佂䅚允䅁䅁䅅䅁䙁䩁畨潅䅐楓䄵䍄䉁䅁䅁兂䅁䅁䅍䅄䅁䅁䅯䅁䅁䅁䅯允䅁䅁䅯兂䅁䅁䅕䅁䅁䅁㝃唵䉁䅁䅁允䅁䅁䅕児塲㍯㥁樲䴸䅉䅅䅁䙁䅁䅁睁䵁䅁䅁权晁䅁䅁权呂䅁䅁权䙁䅁䅁兂䅁䅁䅁䉑浪䅑䅅䅁䉁䅁䅁兂䝂癴㥐倱睧䅑杷允䅁䅁䅑䅁䑁䅁䅷䅁䭁䕁䄸䅁䭁䕁䄴䅁䙁䅁䅁䅁杂佄䅚允䅁䅁䅅䅁䙁䭁䠵場啯桲䅊䍄䉁䅁䅁兂䅁䅁䅍䅄䅁䅁䅯䅁䅁䅁䅯睕䅁䅁䅯兂䅁䅁䅕䅁䅁䵁煂欵䉁䅁䅁允䅁䅁䅕佖汏㡭杔き䵁䅉䅅䅁䕁䅁䅁睁䵁䅁䅁权偂䅁䅁权佂䅁䅁兂䅁䅁䅁䈴浺䅑䅅䅁䉁䅁䅁兂䑄匹捨㡪偉䅑杷允䅁䅁䅕䅁䑁䅁䅷䅁䭁䅁䅁䅁䭁䅁䅅䅁䭁䅁䅕䅁䙁䅁䅁䅁䅄⭬䅖允䅁䅁䅅䅁䙁䩁婱婭婭摭⽫䍄䉁䅁䅁兂䅁䅁䅍䅄䅁䅁䅯䅈䅁䅁䅯允䅁䅁䅯兂䅁䅁䅕䅁䅁䥁祁欵䉁䅁䅁允䅁䅁䅕椹捨㡪ㅌ䐲䴸䅉䅅䅁䙁䅁䅁睁䵁䅁䅁权晁䅁䅁权䉁䅁䅁权䙁䅁䅁兂䅁䅁䅁乙決䅑䅅䅁䉁䅁䅁兂乄䵺䵺䵺捺睐杷允䅁䅁䅕䅁䑁䅁䅷䅁䭁䉁䅷䅁䭁䙁䅍䅁䭁䅁䅕䅁䙁䅁䅁䅁䅄敖䅚允䅁䅁䅅䅁䙁乁欰潂噇祑䄵䍄䉁䅁䅁䅂䅁䅁䅍䅄䅁䅁䅯睔䅁䅁䅯杔䅁䅁䅕䅁䅁䕁浂欵䉁䅁䅁允䅁䅁䅕瑃橥䑣䬰啄䵁䅉䅅䅁䙁䅁䅁睁䵁䅁䅁权慁䅁䅁权䉁䅁䅁权䙁䅁䅁兂䅁䅁䅁佧汦䅑䅅䅁䉁䅁䅁兂㉄䙋偹癷杘睐杷允䅁䅁䅕䅁䑁䅁䅷䅁䭁䉁䄰䅁䭁䙁䅍䅁䭁䅁䅕䅁䙁䅁䅁䅁䅄住䅚允䅁䅁䅅䅁䙁䙁余扌摋礷䄵䍄䉁䅁䅁兂䅁䅁䅍䅄䅁䅁䅯睈䅁䅁䅯允䅁䅁䅯兂䅁䅁䅕䅁䅁䝁啁欵䉁䅁䅁允䅁䅁䅕䡰㥁瑃橥䐴䴸䅉䅅䅁䙁䅁䅁睁䵁䅁䅁权摁䅁䅁权呂䅁䅁权䙁䅁䅁兂䅁䅁䅁䥯浈䅑䅅䅁䉁䅁䅁兂獃䙈歰㕏琸䅑杷允䅁䅁䅕䅁䑁䅁䅷䅁䭁䅁䅁䅁䭁䙁䅍䅁䭁䅁䅕䅁䙁䅁䅁䅁䅁併䅖允䅁䅁䅅䅁䙁䱁䩰䅄牉穊䅊䍄䉁䅁䅁兂䅁䅁䅍䅄䅁䅁䅯䅁䅁䅁䅯睕䅁䅁䅯兂䅁䅁䅕䅁䅁䍁灁欵䉁䅁䅁允䅁䅁䅕搵楁⼲⭫き䵁䅉䅅䅁䕁䅁䅁睁䵁䅁䅁权偂䅁䅁权佂䅁䅁兂䅁䅁䅁佧汘䅑䅅䅁䉁䅁䅁兂卂䉵䘶ㄶ剅䅑杷允䅁䅁䅕䅁䑁䅁䅷䅁䭁䅁䅁䅁䭁䅁䅅䅁䭁䅁䅕䅁䙁䅁䅁䅁杄⬲䅖允䅁䅁䅅䅁䙁佁㙆䭆䠵搴⽯䍄䉁䅁䅁兂䅁䅁䅍䅄䅁䅁䅯䅁䅁䅁䅯睕䅁䅁䅯兂䅁䅁䅕䅁䅁䅁㑁欵䉁䅁䅁允䅁䅁䅕䅁䅁䅁权き䵁䅉䅅䅁䙁䅁䅁睁䵁䅁䅁权晁䅁䅁权呂䅁䅁权䙁䅁䅁兂䅁䅁䅁䱉汄䅑䅅䅁䉁䅁䅁兂㑃潈牘摕睧䅑杷允䅁䅁䅕䅁䑁䅁䅷䅁䭁䉁䄸䅁䭁䙁䅍䅁䭁䅁䅕䅁䙁䅁䅁䅁䅂數䅖允䅁䅁䅅䅁䙁䵁㉬灶愸穌䅆䍄䉁䅁䅁䅂䅁䅁䅍䅄䅁䅁䅯睔䅁䅁䅯杔䅁䅁䅯䅉䅁䅁䅅䅁䉁䅁䅁兂乄䵺䵺䵺佷䅑杷允䅁䅁䅕䅁䑁䅁䅷䅁䭁䉁䅯䅁䭁䅁䅅䅁䭁䅁䅕䅁䙁䅁䅁䅁杂敓䅚允䅁䅁䅅䅁䙁䭁睒児塲⭯⽧䍄䉁䅁䅁兂䅁䅁䅍䅄䅁䅁䅯杈䅁䅁䅯睕䅁䅁䅯兂䅁䅁䅕䅁䅁佁祄唵䉁䅁䅁允䅁䅁䅕㉣剩堷⽷䕌䵁䅉䅅䅁䙁䅁䅁睁䵁䅁䅁权慁䅁䅁权呂䅁䅁权䙁䅁䅁兂䅁䅁䅁䑙浦䅑䅅䅁䉁䅁䅁兂晁敨剴乵㘴䅑杷允䅁䅁䅕䅁䑁䅁䅷䅁䭁䅁䅁䅁䭁䅁䅅䅁䭁䅁䅕䅁䙁䅁䅁䅁䅃佇䅚允䅁䅁䅅䅁䙁䱁敧敨剴乵⼴䍄䉁䅁䅁兂䅁䅁䅍䅄䅁䅁䅯睈䅁䅁䅯允䅁䅁䅯兂䅁䅁䅕䅁䅁佁穄唵䉁䅁䅁允䅁䅁䅕場啯歲桦樲䴸䅉䅅䅁䙁䅁䅁睁䵁䅁䅁权慁䅁䅁权䉁䅁䅁权䙁䅁䅁兂䅁䅁䅁䝧浦䅑䅅䅁䉁䅁䅁兂歃䑣䬰㘱潐睐杷允䅁䅁䅑䅁䑁䅁䅷䅁䭁䕁䄸䅁䭁䕁䄴䅁䙁䅁䅁䅁权畮䅖允䅁䅁䅅䅁䙁䡁啳歲桦瑥⽑䍄䉁䅁䅁兂䅁䅁䅍䅄䅁䅁䅯䅁䅁䅁䅯睕䅁䅁䅯兂䅁䅁䅕䅁䅁䥁穄唵䉁䅁䅁允䅁䅁䅕積積積呏歍䵁䅉䅅䅁䙁䅁䅁睁䵁䅁䅁权摁䅁䅁权呂䅁䅁权䙁䅁䅁兂䅁䅁䅁佷氷䅑䅅䅁䉁䅁䅁兂浃㡭村䱳瑉䅑杷允䅁䅁䅑䅁䑁䅁䅷䅁䭁䕁䄸䅁䭁䕁䄴䅁䙁䅁䅁䅁杁余䅚允䅁䅁䅅䅁䙁䑁積積積睍䄹䍄䉁䅁䅁兂䅁䅁䅍䅄䅁䅁䅯杇䅁䅁䅯睕䅁䅁䅯兂䅁䅁䅕䅁䅁䝁䝁欵䉁䅁䅁允䅁䅁䅕牒穢搯契歏䵁䅉䅅䅁䕁䅁䅁睁䵁䅁䅁权偂䅁䅁权佂䅁䅁兂䅁䅁䅁䬴汦䅑䅅䅁䉁䅁䅁兂㝂䭆䠵場啲睐杷允䅁䅁䅑䅁䑁䅁䅷䅁䭁䕁䄸䅁䭁䕁䄴䅁䙁䅁䅁䅁䅃田䅖允䅁䅁䅅䅁䙁䡁啳歲桦来䅚䍄䉁䅁䅁兂䅁䅁䅍䅄䅁䅁䅯睈䅁䅁䅯允䅁䅁䅯兂䅁䅁䅕䅁䅁䭁㑂欵䉁䅁䅁允䅁䅁䅕牕敧敨剴䐴䴸䅉䅅䅁䕁䅁䅁睁䵁䅁䅁权偂䅁䅁权佂䅁䅁兂䅁䅁䅁乷汢䅑䅅䅁䉁䅁䅁兂乄䵺䵺䵺䵷䅑杷允䅁䅁䅕䅁䑁䅁䅷䅁䭁䉁䅯䅁䭁䅁䅅䅁䭁䅁䅕䅁䙁䅁䅁䅁䅄留䅚允䅁䅁䅅䅁䙁䭁睒児塲⭯⽧䍄䉁䅁䅁兂䅁䅁䅍䅄䅁䅁䅯䅁䅁䅁䅯允䅁䅁䅯兂䅁䅁䅕䅁䅁佁㑄唵䉁䅁䅁允䅁䅁䅕䉵䘶ㄶ㑇樳䴸䅉䅅䅁䙁䅁䅁睁䵁䅁䅁权䅁䅁䅁权呂䅁䅁权䙁䅁䅁兂䅁䅁䅁䝁浌䅑䅅䅁䉁䅁䅁兂煃搸乊瑙穁䅑杷允䅁䅁䅕䅁䑁䅁䅷䅁䭁䉁䄰䅁䭁䅁䅅䅁䭁䅁䅕䅁䙁䅁䅁䅁䅁佅䅚允䅁䅁䅅䅁䙁䉁䘫ㄶ㑇瑈⽕䍄䉁䅁䅁兂䅁䅁䅍䅄䅁䅁䅯䅁䅁䅁䅯睕䅁䅁䅯兂䅁䅁䅕䅁䅁䥁瑁欵䉁䅁䅁允䅁䅁䅕扌摋㘷䝥き䵁䅉䅅䅁䕁䅁䅁睁䵁䅁䅁权偂䅁䅁权佂䅁䅁兂䅁䅁䅁乷汈䅑䅅䅁䉁䅁䅁兂䥂場啯歲䡣䅑杷允䅁䅁䅑䅁䑁䅁䅷䅁䭁䕁䄸䅁䭁䕁䄴䅁䙁䅁䅁䅁杄敄䅚允䅁䅁䅅䅁䙁䑁䬰㘱睎剐䅊䍄䉁䅁䅁兂䅁䅁䅍䅄䅁䅁䅯先䅁䅁䅯睕䅁䅁䅯兂䅁䅁䅕䅁䅁䵁瑁欵䉁䅁䅁允䅁䅁䅕杖琴灳瘳歌䵁䅉䅅䅁䙁䅁䅁睁䵁䅁䅁权晁䅁䅁权呂䅁䅁权䙁䅁䅁兂䅁䅁䅁䍯浺䅑䅅䅁䉁䅁䅁兂⽁噎㘶卓硷䅑杷允䅁䅁䅕䅁䑁䅁䅷䅁䭁䉁䅷䅁䭁䙁䅍䅁䭁䅁䅕䅁䙁䅁䅁䅁杁畉䅚允䅁䅁䅅䅁䙁䥁䌯匹捨祄䄵䍄䉁䅁䅁兂䅁䅁䅍䅄䅁䅁䅯先䅁䅁䅯睕䅁䅁䅯兂䅁䅁䅕䅁䅁䍁牄唵䉁䅁䅁允䅁䅁䅕灰䕶䱉祃啌䵁䅉䅅䅁䙁䅁䅁睁䵁䅁䅁权晁䅁䅁权呂䅁䅁权䙁䅁䅁兂䅁䅁䅁䉧浢䅑䅅䅁䉁䅁䅁兂䝂癴㥐倱睧䅑杷允䅁䅁䅑䅁䑁䅁䅷䅁䭁䕁䄸䅁䭁䕁䄴䅁䙁䅁䅁䅁杁畇䅚允䅁䅁䅅䅁䙁䙁㑋潈牘剕䅆䍄䉁䅁䅁兂䅁䅁䅍䅄䅁䅁䅯䅁䅁䅁䅯允䅁䅁䅯兂䅁䅁䅕䅁䅁䭁瑄唵䉁䅁䅁允䅁䅁䅕敨剴䉵䘶稲䴸䅉䅅䅁䕁䅁䅁睁䵁䅁䅁权偂䅁䅁权佂䅁䅁兂䅁䅁䅁义氳䅑䅅䅁䉁䅁䅁兂慃婭婭婭䡫䅑杷允䅁䅁䅕䅁䑁䅁䅷䅁䭁䉁䅷䅁䭁䙁䅍䅁䭁䅁䅕䅁䙁䅁䅁䅁䅁⭆䅚允䅁䅁䅅䅁䙁䙁㘶兓䍷祱䄱䍄䉁䅁䅁兂䅁䅁䅍䅄䅁䅁䅯杈䅁䅁䅯睕䅁䅁䅯兂䅁䅁䅕䅁䅁䭁䑂欵䉁䅁䅁允䅁䅁䅕倹唳佥浬䕊䵁䅉䅅䅁䕁䅁䅁睁䵁䅁䅁权偂䅁䅁权佂䅁䅁兂䅁䅁䅁䑧浔䅑䅅䅁䉁䅁䅁兂獄払敧敨剳䅑杷允䅁䅁䅕䅁䑁䅁䅷䅁䭁䉁䄰䅁䭁䅁䅅䅁䭁䅁䅕䅁䙁䅁䅁䅁䅁佌䅚允䅁䅁䅅䅁䙁䝁浚浚浚瑚⽙䍄䉁䅁䅁兂䅁䅁䅍䅄䅁䅁䅯睈䅁䅁䅯允䅁䅁䅯兂䅁䅁䅕䅁䅁佁療欵䉁䅁䅁允䅁䅁䅕牕敧敨剴䐴䴸䅉䅅䅁䕁䅁䅁睁䵁䅁䅁权偂䅁䅁权佂䅁䅁兂䅁䅁䅁䍙浄䅑䅅䅁䉁䅁䅁兂䑄匹捨㡪光䅑杷允䅁䅁䅕䅁䑁䅁䅷䅁䭁䉁䅯䅁䭁䅁䅅䅁䭁䅁䅕䅁䙁䅁䅁䅁杄⭋䅚允䅁䅁䅅䅁䙁䭁睒児塲⭯⽧䍄䉁䅁䅁兂䅁䅁䅍䅄䅁䅁䅯先䅁䅁䅯睕䅁䅁䅯兂䅁䅁䅕䅁䅁䭁䵄唵䉁䅁䅁允䅁䅁䅕噋偹癷潕歌䵁䅉䅅䅁䙁䅁䅁睁䵁䅁䅁权摁䅁䅁权呂䅁䅁权䙁䅁䅁兂䅁䅁䅁䱯氷䅑䅅䅁䉁䅁䅁兂䵂㑎䉬余瑕䅑杷允䅁䅁䅕䅁䑁䅁䅷䅁䭁䉁䄰䅁䭁䙁䅍䅁䭁䅁䅕䅁䙁䅁䅁䅁䅂畑䅚允䅁䅁䅅䅁䙁䕁㉡⼸唳䍵䄵䍄䉁䅁䅁兂䅁䅁䅍䅄䅁䅁䅯杈䅁䅁䅯允䅁䅁䅯兂䅁䅁䅕䅁䅁䥁慃唵䉁䅁䅁允䅁䅁䅕積積積積稰䴸䅉䅅䅁䙁䅁䅁睁䵁䅁䅁权敁䅁䅁权呂䅁䅁权䙁䅁䅁兂䅁䅁䅁乁汔䅑䅅䅁䉁䅁䅁兂汁潂噇㑑獳䅑杷允䅁䅁䅑䅁䑁䅁䅷䅁䭁䕁䄸䅁䭁䕁䄴䅁䙁䅁䅁䅁䅂⭎䅚允䅁䅁䅅䅁䙁䅁塲㍯㥁桃䅆䍄䉁䅁䅁䅂䅁䅁䅍䅄䅁䅁䅯睔䅁䅁䅯杔䅁䅁䅕䅁䅁䥁奃唵䉁䅁䅁允䅁䅁䅕⽷潕䥘䌯呸䴸䅉䅅䅁䙁䅁䅁睁䵁䅁䅁权敁䅁䅁权呂䅁䅁权䙁䅁䅁兂䅁䅁䅁䩯氷䅑䅅䅁䉁䅁䅁兂橁⼲⭬湡煷䅑杷允䅁䅁䅑䅁䑁䅁䅷䅁䭁䕁䄸䅁䭁䕁䄴䅁䙁䅁䅁䅁䅂伶䅖允䅁䅁䅅䅁䙁佁剸䉵䘶砶䅆䍄䉁䅁䅁兂䅁䅁䅍䅄䅁䅁䅯䅁䅁䅁䅯睕䅁䅁䅯兂䅁䅁䅕䅁䅁䭁奁欵䉁䅁䅁允䅁䅁䅕硢䑋䵷䉯き䵁䅉䅅䅁䕁䅁䅁睁䵁䅁䅁权偂䅁䅁权佂䅁䅁兂䅁䅁䅁䙧浘䅑䅅䅁䉁䅁䅁兂䭁㘱睎児兯䅑杷允䅁䅁䅕䅁䑁䅁䅷䅁䭁䅁䅁䅁䭁䅁䅅䅁䭁䅁䅕䅁䙁䅁䅁䅁䅃整䅖允䅁䅁䅅䅁䙁䩁婱婭婭摭⽫䍄䉁䅁䅁䅂䅁䅁䅍䅄䅁䅁䅯睔䅁䅁䅯杔䅁䅁䅕䅁䅁䅁䩄唵䉁䅁䅁允䅁䅁䅕歲桦桥畓稫䴸䅉䅅䅁䙁䅁䅁睁䵁䅁䅁权慁䅁䅁权呂䅁䅁权䙁䅁䅁兂䅁䅁䅁䱯汦䅑䅅䅁䉁䅁䅁兂⽁噎㘶敓㕷䅑杷允䅁䅁䅕䅁䑁䅁䅷䅁䭁䅁䅁䅁䭁䅁䅅䅁䭁䅁䅕䅁䙁䅁䅁䅁杁⭸䅖允䅁䅁䅅䅁䙁䑁䬰㘱睎摐⽯䍄䉁䅁䅁兂䅁䅁䅍䅄䅁䅁䅯杈䅁䅁䅯睕䅁䅁䅯兂䅁䅁䅕䅁䅁䝁㙁欵䉁䅁䅁允䅁䅁䅕倹唳佥浬䕊䵁䅉䅅䅁䕁䅁䅁睁䵁䅁䅁权偂䅁䅁权佂䅁䅁兂䅁䅁䅁偙汪䅑䅅䅁䉁䅁䅁兂㥁瑃橥䑣到䅑杷允䅁䅁䅕䅁䑁䅁䅷䅁䭁䉁䄰䅁䭁䅁䅅䅁䭁䅁䅕䅁䙁䅁䅁䅁䅄畒䅚允䅁䅁䅅䅁䙁䭁䠵場啯瑲⽣䍄䉁䅁䅁兂䅁䅁䅍䅄䅁䅁䅯杇䅁䅁䅯允䅁䅁䅯兂䅁䅁䅕䅁䅁佁啂欵䉁䅁䅁允䅁䅁䅕䡰㥁瑃橥䐶䴸䅉䅅䅁䕁䅁䅁睁䵁䅁䅁权偂䅁䅁权佂䅁䅁兂䅁䅁䅁䡷浐䅑䅅䅁䉁䅁䅁兂䅁䅁䅁䅁䵁䅑杷允䅁䅁䅕䅁䑁䅁䅷䅁䭁䉁䄴䅁䭁䙁䅍䅁䭁䅁䅕䅁䙁䅁䅁䅁䅁但䅚允䅁䅁䅅䅁䙁䝁匸㡧䭄匴䅬䍄䉁䅁䅁兂䅁䅁䅍䅄䅁䅁䅯䅁䅁䅁䅯允䅁䅁䅯兂䅁䅁䅕䅁䅁䍁睂欵䉁䅁䅁允䅁䅁䅕䉵䘶ㄶ㑇樳䴸䅉䅅䅁䕁䅁䅁睁䵁䅁䅁权偂䅁䅁权佂䅁䅁兂䅁䅁䅁临汦䅑䅅䅁䉁䅁䅁兂㉄䙋偹癷䥕䅑杷允䅁䅁䅑䅁䑁䅁䅷䅁䭁䕁䄸䅁䭁䕁䄴䅁䙁䅁䅁䅁杁敏䅚允䅁䅁䅅䅁䙁佁㙆䭆䠵儴䄵䍄䉁䅁䅁䅂䅁䅁䅍䅄䅁䅁䅯睔䅁䅁䅯杔䅁䅁䅕䅁䅁䅁桁欵䉁䅁䅁允䅁䅁䅕浚浚浚浚䕅䵁䅉䅅䅁䙁䅁䅁睁䵁䅁䅁权摁䅁䅁权呂䅁䅁权䙁䅁䅁兂䅁䅁䅁䱉汌䅑䅅䅁䉁䅁䅁兂䭁㘱睎捐瑯䅑杷允䅁䅁䅕䅁䑁䅁䅷䅁䭁䉁䄴䅁䭁䅁䅅䅁䭁䅁䅕䅁䙁䅁䅁䅁杁佡䅚允䅁䅁䅅䅁䙁䅁䅁䅁䅁乁⽁䍄䉁䅁䅁䅂䅁䅁䅍䅄䅁䅁䅯杇䅁䅁䅯䅔䅁䅁䅯䅉䅁䅁䅅䅁䉁䅁䅁兂穁積積㍍㑍䅑杷允䅁䅁䅕䅁䑁䅁䅷䅁䭁䉁䄰䅁䭁䅁䅅䅁䭁䅁䅕䅁䙁䅁䅁䅁杂佒䅚允䅁䅁䅅䅁䙁䭁䠵場啯瑲⽣䍄䉁䅁䅁䅂䅁䅁䅍䅄䅁䅁䅯睔䅁䅁䅯杔䅁䅁䅕䅁䅁佁䝁欵䉁䅁䅁允䅁䅁䅕児塲㍯㥁歅䵁䅉䅅䅁䙁䅁䅁睁䵁䅁䅁权慁䅁䅁权呂䅁䅁权䙁䅁䅁兂䅁䅁䅁䍧浘䅑䅅䅁䉁䅁䅁兂䥂場啯煲㙣䅑杷允䅁䅁䅕䅁䑁䅁䅷䅁䭁䅁䅁䅁䭁䙁䅍䅁䭁䅁䅕䅁䙁䅁䅁䅁杁敁䅚允䅁䅁䅅䅁䙁䭁硲欰椱䑣䅊䍄䉁䅁䅁䅂䅁䅁䅍䅄䅁䅁䅯睔䅁䅁䅯杔䅁䅁䅕䅁䅁佁歃唵䉁䅁䅁允䅁䅁䅕㘱睎児塲稰䴸䅉䅅䅁䕁䅁䅁睁䵁䅁䅁权偂䅁䅁权佂䅁䅁兂䅁䅁䅁䕷浮䅑䅅䅁䉁䅁䅁兂䥂場啯歲剣䅑杷允䅁䅁䅕䅁䑁䅁䅷䅁䭁䅁䅁䅁䭁䅁䅅䅁䭁䅁䅕䅁䙁䅁䅁䅁杄⭆䅚允䅁䅁䅅䅁䙁䱁敧敨剴乵⼴䍄䉁䅁䅁兂䅁䅁䅍䅄䅁䅁䅯先䅁䅁䅯睕䅁䅁䅯兂䅁䅁䅕䅁䅁䝁婄唵䉁䅁䅁允䅁䅁䅕⽷潕䥘䌯啌䵁䅉䅅䅁䕁䅁䅁睁䵁䅁䅁权晁䅁䅁权䵂䅁䅁权杁䅁䅁允䅁䅁䅅䅁䙁偁潙䥘䌯呎䅊䍄䉁䅁䅁䅂䅁䅁䅍䅄䅁䅁䅯睔䅁䅁䅯杔䅁䅁䅕䅁䅁䭁㑁欵䉁䅁䅁允䅁䅁䅕歲桦桥畓啄䵁䅉䅅䅁䙁䅁䅁睁䵁䅁䅁权敁䅁䅁权呂䅁䅁权䙁䅁䅁兂䅁䅁䅁䑯浈䅑䅅䅁䉁䅁䅁兂䥂場啯歲浣䅑杷允䅁䅁䅑䅁䑁䅁䅷䅁䭁䕁䄸䅁䭁䕁䄴䅁䙁䅁䅁䅁杂⭕䅚允䅁䅁䅅䅁䙁䅁塲㍯㥁桃䅂䍄䉁䅁䅁兂䅁䅁䅍䅄䅁䅁䅯杇䅁䅁䅯允䅁䅁䅯兂䅁䅁䅕䅁䅁䵁硁欵䉁䅁䅁允䅁䅁䅕䡰㥁瑃橥䐶䴸䅉䅅䅁䙁䅁䅁睁䵁䅁䅁权敁䅁䅁权䉁䅁䅁权䙁䅁䅁兂䅁䅁䅁䝧浺䅑䅅䅁䉁䅁䅁兂䅁䅁䅁䅁兄睐杷允䅁䅁䅑䅁䑁䅁䅷䅁䭁䕁䄸䅁䭁䕁䄴䅁䙁䅁䅁䅁䅄佹䅖允䅁䅁䅅䅁䙁乁橥䑣䬰⼱⽳䍄䉁䅁䅁兂䅁䅁䅍䅄䅁䅁䅯䅁䅁䅁䅯允䅁䅁䅯兂䅁䅁䅕䅁䅁䵁㝃唵䉁䅁䅁允䅁䅁䅕児塲㍯㥁樲䴸䅉䅅䅁䙁䅁䅁睁䵁䅁䅁权敁䅁䅁权䉁䅁䅁权䙁䅁䅁兂䅁䅁䅁䝯浢䅑䅅䅁䉁䅁䅁兂䅁䅁䅁䅁兄睐杷允䅁䅁䅕䅁䑁䅁䅷䅁䭁䅁䅁䅁䭁䅁䅅䅁䭁䅁䅕䅁䙁䅁䅁䅁䅃⭙䅚允䅁䅁䅅䅁䙁䱁敧敨剴乵⼴䍄䉁䅁䅁兂䅁䅁䅍䅄䅁䅁䅯睈䅁䅁䅯睕䅁䅁䅯兂䅁䅁䅕䅁䅁䥁权唵䉁䅁䅁允䅁䅁䅕䵮村䡳潉啍䵁䅉䅅䅁䕁䅁䅁睁䵁䅁䅁权偂䅁䅁权佂䅁䅁兂䅁䅁䅁䉑浲䅑䅅䅁䉁䅁䅁兂卂䉵䘶ㄶ剅䅑杷允䅁䅁䅕䅁䑁䅁䅷䅁䭁䉁䄰䅁䭁䙁䅍䅁䭁䅁䅕䅁䙁䅁䅁䅁䅁⭳䅖允䅁䅁䅅䅁䙁䅁塲㍯㥁楹䄱䍄䉁䅁䅁䅂䅁䅁䅍䅄䅁䅁䅯睔䅁䅁䅯杔䅁䅁䅕䅁䅁䕁佄唵䉁䅁䅁允䅁䅁䅕体㙆䭆䠵啂䵁䅉䅅䅁䙁䅁䅁睁䵁䅁䅁权䅁䅁䅁权䉁䅁䅁权䙁䅁䅁兂䅁䅁䅁䙙洷䅑䅅䅁䉁䅁䅁兂㑃潈牘払敪睐杷允䅁䅁䅕䅁䑁䅁䅷䅁䭁䅁䅁䅁䭁䅁䅅䅁䭁䅁䅕䅁䙁䅁䅁䅁权效䅚允䅁䅁䅅䅁䙁䱁敧敨剴乵⼴䍄䉁䅁䅁兂䅁䅁䅍䅄䅁䅁䅯杇䅁䅁䅯允䅁䅁䅯兂䅁䅁䅕䅁䅁䭁穂欵䉁䅁䅁允䅁䅁䅕䡰㥁瑃橥䐶䴸䅉䅅䅁䙁䅁䅁睁䵁䅁䅁权䅁䅁䅁权呂䅁䅁权䙁䅁䅁兂䅁䅁䅁䙑浲䅑䅅䅁䉁䅁䅁兂煃搸乊瑙穁䅑杷允䅁䅁䅑䅁䑁䅁䅷䅁䭁䕁䄸䅁䭁䕁䄴䅁䙁䅁䅁䅁䅂畒䅚允䅁䅁䅅䅁䙁䕁桪桥畓硒䅆䍄䉁䅁䅁兂䅁䅁䅍䅄䅁䅁䅯睈䅁䅁䅯允䅁䅁䅯兂䅁䅁䅕䅁䅁䍁桁欵䉁䅁䅁允䅁䅁䅕椹捨㡪ㅌ䐴䴸䅉䅅䅁䙁䅁䅁睁䵁䅁䅁权摁䅁䅁权䉁䅁䅁权䙁䅁䅁兂䅁䅁䅁䉷浶䅑䅅䅁䉁䅁䅁兂晁敨剴䉵嘷睐杷允䅁䅁䅕䅁䑁䅁䅷䅁䭁䅁䅁䅁䭁䙁䅍䅁䭁䅁䅕䅁䙁䅁䅁䅁䅄畹䅖允䅁䅁䅅䅁䙁䝁渳㘫确樸䅊䍄䉁䅁䅁兂䅁䅁䅍䅄䅁䅁䅯睈䅁䅁䅯睕䅁䅁䅯兂䅁䅁䅕䅁䅁䍁歃唵䉁䅁䅁允䅁䅁䅕䉵䘶ㄶ㑆䕍䵁䅉䅅䅁䕁䅁䅁睁䵁䅁䅁权偂䅁䅁权佂䅁䅁兂䅁䅁䅁䡯浄䅑䅅䅁䉁䅁䅁兂䅁䅁䅁䅁䵁䅑杷允䅁䅁䅕䅁䑁䅁䅷䅁䭁䉁䄴䅁䭁䙁䅍䅁䭁䅁䅕䅁䙁䅁䅁䅁杂⭌䅚允䅁䅁䅅䅁䙁䕁桪桥畓祒䅚䍄䉁䅁䅁兂䅁䅁䅍䅄䅁䅁䅯杇䅁䅁䅯允䅁䅁䅯兂䅁䅁䅕䅁䅁䕁⽁欵䉁䅁䅁允䅁䅁䅕䡰㥁瑃橥䐶䴸䅉䅅䅁䙁䅁䅁睁䵁䅁䅁权摁䅁䅁权呂䅁䅁权䙁䅁䅁兂䅁䅁䅁䡁浄䅑䅅䅁䉁䅁䅁兂㍁啩杆刵畁䅑杷允䅁䅁䅕䅁䑁䅁䅷䅁䭁䉁䄰䅁䭁䙁䅍䅁䭁䅁䅕䅁䙁䅁䅁䅁杂畲䅖允䅁䅁䅅䅁䙁乁佮ㄹ橐印䄱䍄䉁䅁䅁兂䅁䅁䅍䅄䅁䅁䅯先䅁䅁䅯睕䅁䅁䅯兂䅁䅁䅕䅁䅁䅁灁欵䉁䅁䅁允䅁䅁䅕浚浚浚浢歌䵁䅉䅅䅁䕁䅁䅁睁䵁䅁䅁权偂䅁䅁权佂䅁䅁兂䅁䅁䅁䙷浘䅑䅅䅁䉁䅁䅁兂䭁㘱睎児兯䅑杷允䅁䅁䅑䅁䑁䅁䅷䅁䭁䕁䄸䅁䭁䕁䄴䅁䙁䅁䅁䅁杂整䅖允䅁䅁䅅䅁䙁䵁䴳䵺䵺乺⽷䍄䉁䅁䅁䅂䅁䅁䅍䅄䅁䅁䅯睔䅁䅁䅯杔䅁䅁䅕䅁䅁佁乂欵䉁䅁䅁允䅁䅁䅕䥘䌯匹捨啅䵁䅉䅅䅁䙁䅁䅁睁䵁䅁䅁权晁䅁䅁权䉁䅁䅁权䙁䅁䅁兂䅁䅁䅁䡷浌䅑䅅䅁䉁䅁䅁兂卂䉵䘶ㄶ杈睐杷允䅁䅁䅑䅁䑁䅁䅷䅁䭁䕁䄸䅁䭁䕁䄴䅁䙁䅁䅁䅁杁散䅚允䅁䅁䅅䅁䙁䵁䴳䵺䵺䅺䅸䍄䉁䅁䅁兂䅁䅁䅍䅄䅁䅁䅯先䅁䅁䅯允䅁䅁䅯兂䅁䅁䅕䅁䅁䭁䩄唵䉁䅁䅁允䅁䅁䅕㘱睎児塲稰䴸䅉䅅䅁䕁䅁䅁睁䵁䅁䅁权偂䅁䅁权佂䅁䅁兂䅁䅁䅁䵙汔䅑䅅䅁䉁䅁䅁兂慃婭婭婭ㅮ睐杷允䅁䅁䅑䅁䑁䅁䅷䅁䭁䕁䄸䅁䭁䕁䄴䅁䙁䅁䅁䅁权敃䅚允䅁䅁䅅䅁䙁佁㙆䭆䠵刴䅆䍄䉁䅁䅁兂䅁䅁䅍䅄䅁䅁䅯先䅁䅁䅯睕䅁䅁䅯兂䅁䅁䅕䅁䅁䕁畄唵䉁䅁䅁允䅁䅁䅕灰䕶䱉祃啌䵁䅉䅅䅁䙁䅁䅁睁䵁䅁䅁权摁䅁䅁权呂䅁䅁权䙁䅁䅁兂䅁䅁䅁䔴浘䅑䅅䅁䉁䅁䅁兂ㅂ硫䕧潖甴䅑杷允䅁䅁䅕䅁䑁䅁䅷䅁䭁䅁䅁䅁䭁䙁䅍䅁䭁䅁䅕䅁䙁䅁䅁䅁䅁⭢䅚允䅁䅁䅅䅁䙁䙁橔婰䕶䐴䅎䍄䉁䅁䅁兂䅁䅁䅍䅄䅁䅁䅯先䅁䅁䅯睕䅁䅁䅯兂䅁䅁䅕䅁䅁䥁煃唵䉁䅁䅁允䅁䅁䅕挲㌷⭕汏啌䵁䅉䅅䅁䕁䅁䅁睁䵁䅁䅁权偂䅁䅁权佂䅁䅁兂䅁䅁䅁䡙洳䅑䅅䅁䉁䅁䅁兂偃癷潕䥘䴸䅑杷允䅁䅁䅕䅁䑁䅁䅷䅁䭁䉁䄰䅁䭁䅁䅅䅁䭁䅁䅕䅁䙁䅁䅁䅁䅃佋䅚允䅁䅁䅅䅁䙁䝁浚浚浚瑚⽙䍄䉁䅁䅁兂䅁䅁䅍䅄䅁䅁䅯先䅁䅁䅯睕䅁䅁䅯兂䅁䅁䅕䅁䅁䅁⽂欵䉁䅁䅁允䅁䅁䅕䉲慸䑚晵啌䵁䅉䅅䅁䕁䅁䅁睁䵁䅁䅁权偂䅁䅁权佂䅁䅁兂䅁䅁䅁䵉汘䅑䅅䅁䉁䅁䅁兂䅁䅁䅁䅁い睐杷允䅁䅁䅑䅁䑁䅁䅷䅁䭁䕁䄸䅁䭁䕁䄴䅁䙁䅁䅁䅁杂畃䅚允䅁䅁䅅䅁䙁䕁桪桥畓硒䅊䍄䉁䅁䅁䅂䅁䅁䅍䅄䅁䅁䅯睔䅁䅁䅯杔䅁䅁䅕䅁䅁䭁時欵䉁䅁䅁允䅁䅁䅕積積積積い䵁䅉䅅䅁䙁䅁䅁睁䵁䅁䅁权慁䅁䅁权䉁䅁䅁权䙁䅁䅁兂䅁䅁䅁䩯汔䅑䅅䅁䉁䅁䅁兂䅁䅁䅁䅁杄睐杷允䅁䅁䅕䅁䑁䅁䅷䅁䭁䉁䅷䅁䭁䙁䅍䅁䭁䅁䅕䅁䙁䅁䅁䅁䅄⭦䅚允䅁䅁䅅䅁䙁䵁㉬灶愸祲䄱䍄䉁䅁䅁兂䅁䅁䅍䅄䅁䅁䅯先䅁䅁䅯允䅁䅁䅯兂䅁䅁䅕䅁䅁䥁杄唵䉁䅁䅁允䅁䅁䅕㘱睎児塲稰䴸䅉䅅䅁䕁䅁䅁睁䵁䅁䅁权䅁䅁䅁权䵂䅁䅁权杁䅁䅁允䅁䅁䅅䅁䙁䕁桪桥畓穒䅊䍄䉁䅁䅁兂䅁䅁䅍䅄䅁䅁䅯䅁䅁䅁䅯睕䅁䅁䅯兂䅁䅁䅕䅁䅁䅁䡂欵䉁䅁䅁允䅁䅁䅕潅䅐煹䙈き䵁䅉䅅䅁䙁䅁䅁睁䵁䅁䅁权敁䅁䅁权呂䅁䅁权䙁䅁䅁兂䅁䅁䅁䘴洳䅑䅅䅁䉁䅁䅁兂剃堷⽷噎椴䅑杷允䅁䅁䅕䅁䑁䅁䅷䅁䭁䅁䅁䅁䭁䙁䅍䅁䭁䅁䅕䅁䙁䅁䅁䅁杄⭚䅚允䅁䅁䅅䅁䙁䙁橔婰䕶䐴䅎䍄䉁䅁䅁兂䅁䅁䅍䅄䅁䅁䅯杈䅁䅁䅯允䅁䅁䅯兂䅁䅁䅕䅁䅁䕁⭃唵䉁䅁䅁允䅁䅁䅕積積積積稰䴸䅉䅅䅁䙁䅁䅁睁䵁䅁䅁权慁䅁䅁权呂䅁䅁权䙁䅁䅁兂䅁䅁䅁䡉浈䅑䅅䅁䉁䅁䅁兂癁匳䝑噧㝕䅑杷允䅁䅁䅕䅁䑁䅁䅷䅁䭁䉁䅷䅁䭁䙁䅍䅁䭁䅁䅕䅁䙁䅁䅁䅁杄敔䅚允䅁䅁䅅䅁䙁䝁匸㡧䭄卙䄵䍄䉁䅁䅁䅂䅁䅁䅍䅄䅁䅁䅯睔䅁䅁䅯杔䅁䅁䅕䅁䅁䭁奃唵䉁䅁䅁允䅁䅁䅕瑃橥䑣䬰穸䴸䅉䅅䅁䕁䅁䅁睁䵁䅁䅁权偂䅁䅁权佂䅁䅁兂䅁䅁䅁䑙洳䅑䅅䅁䉁䅁䅁兂䑄匹捨㡪䱉䅑杷允䅁䅁䅑䅁䑁䅁䅷䅁䭁䕁䄸䅁䭁䕁䄴䅁䙁䅁䅁䅁杂⭆䅚允䅁䅁䅅䅁䙁䑁積積積硍䅎䍄䉁䅁䅁䅂䅁䅁䅍䅄䅁䅁䅯睔䅁䅁䅯杔䅁䅁䅕䅁䅁䕁㍂欵䉁䅁䅁允䅁䅁䅕児塲㍯㥁䕄䵁䅉䅅䅁䙁䅁䅁睁䵁䅁䅁权摁䅁䅁权䉁䅁䅁权䙁䅁䅁兂䅁䅁䅁偁汶䅑䅅䅁䉁䅁䅁兂晁敨剴䉵嘷睐杷允䅁䅁䅕䅁䑁䅁䅷䅁䭁䉁䅯䅁䭁䙁䅍䅁䭁䅁䅕䅁䙁䅁䅁䅁䅃畅䅚允䅁䅁䅅䅁䙁䅁䉡啬䱏䑔䅰䍄䉁䅁䅁兂䅁䅁䅍䅄䅁䅁䅯䅈䅁䅁䅯睕䅁䅁䅯兂䅁䅁䅕䅁䅁䍁歄唵䉁䅁䅁允䅁䅁䅕桙奂扏䥒歌䵁䅉䅅䅁䙁䅁䅁睁䵁䅁䅁权捁䅁䅁权䉁䅁䅁权䙁䅁䅁兂䅁䅁䅁䭁汐䅑䅅䅁䉁䅁䅁兂偃癷潕䥘匯睐杷允䅁䅁䅑䅁䑁䅁䅷䅁䭁䕁䄸䅁䭁䕁䄴䅁䙁䅁䅁䅁䅄佡䅚允䅁䅁䅅䅁䙁䡁㥅瑃橥䅣䄱䍄䉁䅁䅁兂䅁䅁䅍䅄䅁䅁䅯䅁䅁䅁䅯睕䅁䅁䅯兂䅁䅁䅕䅁䅁䕁䵁欵䉁䅁䅁允䅁䅁䅕䙅㕧䵴坩歍䵁䅉䅅䅁䙁䅁䅁睁䵁䅁䅁权晁䅁䅁权呂䅁䅁权䙁䅁䅁兂䅁䅁䅁䔴浦䅑䅅䅁䉁䅁䅁兂䕁杖琴桳砰䅑杷允䅁䅁䅑䅁䑁䅁䅷䅁䭁䕁䄸䅁䭁䕁䄴䅁䙁䅁䅁䅁䅄敥䅚允䅁䅁䅅䅁䙁䡁啳歲桦来䅸䍄䉁䅁䅁兂䅁䅁䅍䅄䅁䅁䅯杇䅁䅁䅯睕䅁䅁䅯兂䅁䅁䅕䅁䅁䥁奃唵䉁䅁䅁允䅁䅁䅕瑃橥䑣焳䕏䵁䅉䅅䅁䙁䅁䅁睁䵁䅁䅁权䅁䅁䅁权呂䅁䅁权䙁䅁䅁兂䅁䅁䅁䩁汦䅑䅅䅁䉁䅁䅁兂㡃䩤奍䡂睙䅑杷允䅁䅁䅕䅁䑁䅁䅷䅁䭁䉁䅯䅁䭁䅁䅅䅁䭁䅁䅕䅁䙁䅁䅁䅁䅂佲䅖允䅁䅁䅅䅁䙁䅁䅁䅁䅁佁⽁䍄䉁䅁䅁兂䅁䅁䅍䅄䅁䅁䅯䅈䅁䅁䅯睕䅁䅁䅯兂䅁䅁䅕䅁䅁䥁䩂欵䉁䅁䅁允䅁䅁䅕硢䑋䵷桰歌䵁䅉䅅䅁䙁䅁䅁睁䵁䅁䅁权晁䅁䅁权䉁䅁䅁权䙁䅁䅁兂䅁䅁䅁䡷洯䅑䅅䅁䉁䅁䅁兂卂䉵䘶ㄶ杈睐杷允䅁䅁䅕䅁䑁䅁䅷䅁䭁䉁䄰䅁䭁䅁䅅䅁䭁䅁䅕䅁䙁䅁䅁䅁䅁敍䅚允䅁䅁䅅䅁䙁䭁䠵場啯瑲⽣䍄䉁䅁䅁䅂䅁䅁䅍䅄䅁䅁䅯䅈䅁䅁䅯䅔䅁䅁䅯䅉䅁䅁䅅䅁䉁䅁䅁兂㥁瑃橥䑣瀰䅑杷允䅁䅁䅕䅁䑁䅁䅷䅁䭁䅁䅁䅁䭁䅁䅅䅁䭁䅁䅕䅁䙁䅁䅁䅁杁⭎䅚允䅁䅁䅅䅁䙁䱁敧敨剴乵⼴䍄䉁䅁䅁䅂䅁䅁䅍䅄䅁䅁䅯睔䅁䅁䅯杔䅁䅁䅕䅁䅁䭁㉃唵䉁䅁䅁允䅁䅁䅕椹捨㡪ㅌ䐴䴸䅉䅅䅁䙁䅁䅁睁䵁䅁䅁权敁䅁䅁权䉁䅁䅁权䙁䅁䅁兂䅁䅁䅁䑑浢䅑䅅䅁䉁䅁䅁兂䑄匹捨㡪噌睐杷允䅁䅁䅕䅁䑁䅁䅷䅁䭁䅁䅁䅁䭁䙁䅍䅁䭁䅁䅕䅁䙁䅁䅁䅁䅂⭊䅚允䅁䅁䅅䅁䙁佁兘瑉㕶橐䅎䍄䉁䅁䅁兂䅁䅁䅍䅄䅁䅁䅯先䅁䅁䅯允䅁䅁䅯兂䅁䅁䅕䅁䅁䵁㥃唵䉁䅁䅁允䅁䅁䅕㘱睎児塲稰䴸䅉䅅䅁䙁䅁䅁睁䵁䅁䅁权䅁䅁䅁权呂䅁䅁权䙁䅁䅁兂䅁䅁䅁䙑浈䅑䅅䅁䉁䅁䅁兂㕁䵴㉨瑶稸䅑杷允䅁䅁䅑䅁䑁䅁䅷䅁䭁䕁䄸䅁䭁䕁䄴䅁䙁䅁䅁䅁权畭䅖允䅁䅁䅅䅁䙁佁㙆䭆䠵挴⽯䍄䉁䅁䅁兂䅁䅁䅍䅄䅁䅁䅯先䅁䅁䅯允䅁䅁䅯兂䅁䅁䅕䅁䅁䥁佂欵䉁䅁䅁允䅁䅁䅕歲桦桥畓稱䴸䅉䅅䅁䙁䅁䅁睁䵁䅁䅁权晁䅁䅁权䉁䅁䅁权䙁䅁䅁兂䅁䅁䅁䴴氳䅑䅅䅁䉁䅁䅁兂歃䑣䬰㘱材睐杷允䅁䅁䅑䅁䑁䅁䅷䅁䭁䕁䄸䅁䭁䕁䄴䅁䙁䅁䅁䅁权佳䅖允䅁䅁䅅䅁䙁䍁捬㡪ㅌ之⽷䍄䉁䅁䅁兂䅁䅁䅍䅄䅁䅁䅯杇䅁䅁䅯允䅁䅁䅯兂䅁䅁䅕䅁䅁佁煄唵䉁䅁䅁允䅁䅁䅕積積積積稴䴸䅉䅅䅁䙁䅁䅁睁䵁䅁䅁权摁䅁䅁权䉁䅁䅁权䙁䅁䅁兂䅁䅁䅁䭙氯䅑䅅䅁䉁䅁䅁兂塄㍯㥁瑃呦睐杷允䅁䅁䅕䅁䑁䅁䅷䅁䭁䅁䅁䅁䭁䙁䅍䅁䭁䅁䅕䅁䙁䅁䅁䅁䅂敤䅚允䅁䅁䅅䅁䙁䙁橔婰䕶䑁䅒䍄䉁䅁䅁兂䅁䅁䅍䅄䅁䅁䅯䅈䅁䅁䅯允䅁䅁䅯兂䅁䅁䅕䅁䅁䍁桁欵䉁䅁䅁允䅁䅁䅕歲桦桥畓稱䴸䅉䅅䅁䕁䅁䅁睁䵁䅁䅁权偂䅁䅁权佂䅁䅁兂䅁䅁䅁䙉浺䅑䅅䅁䉁䅁䅁兂慃婭婭婭偫䅑杷允䅁䅁䅕䅁䑁䅁䅷䅁䭁䅁䅁䅁䭁䙁䅍䅁䭁䅁䅕䅁䙁䅁䅁䅁杁當䅖允䅁䅁䅅䅁䙁偁周㘴扗䑨䅊䍄䉁䅁䅁兂䅁䅁䅍䅄䅁䅁䅯䅁䅁䅁䅯允䅁䅁䅯兂䅁䅁䅕䅁䅁䝁楃唵䉁䅁䅁允䅁䅁䅕灭婭婭婭吲䴸䅉䅅䅁䙁䅁䅁睁䵁䅁䅁权慁䅁䅁权䉁䅁䅁权䙁䅁䅁兂䅁䅁䅁䍯浔䅑䅅䅁䉁䅁䅁兂歃䑣䬰㘱潐睐杷允䅁䅁䅕䅁䑁䅁䅷䅁䭁䉁䅯䅁䭁䙁䅍䅁䭁䅁䅕䅁䙁䅁䅁䅁权敃䅚允䅁䅁䅅䅁䙁䕁㉡⼸唳䑇䅰䍄䉁䅁䅁兂䅁䅁䅍䅄䅁䅁䅯睈䅁䅁䅯睕䅁䅁䅯兂䅁䅁䅕䅁䅁佁扂欵䉁䅁䅁允䅁䅁䅕匰扌堫䬴啍䵁䅉䅅䅁䙁䅁䅁睁䵁䅁䅁权慁䅁䅁权呂䅁䅁权䙁䅁䅁兂䅁䅁䅁䝧洷䅑䅅䅁䉁䅁䅁兂癁匳䝑噧㝕䅑杷允䅁䅁䅕䅁䑁䅁䅷䅁䭁䅁䅁䅁䭁䅁䅅䅁䭁䅁䅕䅁䙁䅁䅁䅁䅂敚䅚允䅁䅁䅅䅁䙁䱁敧敨剴乵⼴䍄䉁䅁䅁兂䅁䅁䅍䅄䅁䅁䅯杈䅁䅁䅯允䅁䅁䅯兂䅁䅁䅕䅁䅁䍁扃唵䉁䅁䅁允䅁䅁䅕積積積積稰䴸䅉䅅䅁䙁䅁䅁睁䵁䅁䅁权䅁䅁䅁权呂䅁䅁权䙁䅁䅁兂䅁䅁䅁䥧浄䅑䅅䅁䉁䅁䅁兂⭄䠱灪癊穅䅑杷允䅁䅁䅕䅁䑁䅁䅷䅁䭁䉁䄰䅁䭁䅁䅅䅁䭁䅁䅕䅁䙁䅁䅁䅁杄敉䅚允䅁䅁䅅䅁䙁䉁䘫ㄶ㑇瑈⽕䍄䉁䅁䅁䅂䅁䅁䅍䅄䅁䅁䅯睔䅁䅁䅯杔䅁䅁䅕䅁䅁佁塁欵䉁䅁䅁允䅁䅁䅕㡪ㅌ䙋偹歅䵁䅉䅅䅁䕁䅁䅁睁䵁䅁䅁权偂䅁䅁权佂䅁䅁兂䅁䅁䅁䡷浌䅑䅅䅁䉁䅁䅁兂偃癷潕䥘䴸䅑杷允䅁䅁䅕䅁䑁䅁䅷䅁䭁䉁䅷䅁䭁䅁䅅䅁䭁䅁䅕䅁䙁䅁䅁䅁䅂攫䅖允䅁䅁䅅䅁䙁䉁䘫ㄶ㑇瑈⽕䍄䉁䅁䅁兂䅁䅁䅍䅄䅁䅁䅯䅁䅁䅁䅯睕䅁䅁䅯兂䅁䅁䅕䅁䅁䥁歁欵䉁䅁䅁允䅁䅁䅕搵楁⼲⭫き䵁䅉䅅䅁䕁䅁䅁睁䵁䅁䅁权偂䅁䅁权佂䅁䅁兂䅁䅁䅁䡧浪䅑䅅䅁䉁䅁䅁兂啁歲桦桥䵑䅑杷允䅁䅁䅕䅁䑁䅁䅷䅁䭁䅁䅁䅁䭁䅁䅅䅁䭁䅁䅕䅁䙁䅁䅁䅁杄畤䅚允䅁䅁䅅䅁䙁䱁敧敨剴乵⼴䍄䉁䅁䅁䅂䅁䅁䅍䅄䅁䅁䅯睔䅁䅁䅯杔䅁䅁䅕䅁䅁䥁佂欵䉁䅁䅁允䅁䅁䅕椹捨㡪ㅌ䕅䵁䅉䅅䅁䙁䅁䅁睁䵁䅁䅁权䅁䅁䅁权䉁䅁䅁权䙁䅁䅁兂䅁䅁䅁䩑汢䅑䅅䅁䉁䅁䅁兂慃婭婭婭婮睐杷允䅁䅁䅕䅁䑁䅁䅷䅁䭁䉁䄰䅁䭁䙁䅍䅁䭁䅁䅕䅁䙁䅁䅁䅁䅁敖䅚允䅁䅁䅅䅁䙁䵁ㅐ䙋偹楧䄵䍄䉁䅁䅁䅂䅁䅁䅍䅄䅁䅁䅯睔䅁䅁䅯杔䅁䅁䅕䅁䅁䝁瑄唵䉁䅁䅁允䅁䅁䅕浚浚浚浚䕅䵁䅉䅅䅁䕁䅁䅁睁䵁䅁䅁权偂䅁䅁权佂䅁䅁兂䅁䅁䅁䉧洳䅑䅅䅁䉁䅁䅁兂䭁㘱睎児兯䅑杷允䅁䅁䅕䅁䑁䅁䅷䅁䭁䉁䄰䅁䭁䅁䅅䅁䭁䅁䅕䅁䙁䅁䅁䅁䅁⭇䅚允䅁䅁䅅䅁䙁䉁䘫ㄶ㑇瑈⽕䍄䉁䅁䅁兂䅁䅁䅍䅄䅁䅁䅯䅁䅁䅁䅯允䅁䅁䅯兂䅁䅁䅕䅁䅁佁㑃唵䉁䅁䅁允䅁䅁䅕灭婭婭婭吲䴸䅉䅅䅁䙁䅁䅁睁䵁䅁䅁权敁䅁䅁权䉁䅁䅁权䙁䅁䅁兂䅁䅁䅁䑑洷䅑䅅䅁䉁䅁䅁兂䑄匹捨㡪噌睐杷允䅁䅁䅕䅁䑁䅁䅷䅁䭁䅁䅁䅁䭁䅁䅅䅁䭁䅁䅕䅁䙁䅁䅁䅁䅁畤䅚允䅁䅁䅅䅁䙁䱁敧敨剴乵⼴䍄䉁䅁䅁兂䅁䅁䅍䅄䅁䅁䅯杈䅁䅁䅯睕䅁䅁䅯兂䅁䅁䅕䅁䅁䕁獃唵䉁䅁䅁允䅁䅁䅕㝤昶楇搸か䵁䅉䅅䅁䕁䅁䅁睁䵁䅁䅁权偂䅁䅁权佂䅁䅁兂䅁䅁䅁乑汐䅑䅅䅁䉁䅁䅁兂晁敨剴䉵䠴䅑杷允䅁䅁䅕䅁䑁䅁䅷䅁䭁䉁䅯䅁䭁䙁䅍䅁䭁䅁䅕䅁䙁䅁䅁䅁䅄敒䅚允䅁䅁䅅䅁䙁䕁㍷啩杆呒䅴䍄䉁䅁䅁兂䅁䅁䅍䅄䅁䅁䅯先䅁䅁䅯允䅁䅁䅯兂䅁䅁䅕䅁䅁䍁楂欵䉁䅁䅁允䅁䅁䅕歲桦桥畓稱䴸䅉䅅䅁䙁䅁䅁睁䵁䅁䅁权䅁䅁䅁权䉁䅁䅁权䙁䅁䅁兂䅁䅁䅁䩷氯䅑䅅䅁䉁䅁䅁兂慃婭婭婭婮睐杷允䅁䅁䅕䅁䑁䅁䅷䅁䭁䅁䅁䅁䭁䅁䅅䅁䭁䅁䅕䅁䙁䅁䅁䅁杁位䅚允䅁䅁䅅䅁䙁䱁敧敨剴乵⼴䍄䉁䅁䅁兂䅁䅁䅍䅄䅁䅁䅯䅁䅁䅁䅯睕䅁䅁䅯兂䅁䅁䅕䅁䅁䍁潁欵䉁䅁䅁允䅁䅁䅕搵楁⼲⭫き䵁䅉䅅䅁䙁䅁䅁睁䵁䅁䅁权敁䅁䅁权呂䅁䅁权䙁䅁䅁兂䅁䅁䅁䩉汘䅑䅅䅁䉁䅁䅁兂䝁婧䑖㉩灷䅑杷允䅁䅁䅑䅁䑁䅁䅷䅁䭁䕁䄸䅁䭁䕁䄴䅁䙁䅁䅁䅁䅁敋䅚允䅁䅁䅅䅁䙁䅁塲㍯㥁桃䅊䍄䉁䅁䅁兂䅁䅁䅍䅄䅁䅁䅯䅁䅁䅁䅯睕䅁䅁䅯兂䅁䅁䅕䅁䅁䭁癃唵䉁䅁䅁允䅁䅁䅕歵䵫楁湳歍䵁䅉䅅䅁䙁䅁䅁睁䵁䅁䅁权捁䅁䅁权䉁䅁䅁权䙁䅁䅁兂䅁䅁䅁䑯浲䅑䅅䅁䉁䅁䅁兂㉄䙋偹癷奘睐杷允䅁䅁䅕䅁䑁䅁䅷䅁䭁䉁䅷䅁䭁䙁䅍䅁䭁䅁䅕䅁䙁䅁䅁䅁杁敺䅖允䅁䅁䅅䅁䙁䥁牘払敧卨䄵䍄䉁䅁䅁䅂䅁䅁䅍䅄䅁䅁䅯睔䅁䅁䅯杔䅁䅁䅕䅁䅁䕁䵁欵䉁䅁䅁允䅁䅁䅕䉵䘶ㄶ㑇歅䵁䅉䅅䅁䙁䅁䅁睁䵁䅁䅁权䅁䅁䅁权呂䅁䅁权䙁䅁䅁兂䅁䅁䅁䕁浔䅑䅅䅁䉁䅁䅁兂十㡧䭄捯穕䅑杷允䅁䅁䅕䅁䑁䅁䅷䅁䭁䉁䄰䅁䭁䙁䅍䅁䭁䅁䅕䅁䙁䅁䅁䅁权散䅚允䅁䅁䅅䅁䙁䑁䩥坑汄䍅䄵䍄䉁䅁䅁䅂䅁䅁䅍䅄䅁䅁䅯睔䅁䅁䅯杔䅁䅁䅕䅁䅁佁楁欵䉁䅁䅁允䅁䅁䅕⽷潕䥘䌯啅䵁䅉䅅䅁䕁䅁䅁睁䵁䅁䅁权偂䅁䅁权佂䅁䅁兂䅁䅁䅁䡯浶䅑䅅䅁䉁䅁䅁兂捂㡪ㅌ䙋乷䅑杷允䅁䅁䅕䅁䑁䅁䅷䅁䭁䉁䅷䅁䭁䙁䅍䅁䭁䅁䅕䅁䙁䅁䅁䅁䅁佹䅖允䅁䅁䅅䅁䙁䥁牘払敧卨䄵䍄䉁䅁䅁兂䅁䅁䅍䅄䅁䅁䅯䅁䅁䅁䅯睕䅁䅁䅯兂䅁䅁䅕䅁䅁䭁慄唵䉁䅁䅁允䅁䅁䅕䉯癯匳䝑き䵁䅉䅅䅁䕁䅁䅁睁䵁䅁䅁权兂䅁䅁权䵂䅁䅁权杁䅁䅁允䅁䅁䅅䅁䙁乁橥䑣䬰礱䅬䍄䉁䅁䅁兂䅁䅁䅍䅄䅁䅁䅯先䅁䅁䅯允䅁䅁䅯兂䅁䅁䅕䅁䅁䍁牄唵䉁䅁䅁允䅁䅁䅕㘱睎児塲稰䴸䅉䅅䅁䙁䅁䅁睁䵁䅁䅁权敁䅁䅁权䉁䅁䅁权䙁䅁䅁兂䅁䅁䅁䠴洷䅑䅅䅁䉁䅁䅁兂䅁䅁䅁䅁兄睐杷允䅁䅁䅕䅁䑁䅁䅷䅁䭁䅁䅁䅁䭁䙁䅍䅁䭁䅁䅕䅁䙁䅁䅁䅁杂敤䅚允䅁䅁䅅䅁䙁䙁橔婰䕶䑁䅒䍄䉁䅁䅁䅂䅁䅁䅍䅄䅁䅁䅯睔䅁䅁䅯杔䅁䅁䅕䅁䅁䍁⽃唵䉁䅁䅁允䅁䅁䅕歲桦桥畓稷䴸䅉䅅䅁䕁䅁䅁睁䵁䅁䅁权偂䅁䅁权佂䅁䅁兂䅁䅁䅁䵯汲䅑䅅䅁䉁䅁䅁兂䥂場啯歲㥦睐杷允䅁䅁䅕䅁䑁䅁䅷䅁䭁䉁䄴䅁䭁䙁䅍䅁䭁䅁䅕䅁䙁䅁䅁䅁权⬸䅖允䅁䅁䅅䅁䙁䡁潎敫㠱祐䅸䍄䉁䅁䅁兂䅁䅁䅍䅄䅁䅁䅯睈䅁䅁䅯允䅁䅁䅯兂䅁䅁䅕䅁䅁䕁䵄唵䉁䅁䅁允䅁䅁䅕䡰㥁瑃橥䐴䴸䅉䅅䅁䙁䅁䅁睁䵁䅁䅁权晁䅁䅁权呂䅁䅁权䙁䅁䅁兂䅁䅁䅁佧汘䅑䅅䅁䉁䅁䅁兂⭃确癯唳睑䅑杷允䅁䅁䅕䅁䑁䅁䅷䅁䭁䅁䅁䅁䭁䙁䅍䅁䭁䅁䅕䅁䙁䅁䅁䅁权攵䅖允䅁䅁䅅䅁䙁䉁䕫杖琴樰䅊䍄䉁䅁䅁䅂䅁䅁䅍䅄䅁䅁䅯睔䅁䅁䅯杔䅁䅁䅕䅁䅁䕁時欵䉁䅁䅁允䅁䅁䅕灭婭婭婭い䵁䅉䅅䅁䕁䅁䅁睁䵁䅁䅁权偂䅁䅁权佂䅁䅁兂䅁䅁䅁䝷洯䅑䅅䅁䉁䅁䅁兂䑄匹捨㡪䱉䅑杷允䅁䅁䅕䅁䑁䅁䅷䅁䭁䅁䅁䅁䭁䅁䅅䅁䭁䅁䅕䅁䙁䅁䅁䅁杁佂䅚允䅁䅁䅅䅁䙁䱁敧敨剴乵⼴䍄䉁䅁䅁兂䅁䅁䅍䅄䅁䅁䅯䅈䅁䅁䅯睕䅁䅁䅯兂䅁䅁䅕䅁䅁佁㍂欵䉁䅁䅁允䅁䅁䅕㉩湺㘫确啌䵁䅉䅅䅁䕁䅁䅁睁䵁䅁䅁权偂䅁䅁权佂䅁䅁兂䅁䅁䅁䩑汲䅑䅅䅁䉁䅁䅁兂慃婭婭婭䩮睐杷允䅁䅁䅕䅁䑁䅁䅷䅁䭁䉁䅷䅁䭁䙁䅍䅁䭁䅁䅕䅁䙁䅁䅁䅁䅄畁䅚允䅁䅁䅅䅁䙁偁潙䥘䌯卤䄱䍄䉁䅁䅁兂䅁䅁䅍䅄䅁䅁䅯先䅁䅁䅯睕䅁䅁䅯兂䅁䅁䅕䅁䅁䵁塂欵䉁䅁䅁允䅁䅁䅕⽷潕䥘䌫歌䵁䅉䅅䅁䕁䅁䅁睁䵁䅁䅁权偂䅁䅁权佂䅁䅁兂䅁䅁䅁佉氯䅑䅅䅁䉁䅁䅁兂捂㡪ㅌ䙋具䅑杷允䅁䅁䅑䅁䑁䅁䅷䅁䭁䕁䄸䅁䭁䕁䄴䅁䙁䅁䅁䅁杂敕䅚允䅁䅁䅅䅁䙁䑁積積積硍䅆䍄䉁䅁䅁兂䅁䅁䅍䅄䅁䅁䅯䅁䅁䅁䅯允䅁䅁䅯兂䅁䅁䅕䅁䅁䭁楂欵䉁䅁䅁允䅁䅁䅕䉵䘶ㄶ㑇樳䴸䅉䅅䅁䙁䅁䅁睁䵁䅁䅁权捁䅁䅁权呂䅁䅁权䙁䅁䅁兂䅁䅁䅁䑉浪䅑䅅䅁䉁䅁䅁兂奂扏䥔橤甴䅑杷允䅁䅁䅑䅁䑁䅁䅷䅁䭁䕁䄸䅁䭁䕁䄴䅁䙁䅁䅁䅁杂敱䅖允䅁䅁䅅䅁䙁䑁䬰㘱睎摐⽯䍄䉁䅁䅁䅂䅁䅁䅍䅄䅁䅁䅯睔䅁䅁䅯杔䅁䅁䅕䅁䅁佁煄唵䉁䅁䅁允䅁䅁䅕䭆䠵場啯啅䵁䅉䅅䅁䕁䅁䅁睁䵁䅁䅁权偂䅁䅁权佂䅁䅁兂䅁䅁䅁䅷浈䅑䅅䅁䉁䅁䅁兂灁䥘䌯匹內䅑杷允䅁䅁䅕䅁䑁䅁䅷䅁䭁䅁䅁䅁䭁䙁䅍䅁䭁䅁䅕䅁䙁䅁䅁䅁杄敆䅚允䅁䅁䅅䅁䙁䝁匸㡧䭄呁䅎䍄䉁䅁䅁兂䅁䅁䅍䅄䅁䅁䅯杇䅁䅁䅯睕䅁䅁䅯兂䅁䅁䅕䅁䅁䵁䉁欵䉁䅁䅁允䅁䅁䅕牒穢搯契歏䵁䅉䅅䅁䕁䅁䅁睁䵁䅁䅁权偂䅁䅁权佂䅁䅁兂䅁䅁䅁䭁汦䅑䅅䅁䉁䅁䅁兂穁積積積呐睐杷允䅁䅁䅑䅁䑁䅁䅷䅁䭁䕁䄸䅁䭁䕁䄴䅁䙁䅁䅁䅁杂敧䅚允䅁䅁䅅䅁䙁䭁睒児塲睯䅸䍄䉁䅁䅁兂䅁䅁䅍䅄䅁䅁䅯䅈䅁䅁䅯睕䅁䅁䅯兂䅁䅁䅕䅁䅁䥁允欵䉁䅁䅁允䅁䅁䅕牘䩰䅄牋啌䵁䅉䅅䅁䙁䅁䅁睁䵁䅁䅁权䅁䅁䅁权䉁䅁䅁权䙁䅁䅁兂䅁䅁䅁倴汈䅑䅅䅁䉁䅁䅁兂䙃ㄶ㑇潈托睐杷允䅁䅁䅕䅁䑁䅁䅷䅁䭁䉁䄰䅁䭁䅁䅅䅁䭁䅁䅕䅁䙁䅁䅁䅁杄畔䅚允䅁䅁䅅䅁䙁䭁䠵場啯瑲⽣䍄䉁䅁䅁兂䅁䅁䅍䅄䅁䅁䅯先䅁䅁䅯睕䅁䅁䅯兂䅁䅁䅕䅁䅁䥁偂欵䉁䅁䅁允䅁䅁䅕婤奍䙂佡歌䵁䅉䅅䅁䙁䅁䅁睁䵁䅁䅁权敁䅁䅁权呂䅁䅁权䙁䅁䅁兂䅁䅁䅁䉯浮䅑䅅䅁䉁䅁䅁兂婁䙂余塌灉䅑杷允䅁䅁䅕䅁䑁䅁䅷䅁䭁䅁䅁䅁䭁䙁䅍䅁䭁䅁䅕䅁䙁䅁䅁䅁䅃佗䅚允䅁䅁䅅䅁䙁䑁ね䡹⭡稳䅎䍄䉁䅁䅁兂䅁䅁䅍䅄䅁䅁䅯睈䅁䅁䅯睕䅁䅁䅯兂䅁䅁䅕䅁䅁䅁捃唵䉁䅁䅁允䅁䅁䅕䵮村䡳潉啍䵁䅉䅅䅁䙁䅁䅁睁䵁䅁䅁权晁䅁䅁权呂䅁䅁权䙁䅁䅁兂䅁䅁䅁佯氳䅑䅅䅁䉁䅁䅁兂橁⼲⭬污睷䅑杷允䅁䅁䅑䅁䑁䅁䅷䅁䭁䕁䄸䅁䭁䕁䄴䅁䙁䅁䅁䅁䅂⬵䅖允䅁䅁䅅䅁䙁䉁畓⭒㙆䉆䅊䍄䉁䅁䅁兂䅁䅁䅍䅄䅁䅁䅯杈䅁䅁䅯睕䅁䅁䅯兂䅁䅁䅕䅁䅁佁汃唵䉁䅁䅁允䅁䅁䅕㝤昶楇搸か䵁䅉䅅䅁䕁䅁䅁睁䵁䅁䅁权偂䅁䅁权佂䅁䅁兂䅁䅁䅁䉉浔䅑䅅䅁䉁䅁䅁兂晁敨剴䉵唴䅑杷允䅁䅁䅕䅁䑁䅁䅷䅁䭁䉁䄸䅁䭁䙁䅍䅁䭁䅁䅕䅁䙁䅁䅁䅁䅂⬷䅖允䅁䅁䅅䅁䙁䍁扐堫焵䑘䅂䍄䉁䅁䅁兂䅁䅁䅍䅄䅁䅁䅯䅈䅁䅁䅯允䅁䅁䅯兂䅁䅁䅕䅁䅁䥁剁欵䉁䅁䅁允䅁䅁䅕㑈牘払敧吱䴸䅉䅅䅁䕁䅁䅁睁䵁䅁䅁权偂䅁䅁权佂䅁䅁兂䅁䅁䅁䝷浘䅑䅅䅁䉁䅁䅁兂捂㡪ㅌ䙋乷䅑杷允䅁䅁䅕䅁䑁䅁䅷䅁䭁䅁䅁䅁䭁䙁䅍䅁䭁䅁䅕䅁䙁䅁䅁䅁杄⭉䅚允䅁䅁䅅䅁䙁佁兘瑉㕶橐䅎䍄䉁䅁䅁䅂䅁䅁䅍䅄䅁䅁䅯睔䅁䅁䅯杔䅁䅁䅕䅁䅁䅁噂欵䉁䅁䅁允䅁䅁䅕呣䬰㘱睎い䵁䅉䅅䅁䙁䅁䅁睁䵁䅁䅁权捁䅁䅁权呂䅁䅁权䙁䅁䅁兂䅁䅁䅁乯汄䅑䅅䅁䉁䅁䅁兂䙃ㄶ㑇潈畕䅑杷允䅁䅁䅕䅁䑁䅁䅷䅁䭁䉁䅷䅁䭁䙁䅍䅁䭁䅁䅕䅁䙁䅁䅁䅁权田䅖允䅁䅁䅅䅁䙁䕁椵䙅㕧䍴䄵䍄䉁䅁䅁兂䅁䅁䅍䅄䅁䅁䅯杇䅁䅁䅯允䅁䅁䅯兂䅁䅁䅕䅁䅁䥁剄唵䉁䅁䅁允䅁䅁䅕椹捨㡪ㅌ䐴䴸䅉䅅䅁䕁䅁䅁睁䵁䅁䅁权偂䅁䅁权佂䅁䅁兂䅁䅁䅁䭑汔䅑䅅䅁䉁䅁䅁兂㝂䭆䠵場啲睐杷允䅁䅁䅑䅁䑁䅁䅷䅁䭁䕁䄸䅁䭁䕁䄴䅁䙁䅁䅁䅁䅄⭍䅚允䅁䅁䅅䅁䙁偁潙䥘䌯刹䅆䍄䉁䅁䅁兂䅁䅁䅍䅄䅁䅁䅯䅁䅁䅁䅯允䅁䅁䅯兂䅁䅁䅕䅁䅁䵁兄唵䉁䅁䅁允䅁䅁䅕場啯歲桦樲䴸䅉䅅䅁䙁䅁䅁睁䵁䅁䅁权慁䅁䅁权䉁䅁䅁权䙁䅁䅁兂䅁䅁䅁䝉浐䅑䅅䅁䉁䅁䅁兂歃䑣䬰㘱潐睐杷允䅁䅁䅕䅁䑁䅁䅷䅁䭁䉁䅷䅁䭁䅁䅅䅁䭁䅁䅕䅁䙁䅁䅁䅁䅃改䅖允䅁䅁䅅䅁䙁䉁䘫ㄶ㑇瑈⽕䍄䉁䅁䅁兂䅁䅁䅍䅄䅁䅁䅯杈䅁䅁䅯允䅁䅁䅯兂䅁䅁䅕䅁䅁䅁穄唵䉁䅁䅁允䅁䅁䅕積積積積稰䴸䅉䅅䅁䙁䅁䅁睁䵁䅁䅁权慁䅁䅁权䉁䅁䅁权䙁䅁䅁兂䅁䅁䅁䵉汘䅑䅅䅁䉁䅁䅁兂䅁䅁䅁䅁杄睐杷允䅁䅁䅑䅁䑁䅁䅷䅁䭁䕁䄰䅁䭁䕁䄴䅁䭁䍁䅁䅁䉁䅁䅁允䅁䅁䅕䡰㥁瑃橥歄䵁䅉䅅䅁䙁䅁䅁睁䵁䅁䅁权晁䅁䅁权呂䅁䅁权䙁䅁䅁兂䅁䅁䅁䌴浔䅑䅅䅁䉁䅁䅁兂㉃⼸唳䅥硫䅑杷允䅁䅁䅑䅁䑁䅁䅷䅁䭁䕁䄸䅁䭁䕁䄴䅁䙁䅁䅁䅁䅄⭡䅚允䅁䅁䅅䅁䙁䝁浚浚浚杚䅸䍄䉁䅁䅁兂䅁䅁䅍䅄䅁䅁䅯䅈䅁䅁䅯允䅁䅁䅯兂䅁䅁䅕䅁䅁䅁㑄唵䉁䅁䅁允䅁䅁䅕㑈牘払敧吱䴸䅉䅅䅁䕁䅁䅁睁䵁䅁䅁权偂䅁䅁权佂䅁䅁兂䅁䅁䅁䱙汢䅑䅅䅁䉁䅁䅁兂慃婭婭婭桮睐杷允䅁䅁䅕䅁䑁䅁䅷䅁䭁䉁䅯䅁䭁䅁䅅䅁䭁䅁䅕䅁䙁䅁䅁䅁权佚䅚允䅁䅁䅅䅁䙁䭁睒児塲⭯⽧䍄䉁䅁䅁䅂䅁䅁䅍䅄䅁䅁䅯睔䅁䅁䅯杔䅁䅁䅕䅁䅁佁䙁欵䉁䅁䅁允䅁䅁䅕積積積積啅䵁䅉䅅䅁䕁䅁䅁睁䵁䅁䅁权偂䅁䅁权佂䅁䅁兂䅁䅁䅁䕯洯䅑䅅䅁䉁䅁䅁兂䑄匹捨㡪光䅑杷允䅁䅁䅕䅁䑁䅁䅷䅁䭁䅁䅁䅁䭁䙁䅍䅁䭁䅁䅕䅁䙁䅁䅁䅁䅃畃䅚允䅁䅁䅅䅁䙁䉁奂扏䥔橬䅊䍄䉁䅁䅁兂䅁䅁䅍䅄䅁䅁䅯杈䅁䅁䅯允䅁䅁䅯兂䅁䅁䅕䅁䅁䍁㥂欵䉁䅁䅁允䅁䅁䅕䅁䅁䅁䅁䐰䴸䅉䅅䅁䙁䅁䅁睁䵁䅁䅁权晁䅁䅁权呂䅁䅁权䙁䅁䅁兂䅁䅁䅁䕧浮䅑䅅䅁䉁䅁䅁兂䕁杖琴桳砰䅑杷允䅁䅁䅑䅁䑁䅁䅷䅁䭁䕁䄸䅁䭁䕁䄴䅁䙁䅁䅁䅁杁畤䅚允䅁䅁䅅䅁䙁䡁啳歲桦来䅸䍄䉁䅁䅁兂䅁䅁䅍䅄䅁䅁䅯杈䅁䅁䅯睕䅁䅁䅯兂䅁䅁䅕䅁䅁䵁㙂欵䉁䅁䅁允䅁䅁䅕噋偹癷潖啉䵁䅉䅅䅁䙁䅁䅁睁䵁䅁䅁权䅁䅁䅁权呂䅁䅁权䙁䅁䅁兂䅁䅁䅁䡁浺䅑䅅䅁䉁䅁䅁兂啂㘴扗䅸ぁ䅑杷允䅁䅁䅕䅁䑁䅁䅷䅁䭁䉁䄰䅁䭁䙁䅍䅁䭁䅁䅕䅁䙁䅁䅁䅁杄⭸䅖允䅁䅁䅅䅁䙁䕁㍷啩杆匵䄱䍄䉁䅁䅁兂䅁䅁䅍䅄䅁䅁䅯杇䅁䅁䅯睕䅁䅁䅯兂䅁䅁䅕䅁䅁䍁呂欵䉁䅁䅁允䅁䅁䅕⽷潕䥘椹く䵁䅉䅅䅁䙁䅁䅁睁䵁䅁䅁权晁䅁䅁权䉁䅁䅁权䙁䅁䅁兂䅁䅁䅁䱉汲䅑䅅䅁䉁䅁䅁兂䙃ㄶ㑇潈托睐杷允䅁䅁䅕䅁䑁䅁䅷䅁䭁䉁䄸䅁䭁䅁䅅䅁䭁䅁䅕䅁䙁䅁䅁䅁杄⭗䅚允䅁䅁䅅䅁䙁偁潙䥘䌯改⽁䍄䉁䅁䅁䅂䅁䅁䅍䅄䅁䅁䅯睔䅁䅁䅯杔䅁䅁䅕䅁䅁䵁獁欵䉁䅁䅁允䅁䅁䅕㘱睎児塲歅䵁䅉䅅䅁䙁䅁䅁睁䵁䅁䅁权晁䅁䅁权䉁䅁䅁权䙁䅁䅁兂䅁䅁䅁佉汌䅑䅅䅁䉁䅁䅁兂㥁瑃橥䑣愳睐杷允䅁䅁䅑䅁䑁䅁䅷䅁䭁䕁䄸䅁䭁䕁䄴䅁䙁䅁䅁䅁䅄畒䅚允䅁䅁䅅䅁䙁乁橥䑣䬰砱䅂䍄䉁䅁䅁兂䅁䅁䅍䅄䅁䅁䅯先䅁䅁䅯睕䅁䅁䅯兂䅁䅁䅕䅁䅁䥁䑁欵䉁䅁䅁允䅁䅁䅕䝭匴㡧䭂歌䵁䅉䅅䅁䙁䅁䅁睁䵁䅁䅁权䅁䅁䅁权䉁䅁䅁权䙁䅁䅁兂䅁䅁䅁偁汲䅑䅅䅁䉁䅁䅁兂㑃潈牘払敪睐杷允䅁䅁䅕䅁䑁䅁䅷䅁䭁䉁䅯䅁䭁䙁䅍䅁䭁䅁䅕䅁䙁䅁䅁䅁杄敒䅚允䅁䅁䅅䅁䙁䕁㍷啩杆呒䅴䍄䉁䅁䅁兂䅁䅁䅍䅄䅁䅁䅯䅁䅁䅁䅯允䅁䅁䅯兂䅁䅁䅕䅁䅁佁䥁欵䉁䅁䅁允䅁䅁䅕䉵䘶ㄶ㑇樳䴸䅉䅅䅁䕁䅁䅁睁䵁䅁䅁权偂䅁䅁权佂䅁䅁兂䅁䅁䅁䍷洳䅑䅅䅁䉁䅁䅁兂慃婭婭婭卫䅑杷允䅁䅁䅕䅁䑁䅁䅷䅁䭁䅁䅁䅁䭁䅁䅅䅁䭁䅁䅕䅁䙁䅁䅁䅁䅂佰䅖允䅁䅁䅅䅁䙁䩁婱婭婭摭⽫䍄䉁䅁䅁兂䅁䅁䅍䅄䅁䅁䅯杈䅁䅁䅯允䅁䅁䅯兂䅁䅁䅕䅁䅁䝁ㅃ唵䉁䅁䅁允䅁䅁䅕積積積積稰䴸䅉䅅䅁䕁䅁䅁睁䵁䅁䅁权偂䅁䅁权佂䅁䅁兂䅁䅁䅁䑁浲䅑䅅䅁䉁䅁䅁兂㉄䙋偹癷何䅑杷允䅁䅁䅕䅁䑁䅁䅷䅁䭁䉁䄸䅁䭁䙁䅍䅁䭁䅁䅕䅁䙁䅁䅁䅁杄敖䅚允䅁䅁䅅䅁䙁䡁⼰噎㘶呋䅆䍄䉁䅁䅁兂䅁䅁䅍䅄䅁䅁䅯睈䅁䅁䅯睕䅁䅁䅯兂䅁䅁䅕䅁䅁䥁㡂欵䉁䅁䅁允䅁䅁䅕牡へ硫歧啍䵁䅉䅅䅁䕁䅁䅁睁䵁䅁䅁权偂䅁䅁权佂䅁䅁兂䅁䅁䅁䡯浐䅑䅅䅁䉁䅁䅁兂㝂䭆䠵場䵯䅑杷允䅁䅁䅕䅁䑁䅁䅷䅁䭁䉁䄸䅁䭁䙁䅍䅁䭁䅁䅕䅁䙁䅁䅁䅁杁數䅖允䅁䅁䅅䅁䙁䵁㉬灶愸穌䅆䍄䉁䅁䅁兂䅁䅁䅍䅄䅁䅁䅯杈䅁䅁䅯允䅁䅁䅯兂䅁䅁䅕䅁䅁䝁牂欵䉁䅁䅁允䅁䅁䅕䅁䅁䅁䅁䐰䴸䅉䅅䅁䕁䅁䅁睁䵁䅁䅁权偂䅁䅁权佂䅁䅁兂䅁䅁䅁䡯浪䅑䅅䅁䉁䅁䅁兂䅁䅁䅁䅁䵁䅑杷允䅁䅁䅕䅁䑁䅁䅷䅁䭁䉁䅷䅁䭁䅁䅅䅁䭁䅁䅕䅁䙁䅁䅁䅁䅁敔䅚允䅁䅁䅅䅁䙁偁潙䥘䌯搹⽧䍄䉁䅁䅁兂䅁䅁䅍䅄䅁䅁䅯睈䅁䅁䅯允䅁䅁䅯兂䅁䅁䅕䅁䅁䕁䝁欵䉁䅁䅁允䅁䅁䅕䅁䅁䅁䅁䐴䴸䅉䅅䅁䕁䅁䅁睁䵁䅁䅁权摁䅁䅁权䵂䅁䅁权杁䅁䅁允䅁䅁䅅䅁䙁䭁睒児塲祯䅚䍄䉁䅁䅁䅂䅁䅁䅍䅄䅁䅁䅯䅁䅁䅁䅯睕䅁䅁䅕䅁䅁䭁䍃欵䉁䅁䅁允䅁䅁䅯䅂䅁䅁杷允䅁䅁䅑䅁䑁䅁䅷䅁䭁䉁䄴䅁䭁䕁䅷䅁䭁䍁䅁䅁䉁䅁䅁允䅁䅁䅕灭婭婭婭啄䵁䅉䅅䅁䙁䅁䅁睁䵁䅁䅁权摁䅁䅁权䉁䅁䅁权䙁䅁䅁兂䅁䅁䅁偁氯䅑䅅䅁䉁䅁䅁兂晁敨剴䉵嘷睐杷允䅁䅁䅕䅁䑁䅁䅷䅁䭁䉁䄰䅁䭁䙁䅍䅁䭁䅁䅕䅁䙁䅁䅁䅁杄畤䅚允䅁䅁䅅䅁䙁偁湃歸㍳卹䄱䍄䉁䅁䅁兂䅁䅁䅍䅄䅁䅁䅯䅁䅁䅁䅯允䅁䅁䅯兂䅁䅁䅕䅁䅁䕁⭂欵䉁䅁䅁允䅁䅁䅕䉵䘶ㄶ㑇樳䴸䅉䅅䅁䕁䅁䅁睁䵁䅁䅁权偂䅁䅁权佂䅁䅁兂䅁䅁䅁䕁浦䅑䅅䅁䉁䅁䅁兂畃⭒㙆䭆儴䅑杷允䅁䅁䅕䅁䑁䅁䅷䅁䭁䉁䄴䅁䭁䙁䅍䅁䭁䅁䅕䅁䙁䅁䅁䅁权佭䅖允䅁䅁䅅䅁䙁䅁䉡啬䱏䍢䅬䍄䉁䅁䅁兂䅁䅁䅍䅄䅁䅁䅯杈䅁䅁䅯允䅁䅁䅯兂䅁䅁䅕䅁䅁䍁楄唵䉁䅁䅁允䅁䅁䅕積積積積稰䴸䅉䅅䅁䙁䅁䅁睁䵁䅁䅁权䅁䅁䅁权呂䅁䅁权䙁䅁䅁兂䅁䅁䅁䵷汮䅑䅅䅁䉁䅁䅁兂瑂⼵灵昸祉䅑杷允䅁䅁䅕䅁䑁䅁䅷䅁䭁䉁䄸䅁䭁䅁䅅䅁䭁䅁䅕䅁䙁䅁䅁䅁䅄畦䅚允䅁䅁䅅䅁䙁䙁㑋潈牘敕⽁䍄䉁䅁䅁兂䅁䅁䅍䅄䅁䅁䅯䅁䅁䅁䅯睕䅁䅁䅯兂䅁䅁䅕䅁䅁佁敁欵䉁䅁䅁允䅁䅁䅕硢䑋䵷䉯き䵁䅉䅅䅁䙁䅁䅁睁䵁䅁䅁权摁䅁䅁权䉁䅁䅁权䙁䅁䅁兂䅁䅁䅁䝯洳䅑䅅䅁䉁䅁䅁兂畃⭒㙆䭆堷睐杷允䅁䅁䅑䅁䑁䅁䅷䅁䭁䕁䄸䅁䭁䕁䄴䅁䙁䅁䅁䅁䅁伫䅖允䅁䅁䅅䅁䙁䭁睒児塲硯䅊䍄䉁䅁䅁兂䅁䅁䅍䅄䅁䅁䅯䅈䅁䅁䅯允䅁䅁䅯兂䅁䅁䅕䅁䅁䵁摄唵䉁䅁䅁允䅁䅁䅕積積積積稰䴸䅉䅅䅁䙁䅁䅁睁䵁䅁䅁权䅁䅁䅁权䉁䅁䅁权䙁䅁䅁兂䅁䅁䅁䵑決䅑䅅䅁䉁䅁䅁兂㥁瑃橥䑣愳睐杷允䅁䅁䅕䅁䑁䅁䅷䅁䭁䉁䅯䅁䭁䅁䅅䅁䭁䅁䅕䅁䙁䅁䅁䅁杂敤䅚允䅁䅁䅅䅁䙁䭁睒児塲⭯⽧䍄䉁䅁䅁兂䅁䅁䅍䅄䅁䅁䅯杈䅁䅁䅯允䅁䅁䅯兂䅁䅁䅕䅁䅁䵁牄唵䉁䅁䅁允䅁䅁䅕積積積積稰䴸䅉䅅䅁䙁䅁䅁睁䵁䅁䅁权䅁䅁䅁权呂䅁䅁权䙁䅁䅁兂䅁䅁䅁䵁汐䅑䅅䅁䉁䅁䅁兂㑄⭕汏㑭祑䅑杷允䅁䅁䅑䅁䑁䅁䅷䅁䭁䕁䄸䅁䭁䕁䄴䅁䙁䅁䅁䅁䅄佶䅖允䅁䅁䅅䅁䙁佁㙆䭆䠵攴⽯䍄䉁䅁䅁兂䅁䅁䅍䅄䅁䅁䅯先䅁䅁䅯睕䅁䅁䅯兂䅁䅁䅕䅁䅁䭁瑂欵䉁䅁䅁允䅁䅁䅕㑎䉬余兕歌䵁䅉䅅䅁䙁䅁䅁睁䵁䅁䅁权䅁䅁䅁权䉁䅁䅁权䙁䅁䅁兂䅁䅁䅁䡑浔䅑䅅䅁䉁䅁䅁兂㑃潈牘払敪睐杷允䅁䅁䅕䅁䑁䅁䅷䅁䭁䉁䄸䅁䭁䅁䅅䅁䭁䅁䅕䅁䙁䅁䅁䅁杂⭲䅖允䅁䅁䅅䅁䙁䥁牘払敧摨⽳䍄䉁䅁䅁䅂䅁䅁䅍䅄䅁䅁䅯睔䅁䅁䅯杔䅁䅁䅕䅁䅁䥁奂欵䉁䅁䅁允䅁䅁䅕㡪ㅌ䙋偹歄䵁䅉䅅䅁䙁䅁䅁睁䵁䅁䅁权捁䅁䅁权䉁䅁䅁权䙁䅁䅁兂䅁䅁䅁䱯氷䅑䅅䅁䉁䅁䅁兂偃癷潕䥘匯睐杷允䅁䅁䅕䅁䑁䅁䅷䅁䭁䅁䅁䅁䭁䙁䅍䅁䭁䅁䅕䅁䙁䅁䅁䅁䅄伲䅖允䅁䅁䅅䅁䙁䭁慁㥌欰橂䅎䍄䉁䅁䅁兂䅁䅁䅍䅄䅁䅁䅯䅁䅁䅁䅯睕䅁䅁䅯兂䅁䅁䅕䅁䅁䝁杂欵䉁䅁䅁允䅁䅁䅕癱午坔兌き䵁䅉䅅䅁䙁䅁䅁睁䵁䅁䅁权捁䅁䅁权䉁䅁䅁权䙁䅁䅁兂䅁䅁䅁䅙浘䅑䅅䅁䉁䅁䅁兂晁敨剴䉵嘷睐杷允䅁䅁䅕䅁䑁䅁䅷䅁䭁䉁䅷䅁䭁䅁䅅䅁䭁䅁䅕䅁䙁䅁䅁䅁杁畆䅚允䅁䅁䅅䅁䙁䉁䘫ㄶ㑇瑈⽕䍄䉁䅁䅁兂䅁䅁䅍䅄䅁䅁䅯睈䅁䅁䅯允䅁䅁䅯兂䅁䅁䅕䅁䅁䭁癄唵䉁䅁䅁允䅁䅁䅕場啯歲桦樲䴸䅉䅅䅁䕁䅁䅁睁䵁䅁䅁权偂䅁䅁权佂䅁䅁兂䅁䅁䅁䩑氳䅑䅅䅁䉁䅁䅁兂塄㍯㥁瑃呦睐杷允䅁䅁䅕䅁䑁䅁䅷䅁䭁䅁䅁䅁䭁䅁䅅䅁䭁䅁䅕䅁䙁䅁䅁䅁权佳䅖允䅁䅁䅅䅁䙁䩁婱婭婭摭⽫䍄䉁䅁䅁兂䅁䅁䅍䅄䅁䅁䅯䅈䅁䅁䅯睕䅁䅁䅯兂䅁䅁䅕䅁䅁䭁䩂欵䉁䅁䅁允䅁䅁䅕硢䑋䵷桰歌䵁䅉䅅䅁䙁䅁䅁睁䵁䅁䅁权䅁䅁䅁权呂䅁䅁权䙁䅁䅁兂䅁䅁䅁䕉浦䅑䅅䅁䉁䅁䅁兂十㡧䭄捯穕䅑杷允䅁䅁䅕䅁䑁䅁䅷䅁䭁䉁䄰䅁䭁䅁䅅䅁䭁䅁䅕䅁䙁䅁䅁䅁䅃电䅖允䅁䅁䅅䅁䙁乁橥䑣䬰㤱⽍䍄䉁䅁䅁兂䅁䅁䅍䅄䅁䅁䅯先䅁䅁䅯允䅁䅁䅯兂䅁䅁䅕䅁䅁䅁牁欵䉁䅁䅁允䅁䅁䅕浚浚浚浚樱䴸䅉䅅䅁䙁䅁䅁睁䵁䅁䅁权摁䅁䅁权呂䅁䅁权䙁䅁䅁兂䅁䅁䅁䵁汌䅑䅅䅁䉁䅁䅁兂䵂㑎䉬余瑕䅑杷允䅁䅁䅑䅁䑁䅁䅷䅁䭁䕁䄸䅁䭁䕁䄴䅁䙁䅁䅁䅁杁佂䅚允䅁䅁䅅䅁䙁䭁睒児塲硯䅂䍄䉁䅁䅁兂䅁䅁䅍䅄䅁䅁䅯䅁䅁䅁䅯允䅁䅁䅯兂䅁䅁䅕䅁䅁䅁奄唵䉁䅁䅁允䅁䅁䅕場啯歲桦樲䴸䅉䅅䅁䙁䅁䅁睁䵁䅁䅁权慁䅁䅁权呂䅁䅁权䙁䅁䅁兂䅁䅁䅁䡷浌䅑䅅䅁䉁䅁䅁兂䵂㑎䉬䍙㝕䅑杷允䅁䅁䅑䅁䑁䅁䅷䅁䭁䕁䄸䅁䭁䕁䄴䅁䙁䅁䅁䅁䅁住䅚允䅁䅁䅅䅁䙁䝁浚浚浚桚䅂䍄䉁䅁䅁兂䅁䅁䅍䅄䅁䅁䅯杈䅁䅁䅯允䅁䅁䅯兂䅁䅁䅕䅁䅁䵁灂欵䉁䅁䅁允䅁䅁䅕䅁䅁䅁䅁䐰䴸䅉䅅䅁䙁䅁䅁睁䵁䅁䅁权晁䅁䅁权呂䅁䅁权䙁䅁䅁兂䅁䅁䅁䍧浺䅑䅅䅁䉁䅁䅁兂㉃⼸唳䅥硫䅑杷允䅁䅁䅕䅁䑁䅁䅷䅁䭁䉁䄰䅁䭁䅁䅅䅁䭁䅁䅕䅁䙁䅁䅁䅁䅁伱䅖允䅁䅁䅅䅁䙁乁橥䑣䬰㤱⽍䍄䉁䅁䅁兂䅁䅁䅍䅄䅁䅁䅯先䅁䅁䅯睕䅁䅁䅯兂䅁䅁䅕䅁䅁䥁䙄唵䉁䅁䅁允䅁䅁䅕䑔䩥坑汄啌䵁䅉䅅䅁䕁䅁䅁睁䵁䅁䅁权偂䅁䅁权佂䅁䅁兂䅁䅁䅁乁汘䅑䅅䅁䉁䅁䅁兂畃⭒㙆䭆䘴䅑杷允䅁䅁䅕䅁䑁䅁䅷䅁䭁䉁䄰䅁䭁䙁䅍䅁䭁䅁䅕䅁䙁䅁䅁䅁杁⭴䅖允䅁䅁䅅䅁䙁䅁塲㍯㥁楹䄱䍄䉁䅁䅁䅂䅁䅁䅍䅄䅁䅁䅯睔䅁䅁䅯杔䅁䅁䅕䅁䅁䵁兂欵䉁䅁䅁允䅁䅁䅕瑃橥䑣䬰啅䵁䅉䅅䅁䕁䅁䅁睁䵁䅁䅁权偂䅁䅁权佂䅁䅁兂䅁䅁䅁䥙浌䅑䅅䅁䉁䅁䅁兂啁歲桦桥佑䅑杷允䅁䅁䅕䅁䑁䅁䅷䅁䭁䉁䄸䅁䭁䙁䅍䅁䭁䅁䅕䅁䙁䅁䅁䅁杄⭐䅚允䅁䅁䅅䅁䙁䑁䩥坑汄䑍䅆䍄䉁䅁䅁䅂䅁䅁䅍䅄䅁䅁䅯睔䅁䅁䅯杔䅁䅁䅕䅁䅁䅁煃唵䉁䅁䅁允䅁䅁䅕䉵䘶ㄶ㑇樳䴸䅉䅅䅁䙁䅁䅁睁䵁䅁䅁权慁䅁䅁权呂䅁䅁权䙁䅁䅁兂䅁䅁䅁䥯浄䅑䅅䅁䉁䅁䅁兂㕂匶硙佃㙷䅑杷允䅁䅁䅕䅁䑁䅁䅷䅁䭁䉁䄸䅁䭁䅁䅅䅁䭁䅁䅕䅁䙁䅁䅁䅁杁⭙䅚允䅁䅁䅅䅁䙁偁潙䥘䌯改⽁䍄䉁䅁䅁䅂䅁䅁䅍䅄䅁䅁䅯睔䅁䅁䅯杔䅁䅁䅕䅁䅁䝁婁欵䉁䅁䅁允䅁䅁䅕灭婭婭婭啅䵁䅉䅅䅁䙁䅁䅁睁䵁䅁䅁权晁䅁䅁权䉁䅁䅁权䙁䅁䅁兂䅁䅁䅁䅑浦䅑䅅䅁䉁䅁䅁兂䅁䅁䅁䅁杄睐杷允䅁䅁䅕䅁䑁䅁䅷䅁䭁䅁䅁䅁䭁䅁䅅䅁䭁䅁䅕䅁䙁䅁䅁䅁䅂⭌䅚允䅁䅁䅅䅁䙁䱁敧敨剴乵⼴䍄䉁䅁䅁䅂䅁䅁䅍䅄䅁䅁䅯睔䅁䅁䅯杔䅁䅁䅕䅁䅁䥁㝂欵䉁䅁䅁允䅁䅁䅕呣䬰㘱睎啄䵁䅉䅅䅁䙁䅁䅁睁䵁䅁䅁权敁䅁䅁权呂䅁䅁权䙁䅁䅁兂䅁䅁䅁䵧汶䅑䅅䅁䉁䅁䅁兂牁硨婢牺獣䅑杷允䅁䅁䅕䅁䑁䅁䅷䅁䭁䉁䄴䅁䭁䙁䅍䅁䭁䅁䅕䅁䙁䅁䅁䅁䅄畖䅚允䅁䅁䅅䅁䙁乁㕶浦㡱䍤䅊䍄䉁䅁䅁兂䅁䅁䅍䅄䅁䅁䅯睈䅁䅁䅯睕䅁䅁䅯兂䅁䅁䅕䅁䅁䅁い唵䉁䅁䅁允䅁䅁䅕㥉㕶浦捰䕍䵁䅉䅅䅁䕁䅁䅁睁䵁䅁䅁权偂䅁䅁权佂䅁䅁兂䅁䅁䅁䥁浄䅑䅅䅁䉁䅁䅁兂晁敨剴䉵䰴䅑杷允䅁䅁䅕䅁䑁䅁䅷䅁䭁䅁䅁䅁䭁䙁䅍䅁䭁䅁䅕䅁䙁䅁䅁䅁杄畷䅖允䅁䅁䅅䅁䙁偁周㘴扗䑨䅊䍄䉁䅁䅁䅂䅁䅁䅍䅄䅁䅁䅯䅁䅁䅁䅯睕䅁䅁䅕䅁䅁䥁䍃欵䉁䅁䅁允䅁䅁䅯䅂䅁䅁杷允䅁䅁䅑䅁䑁䅁䅷䅁䭁䕁䄸䅁䭁䕁䄴䅁䙁䅁䅁䅁䅂敷䅖允䅁䅁䅅䅁䭁䉁䅳䅁䵁䅉䅅䅁䙁䅁䅁睁䵁䅁䅁权摁䅁䅁权䉁䅁䅁权䙁䅁䅁兂䅁䅁䅁䍯浔䅑䅅䅁䉁䅁䅁兂浂浚浚浚坢睐杷允䅁䅁䅕䅁䑁䅁䅷䅁䭁䉁䄴䅁䭁䙁䅍䅁䭁䅁䅕䅁䙁䅁䅁䅁䅄⭂䅚允䅁䅁䅅䅁䙁䅁䅁䅁䅁䍁䅰䍄䉁䅁䅁䅂䅁䅁䅍䅄䅁䅁䅯睔䅁䅁䅯杔䅁䅁䅕䅁䅁佁䱂欵䉁䅁䅁允䅁䅁䅕積積積積啅䵁䅉䅅䅁䙁䅁䅁睁䵁䅁䅁权䅁䅁䅁权䉁䅁䅁权䙁䅁䅁兂䅁䅁䅁䕙浌䅑䅅䅁䉁䅁䅁兂㑃潈牘払敪睐杷允䅁䅁䅕䅁䑁䅁䅷䅁䭁䉁䅷䅁䭁䙁䅍䅁䭁䅁䅕䅁䙁䅁䅁䅁权敕䅚允䅁䅁䅅䅁䙁乁欰潂噇祑䄵䍄䉁䅁䅁兂䅁䅁䅍䅄䅁䅁䅯䅈䅁䅁䅯睕䅁䅁䅯兂䅁䅁䅕䅁䅁䵁佁欵䉁䅁䅁允䅁䅁䅕牘䩰䅄牋啌䵁䅉䅅䅁䙁䅁䅁睁䵁䅁䅁权䅁䅁䅁权䉁䅁䅁权䙁䅁䅁兂䅁䅁䅁伴汢䅑䅅䅁䉁䅁䅁兂桄桥畓⭒慈睐杷允䅁䅁䅕䅁䑁䅁䅷䅁䭁䉁䄴䅁䭁䙁䅍䅁䭁䅁䅕䅁䙁䅁䅁䅁权⭰䅖允䅁䅁䅅䅁䙁䡁⭥确癯午䅴䍄䉁䅁䅁兂䅁䅁䅍䅄䅁䅁䅯䅁䅁䅁䅯睕䅁䅁䅯兂䅁䅁䅕䅁䅁䥁偁欵䉁䅁䅁允䅁䅁䅕䙅㕧䵴坩歍䵁䅉䅅䅁䙁䅁䅁睁䵁䅁䅁权慁䅁䅁权呂䅁䅁权䙁䅁䅁兂䅁䅁䅁䝙洷䅑䅅䅁䉁䅁䅁兂癁匳䝑噧㝕䅑杷允䅁䅁䅕䅁䑁䅁䅷䅁䭁䅁䅁䅁䭁䙁䅍䅁䭁䅁䅕䅁䙁䅁䅁䅁杁畡䅚允䅁䅁䅅䅁䙁䙁橔婰䕶䐴䅎䍄䉁䅁䅁兂䅁䅁䅍䅄䅁䅁䅯睈䅁䅁䅯允䅁䅁䅯兂䅁䅁䅕䅁䅁䕁噃唵䉁䅁䅁允䅁䅁䅕牕敧敨剴䐴䴸䅉䅅䅁䕁䅁䅁睁䵁䅁䅁权偂䅁䅁权佂䅁䅁兂䅁䅁䅁䱧氷䅑䅅䅁䉁䅁䅁兂乄䵺䵺䵺獺睐杷允䅁䅁䅑䅁䑁䅁䅷䅁䭁䕁䄸䅁䭁䕁䄴䅁䙁䅁䅁䅁杄伸䅖允䅁䅁䅅䅁䙁䡁㥅瑃橥䅣䄹䍄䉁䅁䅁䅂䅁䅁䅍䅄䅁䅁䅯睔䅁䅁䅯杔䅁䅁䅕䅁䅁佁㕄唵䉁䅁䅁允䅁䅁䅕䭆䠵場啯歄䵁䅉䅅䅁䕁䅁䅁睁䵁䅁䅁权偂䅁䅁权佂䅁䅁兂䅁䅁䅁䡷洷䅑䅅䅁䉁䅁䅁兂䑄匹捨㡪䱉䅑杷允䅁䅁䅕䅁䑁䅁䅷䅁䭁䅁䅁䅁䭁䙁䅍䅁䭁䅁䅕䅁䙁䅁䅁䅁䅃⭌䅚允䅁䅁䅅䅁䙁䍁礲敮渫橨䅎䍄䉁䅁䅁兂䅁䅁䅍䅄䅁䅁䅯杇䅁䅁䅯允䅁䅁䅯兂䅁䅁䅕䅁䅁䍁潁欵䉁䅁䅁允䅁䅁䅕䡰㥁瑃橥䐶䴸䅉䅅䅁䙁䅁䅁睁䵁䅁䅁权晁䅁䅁权呂䅁䅁权䙁䅁䅁兂䅁䅁䅁䭷汪䅑䅅䅁䉁䅁䅁兂㑃潈牘塕睧䅑杷允䅁䅁䅑䅁䑁䅁䅷䅁䭁䕁䄸䅁䭁䕁䄴䅁䙁䅁䅁䅁䅁佔䅚允䅁䅁䅅䅁䙁䙁㑋潈牘剕䅆䍄䉁䅁䅁兂䅁䅁䅍䅄䅁䅁䅯䅁䅁䅁䅯允䅁䅁䅯兂䅁䅁䅕䅁䅁䅁穁欵䉁䅁䅁允䅁䅁䅕䉵䘶ㄶ㑇樳䴸䅉䅅䅁䕁䅁䅁睁䵁䅁䅁权偂䅁䅁权佂䅁䅁兂䅁䅁䅁䅁浦䅑䅅䅁䉁䅁䅁兂捂㡪ㅌ䙋卷䅑杷允䅁䅁䅕䅁䑁䅁䅷䅁䭁䉁䅷䅁䭁䙁䅍䅁䭁䅁䅕䅁䙁䅁䅁䅁䅃⬰䅖允䅁䅁䅅䅁䙁䕁椵䙅㕧䍴䄵䍄䉁䅁䅁兂䅁䅁䅍䅄䅁䅁䅯先䅁䅁䅯允䅁䅁䅯兂䅁䅁䅕䅁䅁佁牄唵䉁䅁䅁允䅁䅁䅕㘱睎児塲稰䴸䅉䅅䅁䙁䅁䅁睁䵁䅁䅁权䅁䅁䅁权呂䅁䅁权䙁䅁䅁兂䅁䅁䅁䍯洷䅑䅅䅁䉁䅁䅁兂瑁灳瘳㑰穙䅑杷允䅁䅁䅕䅁䑁䅁䅷䅁䭁䉁䅷䅁䭁䙁䅍䅁䭁䅁䅕䅁䙁䅁䅁䅁䅃⬷䅖允䅁䅁䅅䅁䙁䱁䩰䅄牉祸䄱䍄䉁䅁䅁兂䅁䅁䅍䅄䅁䅁䅯睈䅁䅁䅯睕䅁䅁䅯兂䅁䅁䅕䅁䅁佁睁欵䉁䅁䅁允䅁䅁䅕穐敖歵獫啍䵁䅉䅅䅁䕁䅁䅁睁䵁䅁䅁权偂䅁䅁权佂䅁䅁兂䅁䅁䅁䙉浔䅑䅅䅁䉁䅁䅁兂硂児塲㍯偁䅑杷允䅁䅁䅕䅁䑁䅁䅷䅁䭁䅁䅁䅁䭁䅁䅅䅁䭁䅁䅕䅁䙁䅁䅁䅁权佉䅚允䅁䅁䅅䅁䙁䱁敧敨剴乵⼴䍄䉁䅁䅁兂䅁䅁䅍䅄䅁䅁䅯先䅁䅁䅯允䅁䅁䅯兂䅁䅁䅕䅁䅁䍁⭁欵䉁䅁䅁允䅁䅁䅕歲桦桥畓稱䴸䅉䅅䅁䙁䅁䅁睁䵁䅁䅁权䅁䅁䅁权䉁䅁䅁权䙁䅁䅁兂䅁䅁䅁䍙浮䅑䅅䅁䉁䅁䅁兂㑃潈牘払敪睐杷允䅁䅁䅕䅁䑁䅁䅷䅁䭁䅁䅁䅁䭁䙁䅍䅁䭁䅁䅕䅁䙁䅁䅁䅁䅄攰䅖允䅁䅁䅅䅁䙁䭁慁㥌欰橂䅎䍄䉁䅁䅁兂䅁䅁䅍䅄䅁䅁䅯杇䅁䅁䅯睕䅁䅁䅯兂䅁䅁䅕䅁䅁䵁祁欵䉁䅁䅁允䅁䅁䅕㑈牘払敪歏䵁䅉䅅䅁䙁䅁䅁睁䵁䅁䅁权晁䅁䅁权䉁䅁䅁权䙁䅁䅁兂䅁䅁䅁䩁汮䅑䅅䅁䉁䅁䅁兂卂䉵䘶ㄶ杈睐杷允䅁䅁䅕䅁䑁䅁䅷䅁䭁䉁䄸䅁䭁䙁䅍䅁䭁䅁䅕䅁䙁䅁䅁䅁杂敚䅚允䅁䅁䅅䅁䙁乁楅⼲⭬橃䅆䍄䉁䅁䅁䅂䅁䅁䅍䅄䅁䅁䅯睔䅁䅁䅯杔䅁䅁䅕䅁䅁䍁湂欵䉁䅁䅁允䅁䅁䅕敨剴䉵䘶啄䵁䅉䅅䅁䙁䅁䅁睁䵁䅁䅁权䅁䅁䅁权呂䅁䅁权䙁䅁䅁兂䅁䅁䅁䵯汪䅑䅅䅁䉁䅁䅁兂瑂⼵灵昸祉䅑杷允䅁䅁䅕䅁䑁䅁䅷䅁䭁䉁䅷䅁䭁䙁䅍䅁䭁䅁䅕䅁䙁䅁䅁䅁䅃佌䅚允䅁䅁䅅䅁䙁䥁䌯匹捨祄䄵䍄䉁䅁䅁兂䅁䅁䅍䅄䅁䅁䅯先䅁䅁䅯允䅁䅁䅯兂䅁䅁䅕䅁䅁䕁硃唵䉁䅁䅁允䅁䅁䅕㘱睎児塲稰䴸䅉䅅䅁䙁䅁䅁睁䵁䅁䅁权敁䅁䅁权呂䅁䅁权䙁䅁䅁兂䅁䅁䅁䐴洷䅑䅅䅁䉁䅁䅁兂い搯㑒圶歙䅑杷允䅁䅁䅑䅁䑁䅁䅷䅁䭁䕁䄸䅁䭁䕁䄴䅁䙁䅁䅁䅁杁佦䅚允䅁䅁䅅䅁䙁䑁積積積睍䄱䍄䉁䅁䅁䅂䅁䅁䅍䅄䅁䅁䅯睔䅁䅁䅯杔䅁䅁䅕䅁䅁䭁瑁欵䉁䅁䅁允䅁䅁䅕浚浚浚浚歅䵁䅉䅅䅁䙁䅁䅁睁䵁䅁䅁权敁䅁䅁权䉁䅁䅁权䙁䅁䅁兂䅁䅁䅁䍧浶䅑䅅䅁䉁䅁䅁兂䑄匹捨㡪噌睐杷允䅁䅁䅑䅁䑁䅁䅷䅁䭁䕁䄸䅁䭁䕁䄴䅁䙁䅁䅁䅁䅃佦䅚允䅁䅁䅅䅁䙁䵁䴳䵺䵺䅺䅸䍄䉁䅁䅁䅂䅁䅁䅍䅄䅁䅁䅯睔䅁䅁䅯杔䅁䅁䅕䅁䅁佁塃唵䉁䅁䅁允䅁䅁䅕瑃橥䑣䬰穸䴸䅉䅅䅁䕁䅁䅁睁䵁䅁䅁权偂䅁䅁权佂䅁䅁兂䅁䅁䅁乙決䅑䅅䅁䉁䅁䅁兂歃䑣䬰㘱䝍䅑杷允䅁䅁䅕䅁䑁䅁䅷䅁䭁䉁䄰䅁䭁䙁䅍䅁䭁䅁䅕䅁䙁䅁䅁䅁䅁⭮䅖允䅁䅁䅅䅁䙁䕁㉡⼸唳䍥䄱䍄䉁䅁䅁兂䅁䅁䅍䅄䅁䅁䅯杈䅁䅁䅯睕䅁䅁䅯兂䅁䅁䅕䅁䅁䵁兂欵䉁䅁䅁允䅁䅁䅕渷⽷噎㘴䕊䵁䅉䅅䅁䙁䅁䅁睁䵁䅁䅁权晁䅁䅁权䉁䅁䅁权䙁䅁䅁兂䅁䅁䅁偙氳䅑䅅䅁䉁䅁䅁兂䥂場啯歲桦睐杷允䅁䅁䅑䅁䑁䅁䅷䅁䭁䕁䄸䅁䭁䕁䄴䅁䙁䅁䅁䅁杁⭑䅚允䅁䅁䅅䅁䙁䙁偹癷潕䉘䅂䍄䉁䅁䅁䅂䅁䅁䅍䅄䅁䅁䅯睔䅁䅁䅯杔䅁䅁䅕䅁䅁䭁䉁欵䉁䅁䅁允䅁䅁䅕䘷㑇潈牘い䵁䅉䅅䅁䙁䅁䅁睁䵁䅁䅁权捁䅁䅁权䉁䅁䅁权䙁䅁䅁兂䅁䅁䅁䭉汌䅑䅅䅁䉁䅁䅁兂偃癷潕䥘匯睐杷允䅁䅁䅑䅁䑁䅁䅷䅁䭁䕁䄸䅁䭁䕁䄴䅁䙁䅁䅁䅁杂敤䅚允䅁䅁䅅䅁䙁䝁浚浚浚杚䅸䍄䉁䅁䅁兂䅁䅁䅍䅄䅁䅁䅯先䅁䅁䅯睕䅁䅁䅯兂䅁䅁䅕䅁䅁䭁獂欵䉁䅁䅁允䅁䅁䅕㑎䉬余兕歌䵁䅉䅅䅁䙁䅁䅁睁䵁䅁䅁权䅁䅁䅁权䉁䅁䅁权䙁䅁䅁兂䅁䅁䅁䨴汮䅑䅅䅁䉁䅁䅁兂慃婭婭婭婮睐杷允䅁䅁䅕䅁䑁䅁䅷䅁䭁䅁䅁䅁䭁䅁䅅䅁䭁䅁䅕䅁䙁䅁䅁䅁䅄畊䅚允䅁䅁䅅䅁䙁䱁敧敨剴乵⼴䍄䉁䅁䅁兂䅁䅁䅍䅄䅁䅁䅯杇䅁䅁䅯允䅁䅁䅯兂䅁䅁䅕䅁䅁䵁敂欵䉁䅁䅁允䅁䅁䅕䡰㥁瑃橥䐶䴸䅉䅅䅁䙁䅁䅁睁䵁䅁䅁权䅁䅁䅁权呂䅁䅁权䙁䅁䅁兂䅁䅁䅁䴴汪䅑䅅䅁䉁䅁䅁兂瑂⼵灵昸祉䅑杷允䅁䅁䅕䅁䑁䅁䅷䅁䭁䅁䅁䅁䭁䙁䅍䅁䭁䅁䅕䅁䙁䅁䅁䅁权畏䅚允䅁䅁䅅䅁䙁䅁䅁䅁䅁䑯䅎䍄䉁䅁䅁兂䅁䅁䅍䅄䅁䅁䅯䅈䅁䅁䅯睕䅁䅁䅯兂䅁䅁䅕䅁䅁䭁慄唵䉁䅁䅁允䅁䅁䅕浔光䑗ね歌䵁䅉䅅䅁䙁䅁䅁睁䵁䅁䅁权晁䅁䅁权䉁䅁䅁权䙁䅁䅁兂䅁䅁䅁䌴浺䅑䅅䅁䉁䅁䅁兂䥂場啯歲桦睐杷允䅁䅁䅕䅁䑁䅁䅷䅁䭁䉁䄴䅁䭁䙁䅍䅁䭁䅁䅕䅁䙁䅁䅁䅁䅃敇䅚允䅁䅁䅅䅁䙁䉁䕫杖琴楣䅬䍄䉁䅁䅁䅂䅁䅁䅍䅄䅁䅁䅯睔䅁䅁䅯杔䅁䅁䅕䅁䅁䕁穃唵䉁䅁䅁允䅁䅁䅕場啯歲桦樲䴸䅉䅅䅁䙁䅁䅁睁䵁䅁䅁权捁䅁䅁权䉁䅁䅁权䙁䅁䅁兂䅁䅁䅁佑氯䅑䅅䅁䉁䅁䅁兂穁積積積呐睐杷允䅁䅁䅕䅁䑁䅁䅷䅁䭁䉁䄰䅁䭁䙁䅍䅁䭁䅁䅕䅁䙁䅁䅁䅁权敏䅚允䅁䅁䅅䅁䙁䕁㉡⼸唳䍵䄵䍄䉁䅁䅁兂䅁䅁䅍䅄䅁䅁䅯䅁䅁䅁䅯睕䅁䅁䅯兂䅁䅁䅕䅁䅁䕁ぁ欵䉁䅁䅁允䅁䅁䅕扌摋㘷䝥き䵁䅉䅅䅁䙁䅁䅁睁䵁䅁䅁权敁䅁䅁权䉁䅁䅁权䙁䅁䅁兂䅁䅁䅁佁汮䅑䅅䅁䉁䅁䅁兂穁積積積呐睐杷允䅁䅁䅕䅁䑁䅁䅷䅁䭁䉁䄴䅁䭁䙁䅍䅁䭁䅁䅕䅁䙁䅁䅁䅁杂攷䅖允䅁䅁䅅䅁䙁䡁潎敫㠱祐䅸䍄䉁䅁䅁䅂䅁䅁䅍䅄䅁䅁䅯睔䅁䅁䅯杔䅁䅁䅕䅁䅁䵁硂欵䉁䅁䅁允䅁䅁䅕積積積積啄䵁䅉䅅䅁䙁䅁䅁睁䵁䅁䅁权䅁䅁䅁权䉁䅁䅁权䙁䅁䅁兂䅁䅁䅁䕉浲䅑䅅䅁䉁䅁䅁兂㑃潈牘払敪睐杷允䅁䅁䅕䅁䑁䅁䅷䅁䭁䅁䅁䅁䭁䙁䅍䅁䭁䅁䅕䅁䙁䅁䅁䅁䅂畓䅚允䅁䅁䅅䅁䙁䉁䑋䵷桱呸䅎䍄䉁䅁䅁䅂䅁䅁䅍䅄䅁䅁䅯睔䅁䅁䅯杔䅁䅁䅕䅁䅁䝁桃唵䉁䅁䅁允䅁䅁䅕浚浚浚浚樱䴸䅉䅅䅁䕁䅁䅁睁䵁䅁䅁权偂䅁䅁权佂䅁䅁兂䅁䅁䅁䌴浈䅑䅅䅁䉁䅁䅁兂啁歲桦桥剑䅑杷允䅁䅁䅕䅁䑁䅁䅷䅁䭁䉁䅷䅁䭁䅁䅅䅁䭁䅁䅕䅁䙁䅁䅁䅁䅃畁䅚允䅁䅁䅅䅁䙁䉁䘫ㄶ㑇瑈⽕䍄䉁䅁䅁兂䅁䅁䅍䅄䅁䅁䅯杈䅁䅁䅯允䅁䅁䅯兂䅁䅁䅕䅁䅁䭁汃唵䉁䅁䅁允䅁䅁䅕積積積積稰䴸䅉䅅䅁䙁䅁䅁睁䵁䅁䅁权䅁䅁䅁权呂䅁䅁权䙁䅁䅁兂䅁䅁䅁䵙汘䅑䅅䅁䉁䅁䅁兂㑄⭕汏㑭祑䅑杷允䅁䅁䅕䅁䑁䅁䅷䅁䭁䉁䄰䅁䭁䅁䅅䅁䭁䅁䅕䅁䙁䅁䅁䅁䅃畕䅚允䅁䅁䅅䅁䙁䭁䠵場啯瑲⽣䍄䉁䅁䅁兂䅁䅁䅍䅄䅁䅁䅯䅈䅁䅁䅯睕䅁䅁䅯兂䅁䅁䅕䅁䅁䵁煂欵䉁䅁䅁允䅁䅁䅕㉣剩堷⽺啌䵁䅉䅅䅁䕁䅁䅁睁䵁䅁䅁权䅁䅁䅁权啂䅁䅁兂䅁䅁䅁䥯浌䅑䅅䅁䉁䅁䅁权扁䅁䅁䍄䉁䅁䅁䅂䅁䅁䅍䅄䅁䅁䅯睔䅁䅁䅯杔䅁䅁䅕䅁䅁䥁䍃欵䉁䅁䅁允䅁䅁䅕牕敧敨剴歄䵁䅉䅅䅁䙁䅁䅁睁䵁䅁䅁权晁䅁䅁权䉁䅁䅁权䙁䅁䅁兂䅁䅁䅁䌴浮䅑䅅䅁䉁䅁䅁兂䥂場啯歲桦睐杷允䅁䅁䅕䅁䑁䅁䅷䅁䭁䅁䅁䅁䭁䅁䅅䅁䭁䅁䅕䅁䙁䅁䅁䅁杂佰䅖允䅁䅁䅅䅁䙁䩁婱婭婭摭⽫䍄䉁䅁䅁兂䅁䅁䅍䅄䅁䅁䅯杈䅁䅁䅯允䅁䅁䅯兂䅁䅁䅕䅁䅁䝁㡄唵䉁䅁䅁允䅁䅁䅕硥畓⭒㙆䐱䴸䅉䅅䅁䕁䅁䅁睁䵁䅁䅁权偂䅁䅁权佂䅁䅁兂䅁䅁䅁䭁汐䅑䅅䅁䉁䅁䅁兂浂浚浚浚坢睐杷允䅁䅁䅕䅁䑁䅁䅷䅁䭁䅁䅁䅁䭁䙁䅍䅁䭁䅁䅕䅁䙁䅁䅁䅁杁⭋䅚允䅁䅁䅅䅁䙁佁兘瑉㕶橐䅎䍄䉁䅁䅁兂䅁䅁䅍䅄䅁䅁䅯杇䅁䅁䅯睕䅁䅁䅯兂䅁䅁䅕䅁䅁䍁硄唵䉁䅁䅁允䅁䅁䅕⽷潕䥘䌯問䵁䅉䅅䅁䕁䅁䅁睁䵁䅁䅁权偂䅁䅁权佂䅁䅁兂䅁䅁䅁䅙浮䅑䅅䅁䉁䅁䅁兂獄払敧敨剳䅑杷允䅁䅁䅕䅁䑁䅁䅷䅁䭁䅁䅁䅁䭁䅁䅅䅁䭁䅁䅕䅁䙁䅁䅁䅁杂⬴䅖允䅁䅁䅅䅁䙁佁㙆䭆䠵搴⽯䍄䉁䅁䅁兂䅁䅁䅍䅄䅁䅁䅯杇䅁䅁䅯睕䅁䅁䅯兂䅁䅁䅕䅁䅁䕁䡁欵䉁䅁䅁允䅁䅁䅕牒穢搯契歏䵁䅉䅅䅁䙁䅁䅁睁䵁䅁䅁权慁䅁䅁权呂䅁䅁权䙁䅁䅁兂䅁䅁䅁䍙浌䅑䅅䅁䉁䅁䅁兂㉃⼸唳䥥㙫䅑杷允䅁䅁䅑䅁䑁䅁䅷䅁䭁䕁䄸䅁䭁䕁䄴䅁䙁䅁䅁䅁杂畑䅚允䅁䅁䅅䅁䙁乁橥䑣䬰眱䄹䍄䉁䅁䅁兂䅁䅁䅍䅄䅁䅁䅯䅈䅁䅁䅯允䅁䅁䅯兂䅁䅁䅕䅁䅁䝁䅃欵䉁䅁䅁允䅁䅁䅕椹捨㡪ㅌ䐲䴸䅉䅅䅁䙁䅁䅁睁䵁䅁䅁权摁䅁䅁权䉁䅁䅁权䙁䅁䅁兂䅁䅁䅁余氯䅑䅅䅁䉁䅁䅁兂塄㍯㥁瑃呦睐杷允䅁䅁䅑䅁䑁䅁䅷䅁䭁䕁䄸䅁䭁䕁䄴䅁䙁䅁䅁䅁杂佂䅚允䅁䅁䅅䅁䙁䡁啳歲桦桥䅆䍄䉁䅁䅁䅂䅁䅁䅍䅄䅁䅁䅯睔䅁䅁䅯杔䅁䅁䅕䅁䅁䥁潁欵䉁䅁䅁允䅁䅁䅕灭婭婭婭啅䵁䅉䅅䅁䕁䅁䅁睁䵁䅁䅁权偂䅁䅁权佂䅁䅁兂䅁䅁䅁䍙浢䅑䅅䅁䉁䅁䅁兂卂䉵䘶ㄶ剅䅑杷允䅁䅁䅑䅁䑁䅁䅷䅁䭁䕁䄸䅁䭁䕁䄴䅁䙁䅁䅁䅁杂佚䅚允䅁䅁䅅䅁䙁䡁啳歲桦来䄵䍄䉁䅁䅁兂䅁䅁䅍䅄䅁䅁䅯先䅁䅁䅯允䅁䅁䅯兂䅁䅁䅕䅁䅁䝁兂欵䉁䅁䅁允䅁䅁䅕歲桦桥畓稱䴸䅉䅅䅁䕁䅁䅁睁䵁䅁䅁权偂䅁䅁权佂䅁䅁兂䅁䅁䅁䘴浶䅑䅅䅁䉁䅁䅁兂穁積積積免䅑杷允䅁䅁䅕䅁䑁䅁䅷䅁䭁䉁䅷䅁䭁䅁䅅䅁䭁䅁䅕䅁䙁䅁䅁䅁䅃甯䅖允䅁䅁䅅䅁䙁䉁䘫ㄶ㑇瑈⽕䍄䉁䅁䅁兂䅁䅁䅍䅄䅁䅁䅯杈䅁䅁䅯睕䅁䅁䅯兂䅁䅁䅕䅁䅁佁扁欵䉁䅁䅁允䅁䅁䅕兇坒楄礱啋䵁䅉䅅䅁䙁䅁䅁睁䵁䅁䅁权䅁䅁䅁权䉁䅁䅁权䙁䅁䅁兂䅁䅁䅁䠴浌䅑䅅䅁䉁䅁䅁兂㑃潈牘払敪睐杷允䅁䅁䅑䅁䑁䅁䅷䅁䭁䕁䄸䅁䭁䕁䄴䅁䙁䅁䅁䅁䅃畡䅚允䅁䅁䅅䅁䙁䵁ㅐ䙋偹杷䅴䍄䉁䅁䅁兂䅁䅁䅍䅄䅁䅁䅯先䅁䅁䅯允䅁䅁䅯兂䅁䅁䅕䅁䅁䕁敃唵䉁䅁䅁允䅁䅁䅕㘱睎児塲稰䴸䅉䅅䅁䕁䅁䅁睁䵁䅁䅁权偂䅁䅁权佂䅁䅁兂䅁䅁䅁䥯浄䅑䅅䅁䉁䅁䅁兂浂浚浚浚䵙䅑杷允䅁䅁䅕䅁䑁䅁䅷䅁䭁䉁䄴䅁䭁䙁䅍䅁䭁䅁䅕䅁䙁䅁䅁䅁䅃畱䅖允䅁䅁䅅䅁䙁䡁⭥确癯午䅴䍄䉁䅁䅁䅂䅁䅁䅍䅄䅁䅁䅯睔䅁䅁䅯杔䅁䅁䅕䅁䅁䥁獁欵䉁䅁䅁允䅁䅁䅕硥畓⭒㙆ぅ䵁䅉䅅䅁䙁䅁䅁睁䵁䅁䅁权䅁䅁䅁权䉁䅁䅁权䙁䅁䅁兂䅁䅁䅁䵉汄䅑䅅䅁䉁䅁䅁兂㥁瑃橥䑣愳睐杷允䅁䅁䅕䅁䑁䅁䅷䅁䭁䅁䅁䅁䭁䅁䅅䅁䭁䅁䅕䅁䙁䅁䅁䅁䅄敚䅚允䅁䅁䅅䅁䙁䱁敧敨剴乵⼴䍄䉁䅁䅁兂䅁䅁䅍䅄䅁䅁䅯先䅁䅁䅯允䅁䅁䅯兂䅁䅁䅕䅁䅁䍁婂欵䉁䅁䅁允䅁䅁䅕歲桦桥畓稱䴸䅉䅅䅁䕁䅁䅁睁䵁䅁䅁权偂䅁䅁权佂䅁䅁兂䅁䅁䅁䍁洯䅑䅅䅁䉁䅁䅁兂㝂䭆䠵場卯䅑杷允䅁䅁䅕䅁䑁䅁䅷䅁䭁䉁䄴䅁䭁䙁䅍䅁䭁䅁䅕䅁䙁䅁䅁䅁䅄異䅖允䅁䅁䅅䅁䙁䡁⭥确癯午䅴䍄䉁䅁䅁兂䅁䅁䅍䅄䅁䅁䅯睈䅁䅁䅯睕䅁䅁䅯兂䅁䅁䅕䅁䅁䅁㝃唵䉁䅁䅁允䅁䅁䅕塹⭡确癯啍䵁䅉䅅䅁䙁䅁䅁睁䵁䅁䅁权摁䅁䅁权呂䅁䅁权䙁䅁䅁兂䅁䅁䅁佧決䅑䅅䅁䉁䅁䅁兂浃㡭村䱳瑉䅑杷允䅁䅁䅑䅁䑁䅁䅷䅁䭁䕁䄸䅁䭁䕁䄴䅁䙁䅁䅁䅁杁畔䅚允䅁䅁䅅䅁䙁䙁㑋潈牘剕䅆䍄䉁䅁䅁兂䅁䅁䅍䅄䅁䅁䅯杇䅁䅁䅯允䅁䅁䅯兂䅁䅁䅕䅁䅁䝁湂欵䉁䅁䅁允䅁䅁䅕䡰㥁瑃橥䐶䴸䅉䅅䅁䙁䅁䅁睁䵁䅁䅁权䅁䅁䅁权呂䅁䅁权䙁䅁䅁兂䅁䅁䅁䑷浔䅑䅅䅁䉁䅁䅁兂瑁灳瘳㑰穙䅑杷允䅁䅁䅕䅁䑁䅁䅷䅁䭁䉁䅷䅁䭁䅁䅅䅁䭁䅁䅕䅁䙁䅁䅁䅁䅁佌䅚允䅁䅁䅅䅁䙁䭁䠵場啯瑲⽣䍄䉁䅁䅁兂䅁䅁䅍䅄䅁䅁䅯杈䅁䅁䅯睕䅁䅁䅯兂䅁䅁䅕䅁䅁䭁祁欵䉁䅁䅁允䅁䅁䅕体㙆䭆䠵歊䵁䅉䅅䅁䕁䅁䅁睁䵁䅁䅁权偂䅁䅁权佂䅁䅁兂䅁䅁䅁䵷氷䅑䅅䅁䉁䅁䅁兂塄㍯㥁瑃䙣䅑杷允䅁䅁䅑䅁䑁䅁䅷䅁䭁䕁䄸䅁䭁䕁䄴䅁䙁䅁䅁䅁杁⭌䅚允䅁䅁䅅䅁䙁䡁㥅瑃橥䉣䅊䍄䉁䅁䅁兂䅁䅁䅍䅄䅁䅁䅯䅁䅁䅁䅯睕䅁䅁䅯兂䅁䅁䅕䅁䅁佁慁欵䉁䅁䅁允䅁䅁䅕硢䑋䵷䉯き䵁䅉䅅䅁䕁䅁䅁睁䵁䅁䅁权偂䅁䅁权佂䅁䅁兂䅁䅁䅁䝷浔䅑䅅䅁䉁䅁䅁兂㉄䙋偹癷何䅑杷允䅁䅁䅕䅁䑁䅁䅷䅁䭁䉁䅷䅁䭁䙁䅍䅁䭁䅁䅕䅁䙁䅁䅁䅁杂⭈䅚允䅁䅁䅅䅁䙁䱁摋㘷䝦祃䄵䍄䉁䅁䅁兂䅁䅁䅍䅄䅁䅁䅯先䅁䅁䅯睕䅁䅁䅯兂䅁䅁䅕䅁䅁䝁卄唵䉁䅁䅁允䅁䅁䅕⽷潕䥘䌯啌䵁䅉䅅䅁䕁䅁䅁睁䵁䅁䅁权偂䅁䅁权佂䅁䅁兂䅁䅁䅁䑙浄䅑䅅䅁䉁䅁䅁兂䑄匹捨㡪卉䅑杷允䅁䅁䅕䅁䑁䅁䅷䅁䭁䉁䅷䅁䭁䅁䅅䅁䭁䅁䅕䅁䙁䅁䅁䅁䅄佱䅖允䅁䅁䅅䅁䙁䥁䌯匹捨㥪⽉䍄䉁䅁䅁兂䅁䅁䅍䅄䅁䅁䅯䅈䅁䅁䅯睕䅁䅁䅯兂䅁䅁䅕䅁䅁䵁奄唵䉁䅁䅁允䅁䅁䅕浔光䑗ね歌䵁䅉䅅䅁䙁䅁䅁睁䵁䅁䅁权䅁䅁䅁权呂䅁䅁权䙁䅁䅁兂䅁䅁䅁佷汄䅑䅅䅁䉁䅁䅁兂婁䙂余摌祉䅑杷允䅁䅁䅕䅁䑁䅁䅷䅁䭁䉁䄰䅁䭁䅁䅅䅁䭁䅁䅕䅁䙁䅁䅁䅁杄伱䅖允䅁䅁䅅䅁䙁乁橥䑣䬰㤱⽍䍄䉁䅁䅁兂䅁䅁䅍䅄䅁䅁䅯杈䅁䅁䅯允䅁䅁䅯兂䅁䅁䅕䅁䅁䵁㉃唵䉁䅁䅁允䅁䅁䅕積積積積稰䴸䅉䅅䅁䕁䅁䅁睁䵁䅁䅁权偂䅁䅁权佂䅁䅁兂䅁䅁䅁䝧浦䅑䅅䅁䉁䅁䅁兂塄㍯㥁瑃乣䅑杷允䅁䅁䅕䅁䑁䅁䅷䅁䭁䅁䅁䅁䭁䅁䅅䅁䭁䅁䅕䅁䙁䅁䅁䅁杁⭓䅚允䅁䅁䅅䅁䙁䱁敧敨剴乵⼴䍄䉁䅁䅁兂䅁䅁䅍䅄䅁䅁䅯杈䅁䅁䅯睕䅁䅁䅯兂䅁䅁䅕䅁䅁䵁㉃唵䉁䅁䅁允䅁䅁䅕癴㥐䠱灨䕌䵁䅉䅅䅁䙁䅁䅁睁䵁䅁䅁权䅁䅁䅁权䉁䅁䅁权䙁䅁䅁兂䅁䅁䅁䱁汪䅑䅅䅁䉁䅁䅁兂慃婭婭婭婮睐杷允䅁䅁䅑䅁䑁䅁䅷䅁䭁䕁䄸䅁䭁䕁䄴䅁䙁䅁䅁䅁䅃畃䅚允䅁䅁䅅䅁䙁䍁捬㡪ㅌ䉋䅊䍄䉁䅁䅁兂䅁䅁䅍䅄䅁䅁䅯杇䅁䅁䅯允䅁䅁䅯兂䅁䅁䅕䅁䅁䝁䭁欵䉁䅁䅁允䅁䅁䅕浚浚浚浚樵䴸䅉䅅䅁䙁䅁䅁睁䵁䅁䅁权䅁䅁䅁权䉁䅁䅁权䙁䅁䅁兂䅁䅁䅁䡯浮䅑䅅䅁䉁䅁䅁兂㑃潈牘払敪睐杷允䅁䅁䅕䅁䑁䅁䅷䅁䭁䅁䅁䅁䭁䙁䅍䅁䭁䅁䅕䅁䙁䅁䅁䅁䅃畚䅚允䅁䅁䅅䅁䙁䙁橔婰䕶䐴䅎䍄䉁䅁䅁兂䅁䅁䅍䅄䅁䅁䅯睈䅁䅁䅯允䅁䅁䅯兂䅁䅁䅕䅁䅁䍁⭂欵䉁䅁䅁允䅁䅁䅕牕敧敨剴䐴䴸䅉䅅䅁䕁䅁䅁睁䵁䅁䅁权偂䅁䅁权佂䅁䅁兂䅁䅁䅁䕉浘䅑䅅䅁䉁䅁䅁兂䅁䅁䅁䅁剁䅑杷允䅁䅁䅕䅁䑁䅁䅷䅁䭁䉁䅷䅁䭁䅁䅅䅁䭁䅁䅕䅁䙁䅁䅁䅁䅁畒䅚允䅁䅁䅅䅁䙁偁潙䥘䌯搹⽧䍄䉁䅁䅁䅂䅁䅁䅍䅄䅁䅁䅯睔䅁䅁䅯杔䅁䅁䅕䅁䅁䥁浄唵䉁䅁䅁允䅁䅁䅕䉵䘶ㄶ㑇啅䵁䅉䅅䅁䙁䅁䅁睁䵁䅁䅁权晁䅁䅁权呂䅁䅁权䙁䅁䅁兂䅁䅁䅁偉氳䅑䅅䅁䉁䅁䅁兂偄ㄹ橐塰睳䅑杷允䅁䅁䅕䅁䑁䅁䅷䅁䭁䅁䅁䅁䭁䅁䅅䅁䭁䅁䅕䅁䙁䅁䅁䅁杁⬰䅖允䅁䅁䅅䅁䙁佁㙆䭆䠵搴⽯䍄䉁䅁䅁兂䅁䅁䅍䅄䅁䅁䅯杇䅁䅁䅯允䅁䅁䅯兂䅁䅁䅕䅁䅁䵁坃唵䉁䅁䅁允䅁䅁䅕䅁䅁䅁䅁䐴䴸䅉䅅䅁䙁䅁䅁睁䵁䅁䅁权摁䅁䅁权呂䅁䅁权䙁䅁䅁兂䅁䅁䅁䵯汮䅑䅅䅁䉁䅁䅁兂灁䥘䌯匹畧䅑杷允䅁䅁䅕䅁䑁䅁䅷䅁䭁䅁䅁䅁䭁䅁䅅䅁䭁䅁䅕䅁䙁䅁䅁䅁䅁敭䅖允䅁䅁䅅䅁䙁䩁婱婭婭摭⽫䍄䉁䅁䅁䅂䅁䅁䅍䅄䅁䅁䅯睔䅁䅁䅯杔䅁䅁䅕䅁䅁䍁摁欵䉁䅁䅁允䅁䅁䅕瑃橥䑣䬰䕅䵁䅉䅅䅁䕁䅁䅁睁䵁䅁䅁权偂䅁䅁权佂䅁䅁兂䅁䅁䅁䝷浐䅑䅅䅁䉁䅁䅁兂桄桥畓⭒佅䅑杷允䅁䅁䅑䅁䑁䅁䅷䅁䭁䕁䄸䅁䭁䕁䄴䅁䙁䅁䅁䅁杁⭵䅖允䅁䅁䅅䅁䙁䉁䘫ㄶ㑇畈⽕䍄䉁䅁䅁兂䅁䅁䅍䅄䅁䅁䅯䅁䅁䅁䅯允䅁䅁䅯兂䅁䅁䅕䅁䅁䍁佄唵䉁䅁䅁允䅁䅁䅕児塲㍯㥁樲䴸䅉䅅䅁䙁䅁䅁睁䵁䅁䅁权晁䅁䅁权䉁䅁䅁权䙁䅁䅁兂䅁䅁䅁䉑浈䅑䅅䅁䉁䅁䅁兂歃䑣䬰㘱材睐杷允䅁䅁䅕䅁䑁䅁䅷䅁䭁䅁䅁䅁䭁䙁䅍䅁䭁䅁䅕䅁䙁䅁䅁䅁杁伷䅖允䅁䅁䅅䅁䙁䑁積積積穫䅊䍄䉁䅁䅁䅂䅁䅁䅍䅄䅁䅁䅯睔䅁䅁䅯杔䅁䅁䅕䅁䅁䥁䱂欵䉁䅁䅁允䅁䅁䅕体㙆䭆䠵啅䵁䅉䅅䅁䙁䅁䅁睁䵁䅁䅁权晁䅁䅁权呂䅁䅁权䙁䅁䅁兂䅁䅁䅁乁汘䅑䅅䅁䉁䅁䅁兂扁㥌欰畂睅䅑杷允䅁䅁䅑䅁䑁䅁䅷䅁䭁䕁䄸䅁䭁䕁䄴䅁䙁䅁䅁䅁杂教䅚允䅁䅁䅅䅁䙁䵁ㅐ䙋偹杷䄱䍄䉁䅁䅁䅂䅁䅁䅍䅄䅁䅁䅯睔䅁䅁䅯杔䅁䅁䅕䅁䅁䝁䡄唵䉁䅁䅁允䅁䅁䅕䥘䌯匹捨稫䴸䅉䅅䅁䙁䅁䅁睁䵁䅁䅁权䅁䅁䅁权呂䅁䅁权䙁䅁䅁兂䅁䅁䅁䭑氯䅑䅅䅁䉁䅁䅁兂㙃兓䍷祋祣䅑杷允䅁䅁䅕䅁䑁䅁䅷䅁䭁䉁䅷䅁䭁䙁䅍䅁䭁䅁䅕䅁䙁䅁䅁䅁权敧䅚允䅁䅁䅅䅁䙁䵁㉬灶愸祲䄱䍄䉁䅁䅁䅂䅁䅁䅍䅄䅁䅁䅯睔䅁䅁䅯杔䅁䅁䅕䅁䅁䕁剁欵䉁䅁䅁允䅁䅁䅕牕敧敨剴ぅ䵁䅉䅅䅁䙁䅁䅁睁䵁䅁䅁权晁䅁䅁权呂䅁䅁权䙁䅁䅁兂䅁䅁䅁佷汲䅑䅅䅁䉁䅁䅁兂橁⼲⭬污睷䅑杷允䅁䅁䅕䅁䑁䅁䅷䅁䭁䉁䅯䅁䭁䙁䅍䅁䭁䅁䅕䅁䙁䅁䅁䅁䅁畢䅚允䅁䅁䅅䅁䙁䍁搯䅊䉡呖䅴䍄䉁䅁䅁兂䅁䅁䅍䅄䅁䅁䅯睈䅁䅁䅯睕䅁䅁䅯兂䅁䅁䅕䅁䅁䭁䩂欵䉁䅁䅁允䅁䅁䅕䙂余扌摉啍䵁䅉䅅䅁䙁䅁䅁睁䵁䅁䅁权䅁䅁䅁权呂䅁䅁权䙁䅁䅁兂䅁䅁䅁䜴浮䅑䅅䅁䉁䅁䅁兂啂㘴扗佸穁䅑杷允䅁䅁䅕䅁䑁䅁䅷䅁䭁䉁䄸䅁䭁䙁䅍䅁䭁䅁䅕䅁䙁䅁䅁䅁杄畕䅚允䅁䅁䅅䅁䙁䡁⼰噎㘶呋䅆䍄䉁䅁䅁兂䅁䅁䅍䅄䅁䅁䅯睈䅁䅁䅯睕䅁䅁䅯兂䅁䅁䅕䅁䅁䵁捄唵䉁䅁䅁允䅁䅁䅕祇搯䅊桢䕍䵁䅉䅅䅁䕁䅁䅁睁䵁䅁䅁权偂䅁䅁权佂䅁䅁兂䅁䅁䅁䝯浺䅑䅅䅁䉁䅁䅁兂䥂場啯歲乣䅑杷允䅁䅁䅕䅁䑁䅁䅷䅁䭁䅁䅁䅁䭁䙁䅍䅁䭁䅁䅕䅁䙁䅁䅁䅁权甫䅖允䅁䅁䅅䅁䙁䍁捬㡪ㅌ䑡䅊䍄䉁䅁䅁䅂䅁䅁䅍䅄䅁䅁䅯䅁䅁䅁䅯睕䅁䅁䅕䅁䅁䝁䍃欵䉁䅁䅁允䅁䅁䅯䅂䅁䅁杷允䅁䅁䅕䅁䑁䅁䅷䅁䭁䅁䅁䅁䭁䅁䅅䅁䭁䅁䅕䅁䙁䅁䅁䅁䅁敍䅚允䅁䅁䅅䅁䙁䱁敧敨剴乵⼴䍄䉁䅁䅁兂䅁䅁䅍䅄䅁䅁䅯䅁䅁䅁䅯睕䅁䅁䅯兂䅁䅁䅕䅁䅁佁䥁欵䉁䅁䅁允䅁䅁䅕癱午坔睊歍䵁䅉䅅䅁䙁䅁䅁睁䵁䅁䅁权晁䅁䅁权䉁䅁䅁权䙁䅁䅁兂䅁䅁䅁䝯浌䅑䅅䅁䉁䅁䅁兂㉄䙋偹癷杘睐杷允䅁䅁䅑䅁䑁䅁䅷䅁䭁䕁䄸䅁䭁䕁䄴䅁䙁䅁䅁䅁杂⭌䅚允䅁䅁䅅䅁䙁乁橥䑣䬰砱䅊䍄䉁䅁䅁兂䅁䅁䅍䅄䅁䅁䅯䅁䅁䅁䅯睕䅁䅁䅯兂䅁䅁䅕䅁䅁䍁㡁欵䉁䅁䅁允䅁䅁䅕䅁䅁䅁权き䵁䅉䅅䅁䕁䅁䅁睁䵁䅁䅁权偂䅁䅁权佂䅁䅁兂䅁䅁䅁偷汶䅑䅅䅁䉁䅁䅁兂㑃潈牘払䵧䅑杷允䅁䅁䅕䅁䑁䅁䅷䅁䭁䅁䅁䅁䭁䙁䅍䅁䭁䅁䅕䅁䙁䅁䅁䅁䅂敆䅚允䅁䅁䅅䅁䙁䝁匸㡧䭄呁䅎䍄䉁䅁䅁兂䅁䅁䅍䅄䅁䅁䅯先䅁䅁䅯睕䅁䅁䅯兂䅁䅁䅕䅁䅁䕁䱂欵䉁䅁䅁允䅁䅁䅕婤奍䙂佡歌䵁䅉䅅䅁䕁䅁䅁睁䵁䅁䅁权偂䅁䅁权佂䅁䅁兂䅁䅁䅁乙氯䅑䅅䅁䉁䅁䅁兂桄桥畓⭒䭅䅑杷允䅁䅁䅕䅁䑁䅁䅷䅁䭁䉁䅷䅁䭁䙁䅍䅁䭁䅁䅕䅁䙁䅁䅁䅁䅃攷䅖允䅁䅁䅅䅁䙁䱁䩰䅄牉祸䄱䍄䉁䅁䅁兂䅁䅁䅍䅄䅁䅁䅯睈䅁䅁䅯睕䅁䅁䅯兂䅁䅁䅕䅁䅁䝁祂欵䉁䅁䅁允䅁䅁䅕牡へ硫歧啍䵁䅉䅅䅁䕁䅁䅁睁䵁䅁䅁权偂䅁䅁权佂䅁䅁兂䅁䅁䅁䡧浔䅑䅅䅁䉁䅁䅁兂䑄匹捨㡪䱉䅑杷允䅁䅁䅕䅁䑁䅁䅷䅁䭁䉁䄰䅁䭁䙁䅍䅁䭁䅁䅕䅁䙁䅁䅁䅁杄敬䅖允䅁䅁䅅䅁䙁䱁へ硫䕧楖䄱䍄䉁䅁䅁兂䅁䅁䅍䅄䅁䅁䅯䅁䅁䅁䅯允䅁䅁䅯兂䅁䅁䅕䅁䅁䕁剂欵䉁䅁䅁允䅁䅁䅕䉵䘶ㄶ㑇樳䴸䅉䅅䅁䙁䅁䅁睁䵁䅁䅁权摁䅁䅁权䉁䅁䅁权䙁䅁䅁兂䅁䅁䅁䄴浘䅑䅅䅁䉁䅁䅁兂晁敨剴䉵嘷睐杷允䅁䅁䅕䅁䑁䅁䅷䅁䭁䉁䄴䅁䭁䙁䅍䅁䭁䅁䅕䅁䙁䅁䅁䅁䅄敹䅖允䅁䅁䅅䅁䙁䍁䡵瑆佮祴䅸䍄䉁䅁䅁兂䅁䅁䅍䅄䅁䅁䅯睈䅁䅁䅯允䅁䅁䅯兂䅁䅁䅕䅁䅁䅁桂欵䉁䅁䅁允䅁䅁䅕椹捨㡪ㅌ䐴䴸䅉䅅䅁䙁䅁䅁睁䵁䅁䅁权晁䅁䅁权呂䅁䅁权䙁䅁䅁兂䅁䅁䅁䉧浲䅑䅅䅁䉁䅁䅁兂䝂癴㥐倱睧䅑杷允䅁䅁䅑䅁䑁䅁䅷䅁䭁䕁䄸䅁䭁䕁䄴䅁䙁䅁䅁䅁杂畏䅚允䅁䅁䅅䅁䙁佁㙆䭆䠵儴䄵䍄䉁䅁䅁兂䅁䅁䅍䅄䅁䅁䅯䅈䅁䅁䅯允䅁䅁䅯兂䅁䅁䅕䅁䅁䥁㝂欵䉁䅁䅁允䅁䅁䅕椹捨㡪ㅌ䐲䴸䅉䅅䅁䕁䅁䅁睁䵁䅁䅁权偂䅁䅁权佂䅁䅁兂䅁䅁䅁䥑浌䅑䅅䅁䉁䅁䅁兂硂児塲㍯乁䅑杷允䅁䅁䅑䅁䑁䅁䅷䅁䭁䕁䄸䅁䭁䕁䄴䅁䙁䅁䅁䅁䅃佴䅖允䅁䅁䅅䅁䙁䍁捬㡪ㅌ之⽷䍄䉁䅁䅁䅂䅁䅁䅍䅄䅁䅁䅯睔䅁䅁䅯杔䅁䅁䅕䅁䅁䝁佄唵䉁䅁䅁允䅁䅁䅕㘱睎児塲啂䵁䅉䅅䅁䕁䅁䅁睁䵁䅁䅁权偂䅁䅁权佂䅁䅁兂䅁䅁䅁临汔䅑䅅䅁䉁䅁䅁兂晁敨剴䉵䘴䅑杷允䅁䅁䅕䅁䑁䅁䅷䅁䭁䅁䅁䅁䭁䅁䅅䅁䭁䅁䅕䅁䙁䅁䅁䅁权佅䅚允䅁䅁䅅䅁䙁䱁敧敨剴乵⼴䍄䉁䅁䅁䅂䅁䅁䅍䅄䅁䅁䅯睔䅁䅁䅯杔䅁䅁䅕䅁䅁䵁㙁欵䉁䅁䅁允䅁䅁䅕㡪ㅌ䙋偹歄䵁䅉䅅䅁䙁䅁䅁睁䵁䅁䅁权慁䅁䅁权䉁䅁䅁权䙁䅁䅁兂䅁䅁䅁䙉浲䅑䅅䅁䉁䅁䅁兂歃䑣䬰㘱潐睐杷允䅁䅁䅕䅁䑁䅁䅷䅁䭁䉁䅯䅁䭁䙁䅍䅁䭁䅁䅕䅁䙁䅁䅁䅁杄敉䅚允䅁䅁䅅䅁䙁䱁穢搯㑒呩䅰䍄䉁䅁䅁兂䅁䅁䅍䅄䅁䅁䅯先䅁䅁䅯睕䅁䅁䅯兂䅁䅁䅕䅁䅁䭁䥁欵䉁䅁䅁允䅁䅁䅕䝭匴㡧䭂歌䵁䅉䅅䅁䙁䅁䅁睁䵁䅁䅁权䅁䅁䅁权呂䅁䅁权䙁䅁䅁兂䅁䅁䅁䵉決䅑䅅䅁䉁䅁䅁兂瑂⼵灵昸祉䅑杷允䅁䅁䅑䅁䑁䅁䅷䅁䭁䕁䄸䅁䭁䕁䄴䅁䙁䅁䅁䅁杂⭥䅚允䅁䅁䅅䅁䙁䕁桪桥畓睒䄱䍄䉁䅁䅁䅂䅁䅁䅍䅄䅁䅁䅯睔䅁䅁䅯杔䅁䅁䅕䅁䅁䕁捁欵䉁䅁䅁允䅁䅁䅕噋偹癷潕䕅䵁䅉䅅䅁䕁䅁䅁睁䵁䅁䅁权偂䅁䅁权佂䅁䅁兂䅁䅁䅁䡧洯䅑䅅䅁䉁䅁䅁兂慃婭婭婭䱫䅑杷允䅁䅁䅕䅁䑁䅁䅷䅁䭁䉁䄸䅁䭁䅁䅅䅁䭁䅁䅕䅁䙁䅁䅁䅁䅂位䅚允䅁䅁䅅䅁䙁䕁桪桥畓⭒⽅䍄䉁䅁䅁兂䅁䅁䅍䅄䅁䅁䅯䅁䅁䅁䅯睕䅁䅁䅯兂䅁䅁䅕䅁䅁䍁㕄唵䉁䅁䅁允䅁䅁䅕噋偹癷潖歍䵁䅉䅅䅁䕁䅁䅁睁䵁䅁䅁权偂䅁䅁权佂䅁䅁兂䅁䅁䅁䍉浮䅑䅅䅁䉁䅁䅁兂獄払敧敨剳䅑杷允䅁䅁䅕䅁䑁䅁䅷䅁䭁䉁䄰䅁䭁䙁䅍䅁䭁䅁䅕䅁䙁䅁䅁䅁䅃敹䅖允䅁䅁䅅䅁䙁䍁捬㡪ㅌ䍋䄵䍄䉁䅁䅁兂䅁䅁䅍䅄䅁䅁䅯䅁䅁䅁䅯睕䅁䅁䅯兂䅁䅁䅕䅁䅁䵁穃唵䉁䅁䅁允䅁䅁䅕歵䵫楁湳歍䵁䅉䅅䅁䙁䅁䅁睁䵁䅁䅁权捁䅁䅁权呂䅁䅁权䙁䅁䅁兂䅁䅁䅁乁氯䅑䅅䅁䉁䅁䅁兂楂䙅㕧䕴畧䅑杷允䅁䅁䅕䅁䑁䅁䅷䅁䭁䉁䄰䅁䭁䙁䅍䅁䭁䅁䅕䅁䙁䅁䅁䅁杁敖䅚允䅁䅁䅅䅁䙁䵁ㅐ䙋偹楧䄵䍄䉁䅁䅁兂䅁䅁䅍䅄䅁䅁䅯杈䅁䅁䅯允䅁䅁䅯兂䅁䅁䅕䅁䅁䍁噁欵䉁䅁䅁允䅁䅁䅕⽷潕䥘䌯吱䴸䅉䅅䅁䕁䅁䅁睁䵁䅁䅁权偂䅁䅁权佂䅁䅁兂䅁䅁䅁䕑洳䅑䅅䅁䉁䅁䅁兂卂䉵䘶ㄶ剅䅑杷允䅁䅁䅕䅁䑁䅁䅷䅁䭁䉁䅷䅁䭁䙁䅍䅁䭁䅁䅕䅁䙁䅁䅁䅁杁佘䅚允䅁䅁䅅䅁䙁䭁䙊癴㥐䍆䄵䍄䉁䅁䅁兂䅁䅁䅍䅄䅁䅁䅯杈䅁䅁䅯睕䅁䅁䅯兂䅁䅁䅕䅁䅁䭁⽁欵䉁䅁䅁允䅁䅁䅕倹唳佥浬䕊䵁䅉䅅䅁䕁䅁䅁睁䵁䅁䅁权偂䅁䅁权佂䅁䅁兂䅁䅁䅁䡯洷䅑䅅䅁䉁䅁䅁兂硂児塲㍯䱁䅑杷允䅁䅁䅑䅁䑁䅁䅷䅁䭁䕁䄸䅁䭁䕁䄴䅁䙁䅁䅁䅁杄伷䅖允䅁䅁䅅䅁䙁䍁捬㡪ㅌ䉋䅂䍄䉁䅁䅁䅂䅁䅁䅍䅄䅁䅁䅯睔䅁䅁䅯杔䅁䅁䅕䅁䅁䅁坂欵䉁䅁䅁允䅁䅁䅕体㙆䭆䠵い䵁䅉䅅䅁䙁䅁䅁睁䵁䅁䅁权敁䅁䅁权䉁䅁䅁权䙁䅁䅁兂䅁䅁䅁䍯浐䅑䅅䅁䉁䅁䅁兂䑄匹捨㡪噌睐杷允䅁䅁䅕䅁䑁䅁䅷䅁䭁䅁䅁䅁䭁䅁䅅䅁䭁䅁䅕䅁䙁䅁䅁䅁䅂甲䅖允䅁䅁䅅䅁䙁佁㙆䭆䠵搴⽯䍄䉁䅁䅁䅂䅁䅁䅍䅄䅁䅁䅯睔䅁䅁䅯杔䅁䅁䅕䅁䅁䭁䝂欵䉁䅁䅁允䅁䅁䅕㘱睎児塲䕅䵁䅉䅅䅁䙁䅁䅁睁䵁䅁䅁权䅁䅁䅁权呂䅁䅁权䙁䅁䅁兂䅁䅁䅁䘴浘䅑䅅䅁䉁䅁䅁兂㕁䵴㉨瑶稸䅑杷允䅁䅁䅑䅁䑁䅁䅷䅁䭁䕁䄸䅁䭁䕁䄴䅁䙁䅁䅁䅁权佴䅖允䅁䅁䅅䅁䙁䥁牘払敧摨⽳䍄䉁䅁䅁兂䅁䅁䅍䅄䅁䅁䅯䅈䅁䅁䅯允䅁䅁䅯兂䅁䅁䅕䅁䅁䵁乂欵䉁䅁䅁允䅁䅁䅕椹捨㡪ㅌ䐲䴸䅉䅅䅁䙁䅁䅁睁䵁䅁䅁权慁䅁䅁权呂䅁䅁权䙁䅁䅁兂䅁䅁䅁䱑氷䅑䅅䅁䉁䅁䅁兂㙃兓䍷祋㙣䅑杷允䅁䅁䅕䅁䑁䅁䅷䅁䭁䉁䄴䅁䭁䅁䅅䅁䭁䅁䅕䅁䙁䅁䅁䅁杄畱䅖允䅁䅁䅅䅁䙁䑁積積積㥍⽍䍄䉁䅁䅁兂䅁䅁䅍䅄䅁䅁䅯睈䅁䅁䅯睕䅁䅁䅯兂䅁䅁䅕䅁䅁䥁塄唵䉁䅁䅁允䅁䅁䅕祇搯䅊桢䕍䵁䅉䅅䅁䕁䅁䅁睁䵁䅁䅁权偂䅁䅁权佂䅁䅁兂䅁䅁䅁䵑汔䅑䅅䅁䉁䅁䅁兂灁䥘䌯匹な睐杷允䅁䅁䅑䅁䑁䅁䅷䅁䭁䕁䄸䅁䭁䕁䄴䅁䙁䅁䅁䅁杁敄䅚允䅁䅁䅅䅁䙁䥁䌯匹捨硪䅊䍄䉁䅁䅁兂䅁䅁䅍䅄䅁䅁䅯先䅁䅁䅯睕䅁䅁䅯兂䅁䅁䅕䅁䅁䭁坁欵䉁䅁䅁允䅁䅁䅕歵䵫楁䡵歌䵁䅉䅅䅁䕁䅁䅁睁䵁䅁䅁权偂䅁䅁权佂䅁䅁兂䅁䅁䅁䍙浺䅑䅅䅁䉁䅁䅁兂穁積積積呍䅑杷允䅁䅁䅑䅁䑁䅁䅷䅁䭁䕁䄸䅁䭁䕁䄴䅁䙁䅁䅁䅁䅁敥䅚允䅁䅁䅅䅁䙁䝁浚浚浚杚䅸䍄䉁䅁䅁䅂䅁䅁䅍䅄䅁䅁䅯睔䅁䅁䅯杔䅁䅁䅕䅁䅁佁摄唵䉁䅁䅁允䅁䅁䅕瑃橥䑣䬰啃䵁䅉䅅䅁䕁䅁䅁睁䵁䅁䅁权偂䅁䅁权佂䅁䅁兂䅁䅁䅁䡯浌䅑䅅䅁䉁䅁䅁兂浂浚浚浚䵙䅑杷允䅁䅁䅕䅁䑁䅁䅷䅁䭁䉁䄰䅁䭁䙁䅍䅁䭁䅁䅕䅁䙁䅁䅁䅁䅃畲䅖允䅁䅁䅅䅁䙁乁佮ㄹ橐印䄱䍄䉁䅁䅁䅂䅁䅁䅍䅄䅁䅁䅯睔䅁䅁䅯杔䅁䅁䅕䅁䅁䍁楂欵䉁䅁䅁允䅁䅁䅕䉵䘶ㄶ㑇歄䵁䅉䅅䅁䙁䅁䅁睁䵁䅁䅁权慁䅁䅁权呂䅁䅁权䙁䅁䅁兂䅁䅁䅁䈴浐䅑䅅䅁䉁䅁䅁兂䝁婧䑖ど㙷䅑杷允䅁䅁䅕䅁䑁䅁䅷䅁䭁䅁䅁䅁䭁䅁䅅䅁䭁䅁䅕䅁䙁䅁䅁䅁䅄敥䅚允䅁䅁䅅䅁䙁䱁敧敨剴乵⼴䍄䉁䅁䅁兂䅁䅁䅍䅄䅁䅁䅯䅁䅁䅁䅯睕䅁䅁䅯兂䅁䅁䅕䅁䅁佁⭁欵䉁䅁䅁允䅁䅁䅕䅁䅁䅁权き䵁䅉䅅䅁䙁䅁䅁睁䵁䅁䅁权慁䅁䅁权呂䅁䅁权䙁䅁䅁兂䅁䅁䅁义汄䅑䅅䅁䉁䅁䅁兂权楇搯䕊㙙䅑杷允䅁䅁䅕䅁䑁䅁䅷䅁䭁䉁䄸䅁䭁䙁䅍䅁䭁䅁䅕䅁䙁䅁䅁䅁杂佧䅚允䅁䅁䅅䅁䙁䝁汄䌰扌含䅂䍄䉁䅁䅁䅂䅁䅁䅍䅄䅁䅁䅯睔䅁䅁䅯杔䅁䅁䅕䅁䅁䅁乁欵䉁䅁䅁允䅁䅁䅕䅁䅁䅁䅁ぅ䵁䅉䅅䅁䙁䅁䅁睁䵁䅁䅁权摁䅁䅁权呂䅁䅁权䙁䅁䅁兂䅁䅁䅁䉙浄䅑䅅䅁䉁䅁䅁兂㙃兓䍷㑋畣䅑杷允䅁䅁䅑䅁䑁䅁䅷䅁䭁䕁䄸䅁䭁䕁䄴䅁䙁䅁䅁䅁杄畸䅖允䅁䅁䅅䅁䙁䭁睒児塲⽯⽧䍄䉁䅁䅁兂䅁䅁䅍䅄䅁䅁䅯䅁䅁䅁䅯允䅁䅁䅯兂䅁䅁䅕䅁䅁䭁煂欵䉁䅁䅁允䅁䅁䅕䉵䘶ㄶ㑇樳䴸䅉䅅䅁䙁䅁䅁睁䵁䅁䅁权䅁䅁䅁权䉁䅁䅁权䙁䅁䅁兂䅁䅁䅁偁氷䅑䅅䅁䉁䅁䅁兂㑃潈牘払敪睐杷允䅁䅁䅑䅁䑁䅁䅷䅁䭁䕁䄸䅁䭁䕁䄴䅁䙁䅁䅁䅁杁畧䅚允䅁䅁䅅䅁䙁䥁牘払敧全䄱䍄䉁䅁䅁兂䅁䅁䅍䅄䅁䅁䅯杈䅁䅁䅯允䅁䅁䅯兂䅁䅁䅕䅁䅁䭁䑂欵䉁䅁䅁允䅁䅁䅕⽷潕䥘䌯吱䴸䅉䅅䅁䕁䅁䅁睁䵁䅁䅁权偂䅁䅁权佂䅁䅁兂䅁䅁䅁偧汄䅑䅅䅁䉁䅁䅁兂畃⭒㙆䭆倴䅑杷允䅁䅁䅕䅁䑁䅁䅷䅁䭁䉁䄴䅁䭁䙁䅍䅁䭁䅁䅕䅁䙁䅁䅁䅁䅃⭙䅚允䅁䅁䅅䅁䙁䩁瑈䑦ㄸ楘䅊䍄䉁䅁䅁䅂䅁䅁䅍䅄䅁䅁䅯睔䅁䅁䅯杔䅁䅁䅕䅁䅁䵁慂欵䉁䅁䅁允䅁䅁䅕児塲㍯㥁歄䵁䅉䅅䅁䙁䅁䅁睁䵁䅁䅁权慁䅁䅁权呂䅁䅁权䙁䅁䅁兂䅁䅁䅁䉉浮䅑䅅䅁䉁䅁䅁兂㉃⼸唳䥥㙫䅑杷允䅁䅁䅕䅁䑁䅁䅷䅁䭁䉁䅯䅁䭁䅁䅅䅁䭁䅁䅕䅁䙁䅁䅁䅁杂佢䅚允䅁䅁䅅䅁䙁䭁睒児塲⭯⽧䍄䉁䅁䅁兂䅁䅁䅍䅄䅁䅁䅯䅈䅁䅁䅯睕䅁䅁䅯兂䅁䅁䅕䅁䅁䅁汁欵䉁䅁䅁允䅁䅁䅕㡪ㅌ䙋偷歌䵁䅉䅅䅁䕁䅁䅁睁䵁䅁䅁权偂䅁䅁权佂䅁䅁兂䅁䅁䅁义汐䅑䅅䅁䉁䅁䅁兂䅁䅁䅁䅁䝁䅑杷允䅁䅁䅕䅁䑁䅁䅷䅁䭁䉁䄴䅁䭁䙁䅍䅁䭁䅁䅕䅁䙁䅁䅁䅁䅂佦䅚允䅁䅁䅅䅁䙁䍁捬㡪ㅌ䍡䅆䍄䉁䅁䅁䅂䅁䅁䅍䅄䅁䅁䅯睔䅁䅁䅯杔䅁䅁䅕䅁䅁䭁㙃唵䉁䅁䅁允䅁䅁䅕体㙆䭆䠵吶䴸䅉䅅䅁䙁䅁䅁睁䵁䅁䅁权晁䅁䅁权䉁䅁䅁权䙁䅁䅁兂䅁䅁䅁䈴浺䅑䅅䅁䉁䅁䅁兂㉄䙋偹癷杘睐杷允䅁䅁䅕䅁䑁䅁䅷䅁䭁䅁䅁䅁䭁䙁䅍䅁䭁䅁䅕䅁䙁䅁䅁䅁䅂畚䅚允䅁䅁䅅䅁䙁䙁橔婰䕶䐴䅎䍄䉁䅁䅁䅂䅁䅁䅍䅄䅁䅁䅯睔䅁䅁䅯杔䅁䅁䅕䅁䅁䍁偁欵䉁䅁䅁允䅁䅁䅕䉵䘶ㄶ㑇歅䵁䅉䅅䅁䙁䅁䅁睁䵁䅁䅁权敁䅁䅁权䉁䅁䅁权䙁䅁䅁兂䅁䅁䅁䱷汮䅑䅅䅁䉁䅁䅁兂穁積積積呐睐杷允䅁䅁䅕䅁䑁䅁䅷䅁䭁䅁䅁䅁䭁䅁䅅䅁䭁䅁䅕䅁䙁䅁䅁䅁杂畅䅚允䅁䅁䅅䅁䙁䱁敧敨剴乵⼴䍄䉁䅁䅁兂䅁䅁䅍䅄䅁䅁䅯䅁䅁䅁䅯睕䅁䅁䅯兂䅁䅁䅕䅁䅁佁杂欵䉁䅁䅁允䅁䅁䅕癱午坔兌き䵁䅉䅅䅁䕁䅁䅁睁䵁䅁䅁权偂䅁䅁权佂䅁䅁兂䅁䅁䅁䡯洯䅑䅅䅁䉁䅁䅁兂䑄匹捨㡪䱉䅑杷允䅁䅁䅕䅁䑁䅁䅷䅁䭁䉁䅯䅁䭁䅁䅅䅁䭁䅁䅕䅁䙁䅁䅁䅁权⬳䅖允䅁䅁䅅䅁䙁偁潙䥘䌯改⽁䍄䉁䅁䅁兂䅁䅁䅍䅄䅁䅁䅯睈䅁䅁䅯睕䅁䅁䅯兂䅁䅁䅕䅁䅁佁啄唵䉁䅁䅁允䅁䅁䅕祇搯䅊桢䕍䵁䅉䅅䅁䕁䅁䅁睁䵁䅁䅁权偂䅁䅁权佂䅁䅁兂䅁䅁䅁䥷浈䅑䅅䅁䉁䅁䅁兂獄払敧敨乳䅑杷允䅁䅁䅕䅁䑁䅁䅷䅁䭁䅁䅁䅁䭁䅁䅅䅁䭁䅁䅕䅁䙁䅁䅁䅁䅁⭐䅚允䅁䅁䅅䅁䙁䱁敧敨剴乵⼴䍄䉁䅁䅁兂䅁䅁䅍䅄䅁䅁䅯睈䅁䅁䅯允䅁䅁䅯兂䅁䅁䅕䅁䅁䕁牄唵䉁䅁䅁允䅁䅁䅕場啯歲桦樲䴸䅉䅅䅁䙁䅁䅁睁䵁䅁䅁权䅁䅁䅁权呂䅁䅁权䙁䅁䅁兂䅁䅁䅁䭧汈䅑䅅䅁䉁䅁䅁兂塄㍯㥁癃督䅑杷允䅁䅁䅕䅁䑁䅁䅷䅁䭁䉁䅷䅁䭁䅁䅅䅁䭁䅁䅕䅁䙁䅁䅁䅁杂敦䅚允䅁䅁䅅䅁䙁偁潙䥘䌯搹⽧䍄䉁䅁䅁兂䅁䅁䅍䅄䅁䅁䅯先䅁䅁䅯睕䅁䅁䅯兂䅁䅁䅕䅁䅁䝁兂欵䉁䅁䅁允䅁䅁䅕婤奍䙂佡歌䵁䅉䅅䅁䕁䅁䅁睁䵁䅁䅁权偂䅁䅁权佂䅁䅁兂䅁䅁䅁䝙浪䅑䅅䅁䉁䅁䅁兂晁敨剴䉵临䅑杷允䅁䅁䅑䅁䑁䅁䅷䅁䭁䕁䄸䅁䭁䕁䄴䅁䙁䅁䅁䅁䅃畸䅖允䅁䅁䅅䅁䙁䵁䴳䵺䵺偺⽧䍄䉁䅁䅁兂䅁䅁䅍䅄䅁䅁䅯杈䅁䅁䅯允䅁䅁䅯兂䅁䅁䅕䅁䅁䭁祄唵䉁䅁䅁允䅁䅁䅕積積積積稰䴸䅉䅅䅁䕁䅁䅁睁䵁䅁䅁权偂䅁䅁权佂䅁䅁兂䅁䅁䅁䥯浈䅑䅅䅁䉁䅁䅁兂䅁䅁䅁䅁佁䅑杷允䅁䅁䅕䅁䑁䅁䅷䅁䭁䉁䄸䅁䭁䙁䅍䅁䭁䅁䅕䅁䙁䅁䅁䅁䅃⭆䅚允䅁䅁䅅䅁䙁䕁㉡⼸唳䐫䅂䍄䉁䅁䅁兂䅁䅁䅍䅄䅁䅁䅯睈䅁䅁䅯允䅁䅁䅯兂䅁䅁䅕䅁䅁䕁䩂欵䉁䅁䅁允䅁䅁䅕䡰㥁瑃橥䐴䴸䅉䅅䅁䙁䅁䅁睁䵁䅁䅁权晁䅁䅁权呂䅁䅁权䙁䅁䅁兂䅁䅁䅁䑧浘䅑䅅䅁䉁䅁䅁兂⽁噎㘶卓硷䅑杷允䅁䅁䅑䅁䑁䅁䅷䅁䭁䕁䄸䅁䭁䕁䄴䅁䙁䅁䅁䅁䅂⭹䅖允䅁䅁䅅䅁䙁䙁㑋潈牘兕䅂䍄䉁䅁䅁兂䅁䅁䅍䅄䅁䅁䅯睈䅁䅁䅯睕䅁䅁䅯兂䅁䅁䅕䅁䅁䕁硄唵䉁䅁䅁允䅁䅁䅕㥉㕶浦捰䕍䵁䅉䅅䅁䙁䅁䅁睁䵁䅁䅁权慁䅁䅁权呂䅁䅁权䙁䅁䅁兂䅁䅁䅁䭉汮䅑䅅䅁䉁䅁䅁兂摁浗㝑㐳㔸䅑杷允䅁䅁䅑䅁䑁䅁䅷䅁䭁䕁䄸䅁䭁䕁䄴䅁䙁䅁䅁䅁杂支䅖允䅁䅁䅅䅁䙁䵁ㅐ䙋偹杷䄹䍄䉁䅁䅁兂䅁䅁䅍䅄䅁䅁䅯杈䅁䅁䅯允䅁䅁䅯兂䅁䅁䅕䅁䅁䵁偄唵䉁䅁䅁允䅁䅁䅕積積積積稰䴸䅉䅅䅁䙁䅁䅁睁䵁䅁䅁权慁䅁䅁权呂䅁䅁权䙁䅁䅁兂䅁䅁䅁䅉浪䅑䅅䅁䉁䅁䅁兂䝂癴㥐䈱㙧䅑杷允䅁䅁䅕䅁䑁䅁䅷䅁䭁䅁䅁䅁䭁䙁䅍䅁䭁䅁䅕䅁䙁䅁䅁䅁权敷䅖允䅁䅁䅅䅁䙁偁周㘴扗䑨䅊䍄䉁䅁䅁䅂䅁䅁䅍䅄䅁䅁䅯睔䅁䅁䅯杔䅁䅁䅕䅁䅁䝁卄唵䉁䅁䅁允䅁䅁䅕硥畓⭒㙆歂䵁䅉䅅䅁䙁䅁䅁睁䵁䅁䅁权捁䅁䅁权䉁䅁䅁权䙁䅁䅁兂䅁䅁䅁䅧浲䅑䅅䅁䉁䅁䅁兂晁敨剴䉵嘷睐杷允䅁䅁䅕䅁䑁䅁䅷䅁䭁䅁䅁䅁䭁䅁䅅䅁䭁䅁䅕䅁䙁䅁䅁䅁䅁佴䅖允䅁䅁䅅䅁䙁䩁婱婭婭摭⽫䍄䉁䅁䅁兂䅁䅁䅍䅄䅁䅁䅯杇䅁䅁䅯允䅁䅁䅯兂䅁䅁䅕䅁䅁䅁坂欵䉁䅁䅁允䅁䅁䅕䡰㥁瑃橥䐶䴸䅉䅅䅁䙁䅁䅁睁䵁䅁䅁权摁䅁䅁权呂䅁䅁权䙁䅁䅁兂䅁䅁䅁䑷浈䅑䅅䅁䉁䅁䅁兂坂楄礲敮甸䅑杷允䅁䅁䅕䅁䑁䅁䅷䅁䭁䉁䄸䅁䭁䙁䅍䅁䭁䅁䅕䅁䙁䅁䅁䅁䅂⭣䅚允䅁䅁䅅䅁䙁䝁㡱䩤奍䑊䅆䍄䉁䅁䅁兂䅁䅁䅍䅄䅁䅁䅯䅁䅁䅁䅯允䅁䅁䅯兂䅁䅁䅕䅁䅁䝁䱄唵䉁䅁䅁允䅁䅁䅕児塲㍯㥁樲䴸䅉䅅䅁䙁䅁䅁睁䵁䅁䅁权慁䅁䅁权呂䅁䅁权䙁䅁䅁兂䅁䅁䅁佑汄䅑䅅䅁䉁䅁䅁兂䑄匹捨⭪㕉䅑杷允䅁䅁䅑䅁䑁䅁䅷䅁䭁䕁䄸䅁䭁䕁䄴䅁䙁䅁䅁䅁杁佰䅖允䅁䅁䅅䅁䙁䡁啳歲桦瑥⽑䍄䉁䅁䅁兂䅁䅁䅍䅄䅁䅁䅯䅈䅁䅁䅯睕䅁䅁䅯兂䅁䅁䅕䅁䅁䅁⽃唵䉁䅁䅁允䅁䅁䅕場啯歲桤歌䵁䅉䅅䅁䙁䅁䅁睁䵁䅁䅁权摁䅁䅁权呂䅁䅁权䙁䅁䅁兂䅁䅁䅁䡧浪䅑䅅䅁䉁䅁䅁兂睄㡰䱚㡎瑫䅑杷允䅁䅁䅕䅁䑁䅁䅷䅁䭁䅁䅁䅁䭁䙁䅍䅁䭁䅁䅕䅁䙁䅁䅁䅁杄佅䅚允䅁䅁䅅䅁䙁䉁奂扏䥔橬䅊䍄䉁䅁䅁䅂䅁䅁䅍䅄䅁䅁䅯睔䅁䅁䅯杔䅁䅁䅕䅁䅁䝁晁欵䉁䅁䅁允䅁䅁䅕䭆䠵場啯䕅䵁䅉䅅䅁䙁䅁䅁睁䵁䅁䅁权慁䅁䅁权䉁䅁䅁权䙁䅁䅁兂䅁䅁䅁䴴汐䅑䅅䅁䉁䅁䅁兂䅁䅁䅁䅁杄睐杷允䅁䅁䅕䅁䑁䅁䅷䅁䭁䉁䄰䅁䭁䙁䅍䅁䭁䅁䅕䅁䙁䅁䅁䅁权甫䅖允䅁䅁䅅䅁䙁䝁汄䌰扌匫䄱䍄䉁䅁䅁䅂䅁䅁䅍䅄䅁䅁䅯睔䅁䅁䅯杔䅁䅁䅕䅁䅁䥁䑁欵䉁䅁䅁允䅁䅁䅕㘱睎児塲䕅䵁䅉䅅䅁䙁䅁䅁睁䵁䅁䅁权慁䅁䅁权呂䅁䅁权䙁䅁䅁兂䅁䅁䅁䭯汢䅑䅅䅁䉁䅁䅁兂摁浗㝑㐳㔸䅑杷允䅁䅁䅑䅁䑁䅁䅷䅁䭁䕁䄸䅁䭁䕁䄴䅁䙁䅁䅁䅁杁畬䅖允䅁䅁䅅䅁䙁䍁捬㡪ㅌ䵋⽷䍄䉁䅁䅁兂䅁䅁䅍䅄䅁䅁䅯杇䅁䅁䅯允䅁䅁䅯兂䅁䅁䅕䅁䅁䭁⭃唵䉁䅁䅁允䅁䅁䅕䅁䅁䅁䅁䐴䴸䅉䅅䅁䙁䅁䅁睁䵁䅁䅁权捁䅁䅁权䉁䅁䅁权䙁䅁䅁兂䅁䅁䅁倴汌䅑䅅䅁䉁䅁䅁兂穁積積積呐睐杷允䅁䅁䅕䅁䑁䅁䅷䅁䭁䉁䅷䅁䭁䙁䅍䅁䭁䅁䅕䅁䙁䅁䅁䅁䅂⭗䅚允䅁䅁䅅䅁䙁䭁䙊癴㥐䍆䄵䍄䉁䅁䅁兂䅁䅁䅍䅄䅁䅁䅯先䅁䅁䅯睕䅁䅁䅯兂䅁䅁䅕䅁䅁䅁硂欵䉁䅁䅁允䅁䅁䅕㑎䉬余兕歌䵁䅉䅅䅁䕁䅁䅁睁䵁䅁䅁权偂䅁䅁权佂䅁䅁兂䅁䅁䅁䙙浌䅑䅅䅁䉁䅁䅁兂穁積積積免䅑杷允䅁䅁䅕䅁䑁䅁䅷䅁䭁䅁䅁䅁䭁䅁䅅䅁䭁䅁䅕䅁䙁䅁䅁䅁䅃佴䅖允䅁䅁䅅䅁䙁䩁婱婭婭摭⽫䍄䉁䅁䅁兂䅁䅁䅍䅄䅁䅁䅯䅁䅁䅁䅯允䅁䅁䅯兂䅁䅁䅕䅁䅁䥁坁欵䉁䅁䅁允䅁䅁䅕䉵䘶ㄶ㑇樳䴸䅉䅅䅁䕁䅁䅁睁䵁䅁䅁权偂䅁䅁权佂䅁䅁兂䅁䅁䅁䥧浈䅑䅅䅁䉁䅁䅁兂晁敨剴䉵临䅑杷允䅁䅁䅕䅁䑁䅁䅷䅁䭁䉁䅷䅁䭁䅁䅅䅁䭁䅁䅕䅁䙁䅁䅁䅁䅄⭣䅚允䅁䅁䅅䅁䙁偁潙䥘䌯搹⽧䍄䉁䅁䅁兂䅁䅁䅍䅄䅁䅁䅯杈䅁䅁䅯睕䅁䅁䅯兂䅁䅁䅕䅁䅁䥁流欵䉁䅁䅁允䅁䅁䅕婤奍䙂佢お䵁䅉䅅䅁䕁䅁䅁睁䵁䅁䅁权偂䅁䅁权佂䅁䅁兂䅁䅁䅁䱯汘䅑䅅䅁䉁䅁䅁兂㑃潈牘払敪睐杷允䅁䅁䅕䅁䑁䅁䅷䅁䭁䅁䅁䅁䭁䅁䅅䅁䭁䅁䅕䅁䙁䅁䅁䅁杄⬳䅖允䅁䅁䅅䅁䙁佁㙆䭆䠵搴⽯䍄䉁䅁䅁兂䅁䅁䅍䅄䅁䅁䅯䅈䅁䅁䅯睕䅁䅁䅯兂䅁䅁䅕䅁䅁䝁慄唵䉁䅁䅁允䅁䅁䅕浔光䑗ね歌䵁䅉䅅䅁䙁䅁䅁睁䵁䅁䅁权䅁䅁䅁权䉁䅁䅁权䙁䅁䅁兂䅁䅁䅁䵙汲䅑䅅䅁䉁䅁䅁兂㥁瑃橥䑣愳睐杷允䅁䅁䅑䅁䑁䅁䅷䅁䭁䕁䄸䅁䭁䕁䄴䅁䙁䅁䅁䅁杂佅䅚允䅁䅁䅅䅁䙁偁潙䥘䌯刹䅊䍄䉁䅁䅁兂䅁䅁䅍䅄䅁䅁䅯䅁䅁䅁䅯允䅁䅁䅯兂䅁䅁䅕䅁䅁䕁䙁欵䉁䅁䅁允䅁䅁䅕䉵䘶ㄶ㑇樳䴸䅉䅅䅁䙁䅁䅁睁䵁䅁䅁权䅁䅁䅁权䉁䅁䅁权䙁䅁䅁兂䅁䅁䅁䙁洳䅑䅅䅁䉁䅁䅁兂㑃潈牘払敪睐杷允䅁䅁䅕䅁䑁䅁䅷䅁䭁䉁䅯䅁䭁䅁䅅䅁䭁䅁䅕䅁䙁䅁䅁䅁䅃畈䅚允䅁䅁䅅䅁䙁䭁睒児塲⭯⽧䍄䉁䅁䅁兂䅁䅁䅍䅄䅁䅁䅯䅈䅁䅁䅯允䅁䅁䅯兂䅁䅁䅕䅁䅁䅁祄唵䉁䅁䅁允䅁䅁䅕積積積積稰䴸䅉䅅䅁䕁䅁䅁睁䵁䅁䅁权偂䅁䅁权佂䅁䅁兂䅁䅁䅁䡁浺䅑䅅䅁䉁䅁䅁兂䥂場啯歲乣䅑杷允䅁䅁䅕䅁䑁䅁䅷䅁䭁䉁䅯䅁䭁䙁䅍䅁䭁䅁䅕䅁䙁䅁䅁䅁杄畐䅚允䅁䅁䅅䅁䙁䵁杕䡳潊呍䅴䍄䉁䅁䅁兂䅁䅁䅍䅄䅁䅁䅯䅁䅁䅁䅯睕䅁䅁䅯兂䅁䅁䅕䅁䅁䵁穄唵䉁䅁䅁允䅁䅁䅕積積積呏歍䵁䅉䅅䅁䙁䅁䅁睁䵁䅁䅁权敁䅁䅁权呂䅁䅁权䙁䅁䅁兂䅁䅁䅁䅁浮䅑䅅䅁䉁䅁䅁兂䅁䅁䅁䅁煁䅑杷允䅁䅁䅕䅁䑁䅁䅷䅁䭁䉁䄸䅁䭁䅁䅅䅁䭁䅁䅕䅁䙁䅁䅁䅁䅁⬫䅖允䅁䅁䅅䅁䙁䕁桪桥畓⭒⽅䍄䉁䅁䅁兂䅁䅁䅍䅄䅁䅁䅯䅁䅁䅁䅯允䅁䅁䅯兂䅁䅁䅕䅁䅁䝁湁欵䉁䅁䅁允䅁䅁䅕䉵䘶ㄶ㑇樳䴸䅉䅅䅁䙁䅁䅁睁䵁䅁䅁权慁䅁䅁权呂䅁䅁权䙁䅁䅁兂䅁䅁䅁䍙浦䅑䅅䅁䉁䅁䅁兂䥂場啯煲㙣䅑杷允䅁䅁䅑䅁䑁䅁䅷䅁䭁䕁䄸䅁䭁䕁䄴䅁䙁䅁䅁䅁䅂略䅚允䅁䅁䅅䅁䙁䱁敧敨剴䅵䅸䍄䉁䅁䅁兂䅁䅁䅍䅄䅁䅁䅯睈䅁䅁䅯允䅁䅁䅯兂䅁䅁䅕䅁䅁䍁㡁欵䉁䅁䅁允䅁䅁䅕䡰㥁瑃橥䐴䴸䅉䅅䅁䙁䅁䅁睁䵁䅁䅁权晁䅁䅁权䉁䅁䅁权䙁䅁䅁兂䅁䅁䅁䅁浌䅑䅅䅁䉁䅁䅁兂䅁䅁䅁䅁杄睐杷允䅁䅁䅕䅁䑁䅁䅷䅁䭁䅁䅁䅁䭁䙁䅍䅁䭁䅁䅕䅁䙁䅁䅁䅁䅄攵䅖允䅁䅁䅅䅁䙁䉁䕫杖琴樰䅊䍄䉁䅁䅁兂䅁䅁䅍䅄䅁䅁䅯杈䅁䅁䅯允䅁䅁䅯兂䅁䅁䅕䅁䅁䅁楂欵䉁䅁䅁允䅁䅁䅕䅁䅁䅁䅁䐰䴸䅉䅅䅁䕁䅁䅁睁䵁䅁䅁权偂䅁䅁权佂䅁䅁兂䅁䅁䅁䌴浺䅑䅅䅁䉁䅁䅁兂䙃ㄶ㑇潈单䅑杷允䅁䅁䅕䅁䑁䅁䅷䅁䭁䅁䅁䅁䭁䅁䅅䅁䭁䅁䅕䅁䙁䅁䅁䅁权⬱䅖允䅁䅁䅅䅁䙁佁㙆䭆䠵搴⽯䍄䉁䅁䅁兂䅁䅁䅍䅄䅁䅁䅯杇䅁䅁䅯睕䅁䅁䅯兂䅁䅁䅕䅁䅁佁畂欵䉁䅁䅁允䅁䅁䅕㥌欰潂噆く䵁䅉䅅䅁䕁䅁䅁睁䵁䅁䅁权偂䅁䅁权佂䅁䅁兂䅁䅁䅁乁決䅑䅅䅁䉁䅁䅁兂啁歲桦桥䥑䅑杷允䅁䅁䅑䅁䑁䅁䅷䅁䭁䕁䄸䅁䭁䕁䄴䅁䙁䅁䅁䅁䅂敧䅚允䅁䅁䅅䅁䙁䭁睒児塲睯䅸䍄䉁䅁䅁兂䅁䅁䅍䅄䅁䅁䅯先䅁䅁䅯允䅁䅁䅯兂䅁䅁䅕䅁䅁佁㍁欵䉁䅁䅁允䅁䅁䅕歲桦桥畓稱䴸䅉䅅䅁䕁䅁䅁睁䵁䅁䅁权偂䅁䅁权佂䅁䅁兂䅁䅁䅁䡁浪䅑䅅䅁䉁䅁䅁兂㝂䭆䠵場䵯䅑杷允䅁䅁䅕䅁䑁䅁䅷䅁䭁䉁䅯䅁䭁䅁䅅䅁䭁䅁䅕䅁䙁䅁䅁䅁䅃敊䅚允䅁䅁䅅䅁䙁䭁睒児塲⭯⽧䍄䉁䅁䅁䅂䅁䅁䅍䅄䅁䅁䅯睔䅁䅁䅯杔䅁䅁䅕䅁䅁䅁硁欵䉁䅁䅁允䅁䅁䅕䅁䅁䅁䅁歅䵁䅉䅅䅁䙁䅁䅁睁䵁䅁䅁权晁䅁䅁权呂䅁䅁权䙁䅁䅁兂䅁䅁䅁䙧浪䅑䅅䅁䉁䅁䅁兂㥂穐敖極硫䅑杷允䅁䅁䅑䅁䑁䅁䅷䅁䭁䕁䄸䅁䭁䕁䄴䅁䙁䅁䅁䅁杄佧䅚允䅁䅁䅅䅁䙁䱁敧敨剴䅵䅸䍄䉁䅁䅁兂䅁䅁䅍䅄䅁䅁䅯䅁䅁䅁䅯睕䅁䅁䅯兂䅁䅁䅕䅁䅁䕁㑄唵䉁䅁䅁允䅁䅁䅕噋偹癷潖歍䵁䅉䅅䅁䕁䅁䅁睁䵁䅁䅁权偂䅁䅁权佂䅁䅁兂䅁䅁䅁䑑洷䅑䅅䅁䉁䅁䅁兂䑄匹捨㡪䱉䅑杷允䅁䅁䅑䅁䑁䅁䅷䅁䭁䕁䄸䅁䭁䕁䄴䅁䙁䅁䅁䅁权敥䅚允䅁䅁䅅䅁䙁䑁䬰㘱睎児䅸䍄䉁䅁䅁兂䅁䅁䅍䅄䅁䅁䅯䅁䅁䅁䅯睕䅁䅁䅯兂䅁䅁䅕䅁䅁䍁䍄唵䉁䅁䅁允䅁䅁䅕䘫橐婰䕵歍䵁䅉䅅䅁䙁䅁䅁睁䵁䅁䅁权䅁䅁䅁权呂䅁䅁权䙁䅁䅁兂䅁䅁䅁䘴浐䅑䅅䅁䉁䅁䅁兂㕁䵴㉨瑶稸䅑杷允䅁䅁䅕䅁䑁䅁䅷䅁䭁䉁䅯䅁䭁䅁䅅䅁䭁䅁䅕䅁䙁䅁䅁䅁䅄畉䅚允䅁䅁䅅䅁䙁䭁睒児塲⭯⽧䍄䉁䅁䅁䅂䅁䅁䅍䅄䅁䅁䅯睔䅁䅁䅯杔䅁䅁䅕䅁䅁䭁汁欵䉁䅁䅁允䅁䅁䅕体㙆䭆䠵啅䵁䅉䅅䅁䙁䅁䅁睁䵁䅁䅁权捁䅁䅁权呂䅁䅁权䙁䅁䅁兂䅁䅁䅁䵙汢䅑䅅䅁䉁䅁䅁兂桄桥畓㉒畅䅑杷允䅁䅁䅕䅁䑁䅁䅷䅁䭁䉁䄸䅁䭁䅁䅅䅁䭁䅁䅕䅁䙁䅁䅁䅁䅁敷䅖允䅁䅁䅅䅁䙁䱁敧敨剴乵⼴䍄䉁䅁䅁兂䅁䅁䅍䅄䅁䅁䅯䅁䅁䅁䅯睕䅁䅁䅯兂䅁䅁䅕䅁䅁䭁婁欵䉁䅁䅁允䅁䅁䅕硢䑋䵷䉯き䵁䅉䅅䅁䙁䅁䅁睁䵁䅁䅁权慁䅁䅁权呂䅁䅁权䙁䅁䅁兂䅁䅁䅁偉汦䅑䅅䅁䉁䅁䅁兂偃癷潕佘㔸䅑杷允䅁䅁䅑䅁䑁䅁䅷䅁䭁䕁䄸䅁䭁䕁䄴䅁䙁䅁䅁䅁杁敗䅚允䅁䅁䅅䅁䙁䥁䌯匹捨睪䄵䍄䉁䅁䅁兂䅁䅁䅍䅄䅁䅁䅯先䅁䅁䅯睕䅁䅁䅯兂䅁䅁䅕䅁䅁䝁楃唵䉁䅁䅁允䅁䅁䅕牒穢搯㑒啌䵁䅉䅅䅁䙁䅁䅁睁䵁䅁䅁权晁䅁䅁权䉁䅁䅁权䙁䅁䅁兂䅁䅁䅁䝁洯䅑䅅䅁䉁䅁䅁兂卂䉵䘶ㄶ杈睐杷允䅁䅁䅕䅁䑁䅁䅷䅁䭁䅁䅁䅁䭁䅁䅅䅁䭁䅁䅕䅁䙁䅁䅁䅁䅁⭬䅖允䅁䅁䅅䅁䙁䩁婱婭婭摭⽫䍄䉁䅁䅁兂䅁䅁䅍䅄䅁䅁䅯睈䅁䅁䅯睕䅁䅁䅯兂䅁䅁䅕䅁䅁䵁䑄唵䉁䅁䅁允䅁䅁䅕塹⭡确癯啍䵁䅉䅅䅁䕁䅁䅁睁䵁䅁䅁权偂䅁䅁权佂䅁䅁兂䅁䅁䅁䱯決䅑䅅䅁䉁䅁䅁兂穁積積積牐睐杷允䅁䅁䅑䅁䑁䅁䅷䅁䭁䕁䄸䅁䭁䕁䄴䅁䙁䅁䅁䅁杁⭙䅚允䅁䅁䅅䅁䙁佁㙆䭆䠵儴䄵䍄䉁䅁䅁兂䅁䅁䅍䅄䅁䅁䅯䅈䅁䅁䅯允䅁䅁䅯兂䅁䅁䅕䅁䅁䍁捃唵䉁䅁䅁允䅁䅁䅕㡪ㅌ䙋偹樰䴸䅉䅅䅁䙁䅁䅁睁䵁䅁䅁权摁䅁䅁权呂䅁䅁权䙁䅁䅁兂䅁䅁䅁䙯浔䅑䅅䅁䉁䅁䅁兂䑄匹捨㑪畉䅑杷允䅁䅁䅕䅁䑁䅁䅷䅁䭁䉁䄸䅁䭁䅁䅅䅁䭁䅁䅕䅁䙁䅁䅁䅁权畍䅚允䅁䅁䅅䅁䙁䕁桪桥畓⭒⽅䍄䉁䅁䅁䅂䅁䅁䅍䅄䅁䅁䅯睔䅁䅁䅯杔䅁䅁䅕䅁䅁䕁䥄唵䉁䅁䅁允䅁䅁䅕場啯歲桦樫䴸䅉䅅䅁䕁䅁䅁睁䵁䅁䅁权偂䅁䅁权佂䅁䅁兂䅁䅁䅁䵁氳䅑䅅䅁䉁䅁䅁兂浂浚浚浚䕙䅑杷允䅁䅁䅕䅁䑁䅁䅷䅁䭁䉁䅯䅁䭁䙁䅍䅁䭁䅁䅕䅁䙁䅁䅁䅁权敖䅚允䅁䅁䅅䅁䙁䵁ㅐ䙋偹橙䅴䍄䉁䅁䅁兂䅁䅁䅍䅄䅁䅁䅯杈䅁䅁䅯睕䅁䅁䅯兂䅁䅁䅕䅁䅁䕁敂欵䉁䅁䅁允䅁䅁䅕敫㠱穐敖歉䵁䅉䅅䅁䕁䅁䅁睁䵁䅁䅁权偂䅁䅁权佂䅁䅁兂䅁䅁䅁䬴汲䅑䅅䅁䉁䅁䅁兂啁歲桦桥敔睐杷允䅁䅁䅕䅁䑁䅁䅷䅁䭁䉁䅷䅁䭁䅁䅅䅁䭁䅁䅕䅁䙁䅁䅁䅁䅄⭹䅖允䅁䅁䅅䅁䙁䑁積積積㥍⽍䍄䉁䅁䅁䅂䅁䅁䅍䅄䅁䅁䅯睔䅁䅁䅯杔䅁䅁䅕䅁䅁䭁乂欵䉁䅁䅁允䅁䅁䅕牕敧敨剴啅䵁䅉䅅䅁䙁䅁䅁睁䵁䅁䅁权慁䅁䅁权䉁䅁䅁权䙁䅁䅁兂䅁䅁䅁䌴浌䅑䅅䅁䉁䅁䅁兂歃䑣䬰㘱潐睐杷允䅁䅁䅕䅁䑁䅁䅷䅁䭁䉁䄰䅁䭁䙁䅍䅁䭁䅁䅕䅁䙁䅁䅁䅁权敊䅚允䅁䅁䅅䅁䙁䝁浚浚浚椵䄵䍄䉁䅁䅁兂䅁䅁䅍䅄䅁䅁䅯睈䅁䅁䅯睕䅁䅁䅯兂䅁䅁䅕䅁䅁佁煁欵䉁䅁䅁允䅁䅁䅕癴㥐䠱䩧啍䵁䅉䅅䅁䙁䅁䅁睁䵁䅁䅁权䅁䅁䅁权呂䅁䅁权䙁䅁䅁兂䅁䅁䅁偙氯䅑䅅䅁䉁䅁䅁兂煃搸乊湙祁䅑杷允䅁䅁䅑䅁䑁䅁䅷䅁䭁䕁䄸䅁䭁䕁䄴䅁䙁䅁䅁䅁䅄佧䅚允䅁䅁䅅䅁䙁䱁敧敨剴䅵䅸䍄䉁䅁䅁兂䅁䅁䅍䅄䅁䅁䅯䅁䅁䅁䅯允䅁䅁䅯兂䅁䅁䅕䅁䅁䍁潄唵䉁䅁䅁允䅁䅁䅕敨剴䉵䘶稲䴸䅉䅅䅁䙁䅁䅁睁䵁䅁䅁权晁䅁䅁权呂䅁䅁权䙁䅁䅁兂䅁䅁䅁䅯浪䅑䅅䅁䉁䅁䅁兂䑃䵷桱婒睙䅑杷允䅁䅁䅕䅁䑁䅁䅷䅁䭁䉁䄸䅁䭁䙁䅍䅁䭁䅁䅕䅁䙁䅁䅁䅁䅄畏䅚允䅁䅁䅅䅁䙁䑁䩥坑汄䑍䅆䍄䉁䅁䅁兂䅁䅁䅍䅄䅁䅁䅯䅁䅁䅁䅯睕䅁䅁䅯兂䅁䅁䅕䅁䅁䍁㡂欵䉁䅁䅁允䅁䅁䅕佖汏㡭䅑䕎䵁䅉䅅䅁䙁䅁䅁睁䵁䅁䅁权慁䅁䅁权呂䅁䅁权䙁䅁䅁兂䅁䅁䅁䵯汲䅑䅅䅁䉁䅁䅁兂权楇搯䕊㙙䅑杷允䅁䅁䅑䅁䑁䅁䅷䅁䭁䕁䄸䅁䭁䕁䄴䅁䙁䅁䅁䅁杄敮䅖允䅁䅁䅅䅁䙁䉁䘫ㄶ㑇瑈⽕䍄䉁䅁䅁兂䅁䅁䅍䅄䅁䅁䅯䅁䅁䅁䅯睕䅁䅁䅯兂䅁䅁䅕䅁䅁佁橄唵䉁䅁䅁允䅁䅁䅕兇坒楄匳歍䵁䅉䅅䅁䙁䅁䅁睁䵁䅁䅁权慁䅁䅁权呂䅁䅁权䙁䅁䅁兂䅁䅁䅁䍉浈䅑䅅䅁䉁䅁䅁兂㉃⼸唳䥥㙫䅑杷允䅁䅁䅕䅁䑁䅁䅷䅁䭁䉁䄸䅁䭁䅁䅅䅁䭁䅁䅕䅁䙁䅁䅁䅁䅃敗䅚允䅁䅁䅅䅁䙁䙁㑋潈牘敕⽁䍄䉁䅁䅁䅂䅁䅁䅍䅄䅁䅁䅯睔䅁䅁䅯杔䅁䅁䅕䅁䅁䍁十欵䉁䅁䅁允䅁䅁䅕敨剴䉵䘶ぅ䵁䅉䅅䅁䙁䅁䅁睁䵁䅁䅁权䅁䅁䅁权䉁
